Workbook

Sheet TABEL TER
A1: TABEL TER PPH 21 2025 | J1: TABEL TARIF EFEKTIF
J2: Tidak kawin tanpa tanggungan (TK/0); | Q2: Tidak kawin dengan jumlah tanggungan sebanyak 2 orang (TK/2); | X2: PTKP kawin dengan jumlah tanggungan sebanyak 3 orang (K/3).
J3: Tidak kawin dengan jumlah tanggungan sebanyak 1 orang (TK/1); atau | Q3: Tidak kawin dengan jumlah tanggungan sebanyak 3 orang (TK/3);
A4: Jenis TER | B4: Terendah | C4: Tertinggi | D4: Tarif Pajak | F4: Jenis TER | G4: Status | J4: Kawin tanpa tanggungan (K/0). | Q4: Kawin dengan jumlah tanggungan sebanyak 1 orang (K/1); atau
A5: TER A | B5: 0 | C5: 5400000 | D5: 0 | F5: TER A | G5: TK/0 | Q5: Kawin dengan jumlah tanggungan sebanyak 2 orang (K/2).
A6: TER A | B6: 5400001 | C6: 5650000 | D6: 0.0025 | F6: TER A | G6: TK/1
A7: TER A | B7: 5650001 | C7: 5950000 | D7: 0.005 | F7: TER A | G7: K/0 | J7: Kategori A | Q7: Kategori B | X7: Kategori C
A8: TER A | B8: 5950001 | C8: 6300000 | D8: 0.0075 | F8: TER B | G8: TK/2 | J8: Penghasilan Bruto Bulanan | K8: Tarif Pajak | L8: Terendah | M8: Tertinggi | Q8: Penghasilan Bruto Bulanan | R8: Tarif Pajak | S8: Terendah | T8: Tertinggi | X8: Penghasilan Bruto Bulanan | Y8: Tarif Pajak | Z8: Terendah | AA8: Tertinggi
A9: TER A | B9: 6300001 | C9: 6750000 | D9: 0.01 | F9: TER B | G9: K/1 | J9: Sampai dengan Rp5.400.000 | K9: 0 | L9: 0 | M9: 5400000 | Q9: Sampai dengan Rp6.200.000 | R9: 0 | S9: 0 | T9: 6200000 | X9: Sampai dengan Rp6.600.000 | Y9: 0 | Z9: 0 | AA9: 6600000
A10: TER A | B10: 6750001 | C10: 7500000 | D10: 0.0125 | F10: TER B | G10: TK/3 | J10: Di atas Rp5.400.000 sampai dengan Rp5.650.000 | K10: 0,25% | L10: 5400001 | M10: 5650000 | Q10: Di atas Rp6.200.000 sampai dengan Rp6.500.000 | R10: 0,25% | S10: 6200001 | T10: 6500000 | X10: Di atas Rp6.600.000 sampai dengan Rp6.950.000 | Y10: 0,25% | Z10: 6600001 | AA10: 6950000
A11: TER A | B11: 7500001 | C11: 8550000 | D11: 0.015 | F11: TER B | G11: K/2 | J11: Di atas Rp5.650.000 sampai dengan Rp5.950.000 | K11: 0,5% | L11: 5650001 | M11: 5950000 | Q11: Di atas Rp6.500.000 sampai dengan Rp6.850.000 | R11: 0,5% | S11: 6500001 | T11: 6850000 | X11: Di atas Rp6.950.000 sampai dengan Rp7.350.000 | Y11: 0,5% | Z11: 6950001 | AA11: 7350000
A12: TER A | B12: 8550001 | C12: 9650000 | D12: 0.0175 | F12: TER C | G12: K/3 | J12: Di atas Rp5.950.000 sampai dengan Rp6.300.000 | K12: 0,75% | L12: 5950001 | M12: 6300000 | Q12: Di atas Rp6.850.000 sampai dengan Rp7.300.000 | R12: 0,75% | S12: 6850001 | T12: 7300000 | X12: Di atas Rp7.350.000 sampai dengan Rp7.800.000 | Y12: 0,75% | Z12: 7350001 | AA12: 7800000
A13: TER A | B13: 9650001 | C13: 10050000 | D13: 0.02 | J13: Di atas Rp6.300.000 sampai dengan Rp6.750.000 | K13: 0.01 | L13: 6300001 | M13: 6750000 | Q13: Di atas Rp7.300.000 sampai dengan Rp9.200.000 | R13: 0.01 | S13: 7300001 | T13: 9200000 | X13: Di atas Rp7.800.000 sampai dengan Rp8.850.000 | Y13: 0.01 | Z13: 7800001 | AA13: 8850000
A14: TER A | B14: 10050001 | C14: 10350000 | D14: 0.0225 | J14: Di atas Rp6.750.000 sampai dengan Rp7.500.000 | K14: 1,25% | L14: 6750001 | M14: 7500000 | Q14: Di atas Rp9.200.000 sampai dengan Rp10.750.000 | R14: 1,5% | S14: 9200001 | T14: 10750000 | X14: Di atas Rp8.850.000 sampai dengan Rp9.800.000 | Y14: 1,25% | Z14: 8850001 | AA14: 9800000
A15: TER A | B15: 10350001 | C15: 10700000 | D15: 0.025 | J15: Di atas Rp7.500.000 sampai dengan Rp8.550.000 | K15: 1,5% | L15: 7500001 | M15: 8550000 | Q15: Di atas Rp10.750.000 sampai dengan Rp11.250.000 | R15: 0.02 | S15: 10750001 | T15: 11250000 | X15: Di atas Rp9.800.000 sampai dengan Rp10.950.000 | Y15: 1,5% | Z15: 9800001 | AA15: 10950000
A16: TER A | B16: 10700001 | C16: 11050000 | D16: 0.03 | J16: Di atas Rp8.550.000 sampai dengan Rp9.650.000 | K16: 1,75% | L16: 8550001 | M16: 9650000 | Q16: Di atas Rp11.250.000 sampai dengan Rp11.600.000 | R16: 2,5% | S16: 11250001 | T16: 11600000 | X16: Di atas Rp10.950.000 sampai dengan Rp11.200.000 | Y16: 1,75% | Z16: 10950001 | AA16: 11200000
A17: TER A | B17: 11050001 | C17: 11600000 | D17: 0.035 | J17: Di atas Rp9.650.000 sampai dengan Rp10.050.000 | K17: 0.02 | L17: 9650001 | M17: 10050000 | Q17: Di atas Rp11.600.000 sampai dengan Rp12.600.000 | R17: 0.03 | S17: 11600001 | T17: 12600000 | X17: Di atas Rp11.200.000 sampai dengan Rp12.050.000 | Y17: 0.02 | Z17: 11200001 | AA17: 12050000
A18: TER A | B18: 11600001 | C18: 12500000 | D18: 0.04 | J18: Di atas Rp10.050.000 sampai dengan Rp10.350.000 | K18: 2,25% | L18: 10050001 | M18: 10350000 | Q18: Di atas Rp12.600.000 sampai dengan Rp13.600.000 | R18: 0.04 | S18: 12600001 | T18: 13600000 | X18: Di atas Rp12.050.000 sampai dengan Rp12.950.000 | Y18: 0.03 | Z18: 12050001 | AA18: 12950000
A19: TER A | B19: 12500001 | C19: 13750000 | D19: 0.05 | J19: Di atas Rp10.350.000 sampai dengan Rp10.700.000 | K19: 2,5% | L19: 10350001 | M19: 10700000 | Q19: Di atas Rp13.600.000 sampai dengan Rp14.950.000 | R19: 0.05 | S19: 13600001 | T19: 14950000 | X19: Di atas Rp12.950.000 sampai dengan Rp14.150.000 | Y19: 0.04 | Z19: 12950001 | AA19: 14150000
A20: TER A | B20: 13750001 | C20: 15100000 | D20: 0.06 | J20: Di atas Rp10.700.000 sampai dengan Rp11.050.000 | K20: 0.03 | L20: 10700001 | M20: 11050000 | Q20: Di atas Rp14.950.000 sampai dengan Rp16.400.000 | R20: 0.06 | S20: 14950001 | T20: 16400000 | X20: Di atas Rp14.150.000 sampai dengan Rp15.550.000 | Y20: 0.05 | Z20: 14150001 | AA20: 15550000
A21: TER A | B21: 15100001 | C21: 16950000 | D21: 0.07 | J21: Di atas Rp11.050.000 sampai dengan Rp11.600.000 | K21: 3,5% | L21: 11050001 | M21: 11600000 | Q21: Di atas Rp16.400.000 sampai dengan Rp18.450.000 | R21: 0.07 | S21: 16400001 | T21: 18450000 | X21: Di atas Rp15.550.000 sampai dengan Rp17.050.000 | Y21: 0.06 | Z21: 15550001 | AA21: 17050000
A22: TER A | B22: 16950001 | C22: 19750000 | D22: 0.08 | J22: Di atas Rp11.600.000 sampai dengan Rp12.500.000 | K22: 0.04 | L22: 11600001 | M22: 12500000 | Q22: Di atas Rp18.450.000 sampai dengan Rp21.850.000 | R22: 0.08 | S22: 18450001 | T22: 21850000 | X22: Di atas Rp17.050.000 sampai dengan Rp19.500.000 | Y22: 0.07 | Z22: 17050001 | AA22: 19500000
A23: TER A | B23: 19750001 | C23: 24150000 | D23: 0.09 | J23: Di atas Rp12.500.000 sampai dengan Rp13.750.000 | K23: 0.05 | L23: 12500001 | M23: 13750000 | Q23: Di atas Rp21.850.000 sampai dengan Rp26.000.000 | R23: 0.09 | S23: 21850001 | T23: 26000000 | X23: Di atas Rp19.500.000 sampai dengan Rp22.700.000 | Y23: 0.08 | Z23: 19500001 | AA23: 22700000
A24: TER A | B24: 24150001 | C24: 26450000 | D24: 0.1 | J24: Di atas Rp13.750.000 sampai dengan Rp15.100.000 | K24: 0.06 | L24: 13750001 | M24: 15100000 | Q24: Di atas Rp26.000.000 sampai dengan Rp27.700.000 | R24: 0.1 | S24: 26000001 | T24: 27700000 | X24: Di atas Rp22.700.000 sampai dengan Rp26.600.000 | Y24: 0.09 | Z24: 22700001 | AA24: 26600000
A25: TER A | B25: 26450001 | C25: 28000000 | D25: 0.11 | J25: Di atas Rp15.100.000 sampai dengan Rp16.950.000 | K25: 0.07 | L25: 15100001 | M25: 16950000 | Q25: Di atas Rp27.700.000 sampai dengan Rp29.350.000 | R25: 0.11 | S25: 27700001 | T25: 29350000 | X25: Di atas Rp26.600.000 sampai dengan Rp28.100.000 | Y25: 0.1 | Z25: 26600001 | AA25: 28100000
A26: TER A | B26: 28000001 | C26: 30050000 | D26: 0.12 | J26: Di atas Rp16.950.000 sampai dengan Rp19.750.000 | K26: 0.08 | L26: 16950001 | M26: 19750000 | Q26: Di atas Rp29.350.000 sampai dengan Rp31.450.000 | R26: 0.12 | S26: 29350001 | T26: 31450000 | X26: Di atas Rp28.100.000 sampai dengan Rp30.100.000 | Y26: 0.11 | Z26: 28100001 | AA26: 30100000
A27: TER A | B27: 30050001 | C27: 32400000 | D27: 0.13 | J27: Di atas Rp19.750.000 sampai dengan Rp24.150.000 | K27: 0.09 | L27: 19750001 | M27: 24150000 | Q27: Di atas Rp31.450.000 sampai dengan Rp33.950.000 | R27: 0.13 | S27: 31450001 | T27: 33950000 | X27: Di atas Rp30.100.000 sampai dengan Rp32.600.000 | Y27: 0.12 | Z27: 30100001 | AA27: 32600000
A28: TER A | B28: 32400001 | C28: 35400000 | D28: 0.14 | J28: Di atas Rp24.150.000 sampai dengan Rp26.450.000 | K28: 0.1 | L28: 24150001 | M28: 26450000 | Q28: Di atas Rp33.950.000 sampai dengan Rp37.100.000 | R28: 0.14 | S28: 33950001 | T28: 37100000 | X28: Di atas Rp32.600.000 sampai dengan Rp35.400.000 | Y28: 0.13 | Z28: 32600001 | AA28: 35400000
A29: TER A | B29: 35400001 | C29: 39100000 | D29: 0.15 | J29: Di atas Rp26.450.000 sampai dengan Rp28.000.000 | K29: 0.11 | L29: 26450001 | M29: 28000000 | Q29: Di atas Rp37.100.000 sampai dengan Rp41.100.000 | R29: 0.15 | S29: 37100001 | T29: 41100000 | X29: Di atas Rp35.400.000 sampai dengan Rp38.900.000 | Y29: 0.14 | Z29: 35400001 | AA29: 38900000
A30: TER A | B30: 39100001 | C30: 43850000 | D30: 0.16 | J30: Di atas Rp28.000.000 sampai dengan Rp30.050.000 | K30: 0.12 | L30: 28000001 | M30: 30050000 | Q30: Di atas Rp41.100.000 sampai dengan Rp45.800.000 | R30: 0.16 | S30: 41100001 | T30: 45800000 | X30: Di atas Rp38.900.000 sampai dengan Rp43.000.000 | Y30: 0.15 | Z30: 38900001 | AA30: 43000000
A31: TER A | B31: 43850001 | C31: 47800000 | D31: 0.17 | J31: Di atas Rp30.050.000 sampai dengan Rp32.400.000 | K31: 0.13 | L31: 30050001 | M31: 32400000 | Q31: Di atas Rp45.800.000 sampai dengan Rp49.500.000 | R31: 0.17 | S31: 45800001 | T31: 49500000 | X31: Di atas Rp43.000.000 sampai dengan Rp47.400.000 | Y31: 0.16 | Z31: 43000001 | AA31: 47400000
A32: TER A | B32: 47800001 | C32: 51400000 | D32: 0.18 | J32: Di atas Rp32.400.000 sampai dengan Rp35.400.000 | K32: 0.14 | L32: 32400001 | M32: 35400000 | Q32: Di atas Rp49.500.000 sampai dengan Rp53.800.000 | R32: 0.18 | S32: 49500001 | T32: 53800000 | X32: Di atas Rp47.400.000 sampai dengan Rp51.200.000 | Y32: 0.17 | Z32: 47400001 | AA32: 51200000
A33: TER A | B33: 51400001 | C33: 56300000 | D33: 0.19 | J33: Di atas Rp35.400.000 sampai dengan Rp39.100.000 | K33: 0.15 | L33: 35400001 | M33: 39100000 | Q33: Di atas Rp53.800.000 sampai dengan Rp58.500.000 | R33: 0.19 | S33: 53800001 | T33: 58500000 | X33: Di atas Rp51.200.000 sampai dengan Rp55.800.000 | Y33: 0.18 | Z33: 51200001 | AA33: 55800000
... A47: TER A | B47: 910000001 | C47: 1400000000 | D47: 0.33 | J47: Di atas Rp337.000.000 sampai dengan Rp454.000.000 | K47: 0.29 | L47: 337000001 | M47: 454000000 | Q47: Di atas Rp957.000.000 sampai dengan Rp1.405.000.000 | R47: 0.33 | S47: 957000001 | T47: 1405000000 | X47: Di atas Rp709.000.000 sampai dengan R965.000.000 | Y47: 0.32 | Z47: 709000001 | AA47: 965000000
A48: TER A | B48: 1400000001 | D48: 0.34 | J48: Di atas Rp454.000.000 sampai dengan Rp550.000.000 | K48: 0.3 | L48: 454000001 | M48: 550000000 | Q48: Di atas Rp1.405.000.000 | R48: 0.34 | S48: 1405000001 | X48: Di atas Rp965.000.000 sampai dengan Rp1.419.000.000 | Y48: 0.33 | Z48: 965000001 | AA48: 1419000000
J49: Di atas Rp550.000.000 sampai dengan Rp695.000.000 | K49: 0.31 | L49: 550000001 | M49: 695000000 | X49: Di atas Rp1.419.000.000 | Y49: 0.34 | Z49: 1419000000
A50: TER B | B50: 0 | C50: 6200000 | D50: 0 | J50: Di atas Rp695.000.000 sampai dengan Rp910.000.000 | K50: 0.32 | L50: 695000001 | M50: 910000000
A51: TER B | B51: 6200001 | C51: 6500000 | D51: 0.0025 | J51: Di atas Rp910.000.000 sampai dengan Rp1.400.000.000 | K51: 0.33 | L51: 910000001 | M51: 1400000000
A52: TER B | B52: 6500001 | C52: 6850000 | D52: 0.005 | J52: Di atas Rp1.400.000.000 | K52: 0.34 | L52: 1400000001
A53: TER B | B53: 6850001 | C53: 7300000 | D53: 0.0075
...

Sheet Sheet1
C1: Gaji Bulan : 01-2026 | P1: Printed | Q1: Tuesday , 03-02-2026 17:14
P2: Page | Q2: 1 | R2: of | S2: 5
C3: SEMUA KARYAWAN
C4: PT. JPM
D6: Status Karyawan Kontrak
C7: Tenaga Kerja Langsung
C8: Cost Center Produksi
C9: No | D9: NIP | E9: Nama | G9: THP Final | H9: Gaji Pokok | I9: Bonus | J9: Lembur | K9: Sanksi | L9: Lain | M9: Askes | N9: Rawat Inap | O9: Premi BPJS Kesehatan | P9: JKK | Q9: JKM | R9: Perdin | S9: BPJS Pensiun | T9: JHT & Pensiun | U9: T. Jabatan | V9: T. Fungsional | W9: Potongan Produktifitas | X9: Sanksi Cetak | Y9: T. PPH21 | Z9: PPH 21 | AA9: NIK | AB9: POSISI | AC9: Bruto Upload | AD9: T. PPh | AE9: Bruto + T. PPh | AF9: Kategori | AG9: Tarif | AH9: PPh 21 | AI9: Angka T.PPh | AM9: Bruto Seharusnya Tanpa T.PPh | AQ9: New NIK
C10: Tenaga Kerja
C11: Cost Center Pemasaran
C12: No | D12: NIP | E12: Nama | G12: THP Final | H12: Gaji Pokok | I12: Bonus | J12: Lembur | K12: Sanksi | L12: Lain | M12: Askes | N12: Rawat Inap | O12: Premi BPJS Kesehatan | P12: JKK | Q12: JKM | R12: Perdin | S12: BPJS Pensiun | T12: JHT & Pensiun | U12: T. Jabatan | V12: T. Fungsional | W12: Potongan Produktifitas | X12: Sanksi Cetak | Y12: T. PPH21 | Z12: PPH 21
A13: JPM | C13: =TEXT(D13,"0000000") -> 2514936 | D13: 2514936 | E13: AGUS TRIWAHYUDI | F13: TK/0 | G13: 6053513 | H13: 6053513 | I13: 0 | J13: 0 | K13: 0 | L13: 0 | M13: 0 | N13: 0 | O13: 240000 | P13: 53876 | Q13: 18161 | R13: 0 | S13: 0 | T13: 223980 | U13: 0 | V13: 0 | W13: 0 | X13: 0 | Y13: 0 | Z13: 0 | AA13: =VLOOKUP(C13,[2]Sheet1!$B$9:$Z$1392,25,0) -> #ERROR! | AB13: =VLOOKUP(C13,[2]Sheet1!$B$9:$AA$1392,26,0) -> #ERROR! | AC13: =SUM(G13,N13,O13,P13,Q13)-SUM(K13,L13,W13,X13) -> 6365550 | AD13: =ROUND(AC13*(AI13/(100-AI13)),0) -> #REF! | AE13: =AC13+AD13 -> #REF! | AF13: {=INDEX('TABEL TER'!F$5:F$12,MATCH($F13,'TABEL TER'!G$5:G$12,0))} -> TER A | AG13: =IF($AF13="TER A",VLOOKUP($AE13,'TABEL TER'!$B$5:$D$48,3,TRUE),IF($AF13="TER B",VLOOKUP($AE13,'TABEL TER'!$B$50:$D$89,3,TRUE),IF($AF13="TER C",VLOOKUP($AE13,'TABEL TER'!$B$91:$D$131,3,TRUE)))) -> #REF! | AH13: =ROUND(AE13*AG13,0) -> #REF! | AI13: =AG13*100 -> #REF! | AJ13: =IF(AH13=0,"TIDAK","YA") -> #REF! | AK13: =P13/G13 -> 0.0088999561 | AQ13: =INDEX([1]Sheet1!$A:$K,MATCH(C13,[1]Sheet1!$A:$A,0),7) -> #ERROR! | AR13: =AA13=AQ13 -> #ERROR!
A14: JPM | C14: =TEXT(D14,"0000000") -> 2214823 | D14: 2214823 | E14: AWAN BIMA SAPUTRA | F14: TK/1 | G14: 5288797 | H14: 5288797 | I14: 0 | J14: 0 | K14: 0 | L14: 0 | M14: 0 | N14: 0 | O14: 201304 | P14: 47070 | Q14: 15866 | R14: 0 | S14: 0 | T14: 195685 | U14: 0 | V14: 0 | W14: 0 | X14: 0 | Y14: 0 | Z14: 0 | AA14: =VLOOKUP(C14,[2]Sheet1!$B$9:$Z$1392,25,0) -> #ERROR! | AB14: =VLOOKUP(C14,[2]Sheet1!$B$9:$AA$1392,26,0) -> #ERROR! | AC14: =SUM(G14,N14,O14,P14,Q14)-SUM(K14,L14,W14,X14) -> 5553037 | AD14: =ROUND(AC14*(AI14/(100-AI14)),0) -> #REF! | AE14: =AC14+AD14 -> #REF! | AF14: {=INDEX('TABEL TER'!F$5:F$12,MATCH($F14,'TABEL TER'!G$5:G$12,0))} -> TER A | AG14: =IF($AF14="TER A",VLOOKUP($AE14,'TABEL TER'!$B$5:$D$48,3,TRUE),IF($AF14="TER B",VLOOKUP($AE14,'TABEL TER'!$B$50:$D$89,3,TRUE),IF($AF14="TER C",VLOOKUP($AE14,'TABEL TER'!$B$91:$D$131,3,TRUE)))) -> #REF! | AH14: =ROUND(AE14*AG14,0) -> #REF! | AI14: =AG14*100 -> #REF! | AJ14: =IF(AH14=0,"TIDAK","YA") -> #REF! | AK14: =P14/G14 -> 0.0088999445 | AQ14: =INDEX([1]Sheet1!$A:$K,MATCH(C14,[1]Sheet1!$A:$A,0),7) -> #ERROR! | AR14: =AA14=AQ14 -> #ERROR!
C15: Total Cost Center Pemasaran | G15: 11342310 | H15: 11342310 | I15: 0 | J15: 0 | K15: 0 | L15: 0 | M15: 0 | N15: 0 | O15: =SUM(O13:O14) -> 441304 | P15: =SUM(P13:P14) -> 100946 | Q15: =SUM(Q13:Q14) -> 34027 | R15: 0 | S15: 0 | T15: 419665 | U15: 0 | V15: 0 | W15: 0 | X15: 0 | Y15: 0 | Z15: 0 | AC15: =SUM(AC13:AC14) -> 11918587 | AD15: =SUM(AD13:AD14) -> #REF! | AE15: =SUM(AE13:AE14) -> #REF!
C16: Cost Center Umum
C17: No | D17: NIP | E17: Nama | G17: THP Final | H17: Gaji Pokok | I17: Bonus | J17: Lembur | K17: Sanksi | L17: Lain | M17: Askes | N17: Rawat Inap | O17: Premi BPJS Kesehatan | P17: JKK | Q17: JKM | R17: Perdin | S17: BPJS Pensiun | T17: JHT & Pensiun | U17: T. Jabatan | V17: T. Fungsional | W17: Potongan Produktifitas | X17: Sanksi Cetak | Y17: T. PPH21 | Z17: PPH 21
A18: JPM | C18: =TEXT(D18,"0000000") -> 2314824 | D18: 2314824 | E18: MUHAMMAD DAVI IMAM GUMILANG | F18: TK/0 | G18: 7908432 | H18: 6408432 | I18: 0 | J18: 0 | K18: 209388 | L18: 0 | M18: 0 | N18: 0 | O18: 201304 | P18: 70385 | Q18: 23725 | R18: 0 | S18: 0 | T18: 292612 | U18: 1500000 | V18: 0 | W18: 0 | X18: 0 | Y18: 0 | Z18: 0 | AA18: =VLOOKUP(C18,[2]Sheet1!$B$9:$Z$1392,25,0) -> #ERROR! | AB18: =VLOOKUP(C18,[2]Sheet1!$B$9:$AA$1392,26,0) -> #ERROR! | AC18: =SUM(G18,N18,O18,P18,Q18)-SUM(K18,L18,W18,X18) -> 7994458 | AD18: =ROUND(AC18*(AI18/(100-AI18)),0) -> #REF! | AE18: =AC18+AD18 -> #REF! | AF18: {=INDEX('TABEL TER'!F$5:F$12,MATCH($F18,'TABEL TER'!G$5:G$12,0))} -> TER A | AG18: =IF($AF18="TER A",VLOOKUP($AE18,'TABEL TER'!$B$5:$D$48,3,TRUE),IF($AF18="TER B",VLOOKUP($AE18,'TABEL TER'!$B$50:$D$89,3,TRUE),IF($AF18="TER C",VLOOKUP($AE18,'TABEL TER'!$B$91:$D$131,3,TRUE)))) -> #REF! | AH18: =ROUND(AE18*AG18,0) -> #REF! | AI18: =AG18*100 -> #REF! | AJ18: =IF(AH18=0,"TIDAK","YA") -> #REF! | AK18: =P18/G18 -> 0.0088999943 | AQ18: =INDEX([1]Sheet1!$A:$K,MATCH(C18,[1]Sheet1!$A:$A,0),7) -> #ERROR! | AR18: =AA18=AQ18 -> #ERROR!
A19: JPM | C19: =TEXT(D19,"0000000") -> 2514914 | D19: 2514914 | E19: NINDY PRAVITASARI | F19: TK/0 | G19: 5288796 | H19: 5288796 | I19: 0 | J19: 0 | K19: 89496 | L19: 0 | M19: 0 | N19: 0 | O19: 0 | P19: 47070 | Q19: 15866 | R19: 0 | S19: 0 | T19: 195685 | U19: 0 | V19: 0 | W19: 0 | X19: 0 | Y19: 0 | Z19: 0 | AA19: =VLOOKUP(C19,[2]Sheet1!$B$9:$Z$1392,25,0) -> #ERROR! | AB19: =VLOOKUP(C19,[2]Sheet1!$B$9:$AA$1392,26,0) -> #ERROR! | AC19: =SUM(G19,N19,O19,P19,Q19)-SUM(K19,L19,W19,X19) -> 5262236 | AD19: =ROUND(AC19*(AI19/(100-AI19)),0) -> #REF! | AE19: =AC19+AD19 -> #REF! | AF19: {=INDEX('TABEL TER'!F$5:F$12,MATCH($F19,'TABEL TER'!G$5:G$12,0))} -> TER A | AG19: =IF($AF19="TER A",VLOOKUP($AE19,'TABEL TER'!$B$5:$D$48,3,TRUE),IF($AF19="TER B",VLOOKUP($AE19,'TABEL TER'!$B$50:$D$89,3,TRUE),IF($AF19="TER C",VLOOKUP($AE19,'TABEL TER'!$B$91:$D$131,3,TRUE)))) -> #REF! | AH19: =ROUND(AE19*AG19,0) -> #REF! | AI19: =AG19*100 -> #REF! | AJ19: =IF(AH19=0,"TIDAK","YA") -> #REF! | AK19: =P19/G19 -> 0.0088999462 | AQ19: =INDEX([1]Sheet1!$A:$K,MATCH(C19,[1]Sheet1!$A:$A,0),7) -> #ERROR! | AR19: =AA19=AQ19 -> #ERROR!
A20: JPM | C20: =TEXT(D20,"0000000") -> 2314851 | D20: 2314851 | E20: RAHMAT ADITYA NUGROHO WIBOWO | F20: K/1 | G20: 5676999 | H20: 5676999 | I20: 0 | J20: 0 | K20: 0 | L20: 0 | M20: 0 | N20: 0 | O20: 201304 | P20: 50525 | Q20: 17031 | R20: 0 | S20: 0 | T20: 210049 | U20: 0 | V20: 0 | W20: 0 | X20: 0 | Y20: 0 | Z20: 0 | AA20: =VLOOKUP(C20,[2]Sheet1!$B$9:$Z$1392,25,0) -> #ERROR! | AB20: =VLOOKUP(C20,[2]Sheet1!$B$9:$AA$1392,26,0) -> #ERROR! | AC20: =SUM(G20,N20,O20,P20,Q20)-SUM(K20,L20,W20,X20) -> 5945859 | AD20: =ROUND(AC20*(AI20/(100-AI20)),0) -> #REF! | AE20: =AC20+AD20 -> #REF! | AF20: {=INDEX('TABEL TER'!F$5:F$12,MATCH($F20,'TABEL TER'!G$5:G$12,0))} -> TER B | AG20: =IF($AF20="TER A",VLOOKUP($AE20,'TABEL TER'!$B$5:$D$48,3,TRUE),IF($AF20="TER B",VLOOKUP($AE20,'TABEL TER'!$B$50:$D$89,3,TRUE),IF($AF20="TER C",VLOOKUP($AE20,'TABEL TER'!$B$91:$D$131,3,TRUE)))) -> #REF! | AH20: =ROUND(AE20*AG20,0) -> #REF! | AI20: =AG20*100 -> #REF! | AJ20: =IF(AH20=0,"TIDAK","YA") -> #REF! | AK20: =P20/G20 -> 0.0088999487 | AQ20: =INDEX([1]Sheet1!$A:$K,MATCH(C20,[1]Sheet1!$A:$A,0),7) -> #ERROR! | AR20: =AA20=AQ20 -> #ERROR!
C21: Total Cost Center Umum | G21: 18874227 | H21: 17374227 | I21: 0 | J21: 0 | K21: 298884 | L21: 0 | M21: 0 | N21: 0 | O21: =SUM(O18:O20) -> 402608 | P21: =SUM(P18:P20) -> 167980 | Q21: =SUM(Q18:Q20) -> 56622 | R21: 0 | S21: 0 | T21: 698346 | U21: 1500000 | V21: 0 | W21: 0 | X21: 0 | Y21: 0 | Z21: 0 | AC21: =SUM(AC18:AC20) -> 19202553 | AD21: =SUM(AD18:AD20) -> #REF! | AE21: =SUM(AE18:AE20) -> #REF!
C22: Total Tenaga Kerja | G22: 30216537 | H22: 28716537 | I22: 0 | J22: 0 | K22: 298884 | L22: 0 | M22: 0 | N22: 0 | O22: 997110 | P22: 268927 | Q22: 90650 | R22: 0 | S22: 0 | T22: 1118012 | U22: 1500000 | V22: 0 | W22: 0 | X22: 0 | Y22: 0 | Z22: 0
G23: 30216537 | H23: 28716537 | I23: 0 | J23: 0 | K23: 298884 | L23: 0 | M23: 0 | N23: 0 | O23: 997110 | P23: 268927 | Q23: 90650 | R23: 0 | S23: 0 | T23: 1118012 | U23: 1500000 | V23: 0 | W23: 0 | X23: 0 | Y23: 0 | Z23: 0
C24: Gaji Bulan : 01-2026 | P24: Printed | Q24: Tuesday , 03-02-2026 17:14
P25: Page | Q25: 2 | R25: of | S25: 3
C26: SEMUA KARYAWAN
C27: PT. JPM
C30: Tenaga Kerja Tidak Langsung
C31: Cost Center Produksi
C32: No | D32: NIP | E32: Nama | G32: THP Final | H32: Gaji Pokok | I32: Bonus | J32: Lembur | K32: Sanksi | L32: Lain | M32: Askes | N32: Rawat Inap | O32: Premi BPJS Kesehatan | P32: JKK | Q32: JKM | R32: Perdin | S32: BPJS Pensiun | T32: JHT & Pensiun | U32: T. Jabatan | V32: T. Fungsional | W32: Potongan Produktifitas | X32: Sanksi Cetak | Y32: T. PPH21 | Z32: PPH 21
A33: JPM | C33: =TEXT(D33,"0000000") -> 1714833 | D33: 1714833 | E33: DURI PUSPITASARI | F33: TK/0 | G33: 5424796 | H33: 5424796 | I33: 0 | J33: 0 | K33: 0 | L33: 0 | M33: 0 | N33: 0 | O33: 201304 | P33: 48281 | Q33: 16274 | R33: 0 | S33: 0 | T33: 200717 | U33: 0 | V33: 0 | W33: 0 | X33: 0 | Y33: 0 | Z33: 0 | AA33: =VLOOKUP(C33,[2]Sheet1!$B$9:$Z$1392,25,0) -> #ERROR! | AB33: =VLOOKUP(C33,[2]Sheet1!$B$9:$AA$1392,26,0) -> #ERROR! | AC33: =SUM(G33,N33,O33,P33,Q33)-SUM(K33,L33,W33,X33) -> 5690655 | AD33: =ROUND(AC33*(AI33/(100-AI33)),0) -> #REF! | AE33: =AC33+AD33 -> #REF! | AF33: {=INDEX('TABEL TER'!F$5:F$12,MATCH($F33,'TABEL TER'!G$5:G$12,0))} -> TER A | AG33: =IF($AF33="TER A",VLOOKUP($AE33,'TABEL TER'!$B$5:$D$48,3,TRUE),IF($AF33="TER B",VLOOKUP($AE33,'TABEL TER'!$B$50:$D$89,3,TRUE),IF($AF33="TER C",VLOOKUP($AE33,'TABEL TER'!$B$91:$D$131,3,TRUE)))) -> #REF! | AH33: =ROUND(AE33*AG33,0) -> #REF! | AI33: =AG33*100 -> #REF! | AJ33: =IF(AH33=0,"TIDAK","YA") -> #REF! | AK33: =P33/G33 -> 0.0089000582 | AQ33: =INDEX([1]Sheet1!$A:$K,MATCH(C33,[1]Sheet1!$A:$A,0),7) -> #ERROR! | AR33: =AA33=AQ33 -> #ERROR!
A34: JPM | C34: =TEXT(D34,"0000000") -> 0914834 | D34: 0914834 | E34: HARIYANTO | F34: K/1 | G34: 5288796 | H34: 5038796 | I34: 0 | J34: 0 | K34: 0 | L34: 0 | M34: 0 | N34: 0 | O34: 201304 | P34: 47070 | Q34: 15866 | R34: 0 | S34: 0 | T34: 195685 | U34: 250000 | V34: 0 | W34: 0 | X34: 0 | Y34: 0 | Z34: 0 | AA34: =VLOOKUP(C34,[2]Sheet1!$B$9:$Z$1392,25,0) -> #ERROR! | AB34: =VLOOKUP(C34,[2]Sheet1!$B$9:$AA$1392,26,0) -> #ERROR! | AC34: =SUM(G34,N34,O34,P34,Q34)-SUM(K34,L34,W34,X34) -> 5553036 | AD34: =ROUND(AC34*(AI34/(100-AI34)),0) -> #REF! | AE34: =AC34+AD34 -> #REF! | AF34: {=INDEX('TABEL TER'!F$5:F$12,MATCH($F34,'TABEL TER'!G$5:G$12,0))} -> TER B | AG34: =IF($AF34="TER A",VLOOKUP($AE34,'TABEL TER'!$B$5:$D$48,3,TRUE),IF($AF34="TER B",VLOOKUP($AE34,'TABEL TER'!$B$50:$D$89,3,TRUE),IF($AF34="TER C",VLOOKUP($AE34,'TABEL TER'!$B$91:$D$131,3,TRUE)))) -> #REF! | AH34: =ROUND(AE34*AG34,0) -> #REF! | AI34: =AG34*100 -> #REF! | AJ34: =IF(AH34=0,"TIDAK","YA") -> #REF! | AK34: =P34/G34 -> 0.0088999462 | AQ34: =INDEX([1]Sheet1!$A:$K,MATCH(C34,[1]Sheet1!$A:$A,0),7) -> #ERROR! | AR34: =AA34=AQ34 -> #ERROR!
A35: JPM | C35: =TEXT(D35,"0000000") -> 1714837 | D35: 1714837 | E35: MUHAMMAD MUZAMIL | F35: K/2 | G35: 5288796 | H35: 5288796 | I35: 0 | J35: 0 | K35: 0 | L35: 0 | M35: 0 | N35: 0 | O35: 201304 | P35: 47070 | Q35: 15866 | R35: 0 | S35: 0 | T35: 195685 | U35: 0 | V35: 0 | W35: 0 | X35: 0 | Y35: 0 | Z35: 0 | AA35: =VLOOKUP(C35,[2]Sheet1!$B$9:$Z$1392,25,0) -> #ERROR! | AB35: =VLOOKUP(C35,[2]Sheet1!$B$9:$AA$1392,26,0) -> #ERROR! | AC35: =SUM(G35,N35,O35,P35,Q35)-SUM(K35,L35,W35,X35) -> 5553036 | AD35: =ROUND(AC35*(AI35/(100-AI35)),0) -> #REF! | AE35: =AC35+AD35 -> #REF! | AF35: {=INDEX('TABEL TER'!F$5:F$12,MATCH($F35,'TABEL TER'!G$5:G$12,0))} -> TER B | AG35: =IF($AF35="TER A",VLOOKUP($AE35,'TABEL TER'!$B$5:$D$48,3,TRUE),IF($AF35="TER B",VLOOKUP($AE35,'TABEL TER'!$B$50:$D$89,3,TRUE),IF($AF35="TER C",VLOOKUP($AE35,'TABEL TER'!$B$91:$D$131,3,TRUE)))) -> #REF! | AH35: =ROUND(AE35*AG35,0) -> #REF! | AI35: =AG35*100 -> #REF! | AJ35: =IF(AH35=0,"TIDAK","YA") -> #REF! | AK35: =P35/G35 -> 0.0088999462 | AQ35: =INDEX([1]Sheet1!$A:$K,MATCH(C35,[1]Sheet1!$A:$A,0),7) -> #ERROR! | AR35: =AA35=AQ35 -> #ERROR!
A36: JPM | C36: =TEXT(D36,"0000000") -> 0814830 | D36: 0814830 | E36: AVIVUDIN HANI | F36: K/2 | G36: 4271179 | H36: 3771179 | I36: 0 | J36: 0 | K36: 0 | L36: 0 | M36: 0 | N36: 0 | O36: 198472 | P36: 38013 | Q36: 12814 | R36: 0 | S36: 0 | T36: 158034 | U36: 500000 | V36: 0 | W36: 0 | X36: 0 | Y36: 0 | Z36: 0 | AA36: =VLOOKUP(C36,[2]Sheet1!$B$9:$Z$1392,25,0) -> #ERROR! | AB36: =VLOOKUP(C36,[2]Sheet1!$B$9:$AA$1392,26,0) -> #ERROR! | AC36: =SUM(G36,N36,O36,P36,Q36)-SUM(K36,L36,W36,X36) -> 4520478 | AD36: =ROUND(AC36*(AI36/(100-AI36)),0) -> #REF! | AE36: =AC36+AD36 -> #REF! | AF36: {=INDEX('TABEL TER'!F$5:F$12,MATCH($F36,'TABEL TER'!G$5:G$12,0))} -> TER B | AG36: =IF($AF36="TER A",VLOOKUP($AE36,'TABEL TER'!$B$5:$D$48,3,TRUE),IF($AF36="TER B",VLOOKUP($AE36,'TABEL TER'!$B$50:$D$89,3,TRUE),IF($AF36="TER C",VLOOKUP($AE36,'TABEL TER'!$B$91:$D$131,3,TRUE)))) -> #REF! | AH36: =ROUND(AE36*AG36,0) -> #REF! | AI36: =AG36*100 -> #REF! | AJ36: =IF(AH36=0,"TIDAK","YA") -> #REF! | AK36: =P36/G36 -> 0.0088998846 | AQ36: =INDEX([1]Sheet1!$A:$K,MATCH(C36,[1]Sheet1!$A:$A,0),7) -> #ERROR! | AR36: =AA36=AQ36 -> #ERROR!
A37: JPM | C37: =TEXT(D37,"0000000") -> 1914840 | D37: 1914840 | E37: DENI PRIYATNO TIMUR | F37: TK/0 | G37: 3012197 | H37: 3012197 | I37: 0 | J37: 0 | K37: 0 | L37: 0 | M37: 0 | N37: 0 | O37: 113544 | P37: 26809 | Q37: 9037 | R37: 0 | S37: 0 | T37: 111451 | U37: 0 | V37: 0 | W37: 0 | X37: 0 | Y37: 0 | Z37: 0 | AA37: =VLOOKUP(C37,[2]Sheet1!$B$9:$Z$1392,25,0) -> #ERROR! | AB37: =VLOOKUP(C37,[2]Sheet1!$B$9:$AA$1392,26,0) -> #ERROR! | AC37: =SUM(G37,N37,O37,P37,Q37)-SUM(K37,L37,W37,X37) -> 3161587 | AD37: =ROUND(AC37*(AI37/(100-AI37)),0) -> #REF! | AE37: =AC37+AD37 -> #REF! | AF37: {=INDEX('TABEL TER'!F$5:F$12,MATCH($F37,'TABEL TER'!G$5:G$12,0))} -> TER A | AG37: =IF($AF37="TER A",VLOOKUP($AE37,'TABEL TER'!$B$5:$D$48,3,TRUE),IF($AF37="TER B",VLOOKUP($AE37,'TABEL TER'!$B$50:$D$89,3,TRUE),IF($AF37="TER C",VLOOKUP($AE37,'TABEL TER'!$B$91:$D$131,3,TRUE)))) -> #REF! | AH37: =ROUND(AE37*AG37,0) -> #REF! | AI37: =AG37*100 -> #REF! | AJ37: =IF(AH37=0,"TIDAK","YA") -> #REF! | AK37: =P37/G37 -> 0.0089001483 | AQ37: =INDEX([1]Sheet1!$A:$K,MATCH(C37,[1]Sheet1!$A:$A,0),7) -> #ERROR! | AR37: =AA37=AQ37 -> #ERROR!
A38: JPM | C38: =TEXT(D38,"0000000") -> 0614841 | D38: 0614841 | E38: SUWANTO | F38: K/1 | G38: 5755401 | H38: 5255401 | I38: 0 | J38: 0 | K38: 0 | L38: 0 | M38: 0 | N38: 0 | O38: 201304 | P38: 51223 | Q38: 17266 | R38: 0 | S38: 0 | T38: 212950 | U38: 500000 | V38: 0 | W38: 0 | X38: 0 | Y38: 0 | Z38: 0 | AA38: =VLOOKUP(C38,[2]Sheet1!$B$9:$Z$1392,25,0) -> #ERROR! | AB38: =VLOOKUP(C38,[2]Sheet1!$B$9:$AA$1392,26,0) -> #ERROR! | AC38: =SUM(G38,N38,O38,P38,Q38)-SUM(K38,L38,W38,X38) -> 6025194 | AD38: =ROUND(AC38*(AI38/(100-AI38)),0) -> #REF! | AE38: =AC38+AD38 -> #REF! | AF38: {=INDEX('TABEL TER'!F$5:F$12,MATCH($F38,'TABEL TER'!G$5:G$12,0))} -> TER B | AG38: =IF($AF38="TER A",VLOOKUP($AE38,'TABEL TER'!$B$5:$D$48,3,TRUE),IF($AF38="TER B",VLOOKUP($AE38,'TABEL TER'!$B$50:$D$89,3,TRUE),IF($AF38="TER C",VLOOKUP($AE38,'TABEL TER'!$B$91:$D$131,3,TRUE)))) -> #REF! | AH38: =ROUND(AE38*AG38,0) -> #REF! | AI38: =AG38*100 -> #REF! | AJ38: =IF(AH38=0,"TIDAK","YA") -> #REF! | AK38: =P38/G38 -> 0.008899988 | AQ38: =INDEX([1]Sheet1!$A:$K,MATCH(C38,[1]Sheet1!$A:$A,0),7) -> #ERROR! | AR38: =AA38=AQ38 -> #ERROR!
C39: Total Cost Center Produksi | G39: 29041165 | H39: 27791165 | I39: 0 | J39: 0 | K39: 0 | L39: 0 | M39: 0 | N39: 0 | O39: =SUM(O33:O38) -> 1117232 | P39: =SUM(P33:P38) -> 258466 | Q39: =SUM(Q33:Q38) -> 87123 | R39: 0 | S39: 0 | T39: 1074523 | U39: 1250000 | V39: 0 | W39: 0 | X39: 0 | Y39: 0 | Z39: 0 | AC39: =SUM(AC33:AC38) -> 30503986 | AD39: =SUM(AD33:AD38) -> #REF! | AE39: =SUM(AE33:AE38) -> #REF!
C40: Total Tenaga Kerja Tidak Langsung | G40: 29041165 | H40: 27791165 | I40: 0 | J40: 0 | K40: 0 | L40: 0 | M40: 0 | N40: 0 | O40: 1161647 | P40: 258466 | Q40: 87123 | R40: 0 | S40: 0 | T40: 1074523 | U40: 1250000 | V40: 0 | W40: 0 | X40: 0 | Y40: 0 | Z40: 0
C42: Gaji Bulan : 01-2026 | P42: Printed | Q42: Tuesday , 03-02-2026 17:14
P43: Page | Q43: 3 | R43: of | S43: 3
C44: SEMUA KARYAWAN
...

Sheet Sheet2

Sheet Sheet3
