Workbook
Name DUEFROMCOUNTERPART: #REF!
Name CURRLTDDIFFPAYMONFAACQ: #REF!
Name PAGEBS: #REF!
Name TY: #REF!
Name E1A: #REF!
Name accumdeprbegbalfurniture_Fixture: #REF!
Name Monthof2004: #REF!
Name APDEFERREDTAX: #REF!
Name ref_SBLC: #REF!
Name APSUBSCON: #REF!
Name LIABFORRETIREMENTBENEFIT: #REF!
Name cy_net_income: #REF!
Name liftingsum: #REF!
Name py_net_income: #REF!
Name L1A: #REF!
Name Prd_CopyAll: #REF!
Name W: #REF!
Name CURRLTDDIFFPAYMONFAACQ: #REF!
Name Excel_BuiltIn_Print_Area_5: #REF!
Name APOTHTHIRD: #REF!
Name NOTESPAYABLE: #REF!
Name DUETOCOUNTERPART: #REF!
Name DUETOSTOCKHOLDER: #REF!
Name KKM: #REF!
Name Excel_BuiltIn_Print_Area_4: #REF!
Name N1B: #REF!
Name _R1A: #REF!
Name DUEFROMAFFCO: #REF!
Name Excel_BuiltIn_Print_Area_3: #REF!
Name J1B: #REF!
Name Excel_BuiltIn_Print_Area_11: #REF!
Name Excel_BuiltIn_Print_Titles_10: #REF!
Name kopRIN: #REF!
Name yy: #REF!
Name STK: #REF!
Name DUETOAFFCO: #REF!
Name dhjk: #REF!
Name J1A: #REF!
Name kopRIN: #REF!
Name LIABFORRETIREMENTBENEFIT: #REF!
Name ADVFORACQUISITIONOFINVESTMENT: #REF!
Name N1B: #REF!
Name DUEFROMAFFCON: #REF!
Name DUEFROMOTHSTOCKHOLDER: #REF!
Name ccc: #REF!
Name ARTRADTHIRD: #REF!
Name SHEET4: Sheet1!$BS$61:$BV$61
Name Excel_BuiltIn_Print_Titles_4: #REF!
Name ADVANCES: #REF!
Name E1A: #REF!
Name Attachment_16.2: #REF!
Name Excel_BuiltIn_Print_Area_17: #REF!
Name jjddll: #REF!
Name DIFFINVALUEOFTRANSACTIONWITHUCC: #REF!
Name Monthof2004: #REF!
Name CURRLTDLOAN: #REF!
Name L1A: #REF!
Name APAFFCON: #REF!
Name searchsuratjalan: #REF!
Name KKM: #REF!

Sheet Jobdesc
A1: DATA KARYAWAN SBU PERCETAKAN KOMERSIAL
A2: PERIODE FEBRUARI 2023 | H2: KRY+HL
C3: =SUBTOTAL(103,C6:C495) -> 17 | H3: =A3+G3 -> 0 | I3: =SUBTOTAL(109,I6:I251) -> 0
A4: Cabang | B4: No | C4: Nama Pegawai | D4: Jabatan | E4: Level | F4: Departemen | G4: Cost Center | H4: status | I4: SDM HL
A6: SMG | B6: 1 | C6: DETA LIANA PUSPITA RIA | D6: Accounting | E6: Staff/Operator | F6: Accounting/Finan ce | G6: Akuntansi | H6: Tetap
A7: SMG | B7: 2 | C7: YUNITA HERUWATI | D7: Piutang | E7: Staff/Operator | F7: Accounting/Finan ce | G7: Piutang | H7: Tetap
A8: SMG | B8: 3 | C8: NURUL KHANIFAH | D8: Karu HC | E8: Karu/Wakaru | F8: HRD & Umum | G8: HRD | H8: Tetap
A9: SMG | B9: 4 | C9: GINANJAR | D9: Umum | E9: Staff/Operator | F9: HRD & Umum | G9: Umum | H9: Tetap
A10: SMG | B10: 5 | C10: A. FERY ARDIANSAH | D10: Kadiv PPIC | E10: Kasi/Wakasi/Kadiv/W akadiv/Koordinator | F10: Product Planning Control | G10: PPIC | H10: Tetap
A11: SMG | B11: 6 | C11: AFFAN JULIARDI | D11: Kadiv PPIC | E11: Kasi/Wakasi/Kadiv/W akadiv/Koordinator | F11: Product Planning Control | G11: PPIC | H11: Tetap
A12: SMG | B12: 7 | C12: SUPRIYANTO | D12: Staff Gudang Barang Jadi | E12: Staff/Operator | F12: Product Planning Control | G12: Gudang B.Jadi | H12: Tetap
A13: SMG | B13: 8 | C13: AGUS SALIKIN | D13: Staff Gudang Sparepart & Bahan Baku | E13: Staff/Operator | F13: Product Planning Control | G13: PPIC | H13: Tetap
A14: SMG | B14: 9 | C14: RIZKY YANWARIO | D14: Staff Gudang Sparepart & Bahan Baku | E14: Staff/Operator | F14: Product Planning Control | G14: PPIC | H14: Tetap
A15: SMG | B15: 10 | C15: SOHIM SAIFUL HIDAYAT | D15: Staff Gudang Sparepart & Bahan Baku | E15: Staff/Operator | F15: Product Planning Control | G15: PPIC | H15: Tetap
A16: SMG | B16: 11 | C16: ACHMAD EDI YULIANTO | D16: Finishing | E16: Staff/Operator | F16: Produksi | G16: Finishing | H16: Tetap
A17: SMG | B17: 12 | C17: HARIYANTO | D17: Finishing | E17: Staff/Operator | F17: Produksi | G17: Finishing | H17: Tetap
... A105: SBY | B105: 100 | C105: YUSAK FAHRUR HAMZAH | D105: Assistant Manager Marketing | E105: Manager | F105: Manager/Branch Manager | G105: Manager Pemasaran | H105: Tetap
A106: SBY | B106: 101 | C106: YUNUS ANDRIANTO | D106: Admin Marketing Proyek | E106: Staff/Operator | F106: Pemasaran | G106: Pemasaran | H106: Tetap | I106: 1
A107: SBY | B107: 102 | C107: ZULKARNEN | D107: Admin Marketing Proyek | E107: Staff/Operator | F107: Pemasaran | G107: Pemasaran | H107: Tetap
A108: SBY | B108: 103 | C108: DIDIN KRISTIAWAN | D108: Admin. Marketing | E108: Staff/Operator | F108: Pemasaran | G108: Administrasi Pemasaran | H108: Tetap | I108: 1
A109: SBY | B109: 104 | C109: FELBY ANDELIA SUPRATIKNO | D109: Kadiv Marketing | E109: Kasi/Wakasi/Kadiv/W akadiv/Koordinator | F109: Pemasaran | G109: Pemasaran | H109: Tetap
A110: SBY | B110: 105 | C110: AGUS MAULID | D110: Marketing | E110: Staff/Operator | F110: Pemasaran | G110: Pemasaran | H110: Tetap
A111: SBY | B111: 106 | C111: ARI ARRAHIM | D111: Marketing | E111: Staff/Operator | F111: Pemasaran | G111: Pemasaran | H111: Tetap
A112: SBY | B112: 107 | C112: DANI SOTANTO | D112: Marketing | E112: Staff/Operator | F112: Pemasaran | G112: Pemasaran | H112: Tetap
A113: SBY | B113: 108 | C113: DWI THOFANI M THOYIB | D113: Marketing | E113: Staff/Operator | F113: Pemasaran | G113: Pemasaran | H113: Tetap | I113: 1
A114: SBY | B114: 109 | C114: HERMAN SUSANTO | D114: Marketing | E114: Staff/Operator | F114: Pemasaran | G114: Pemasaran | H114: Tetap
A115: SBY | B115: 110 | C115: RIZA CHOIRUL ANAS | D115: Marketing | E115: Staff/Operator | F115: Pemasaran | G115: Pemasaran | H115: Tetap
A116: SBY | B116: 111 | C116: RONI SUPRIYADI | D116: Marketing | E116: Staff/Operator | F116: Pemasaran | G116: Pemasaran | H116: Tetap
A117: SBY | B117: 112 | C117: SHANDI AMRI AZHAR | D117: Marketing | E117: Staff/Operator | F117: Pemasaran | G117: Pemasaran | H117: Tetap
A118: SBY | B118: 113 | C118: ACHMAD SAFII KARIM | D118: Staff Purchasing | E118: Staff/Operator | F118: Pembelian | G118: Pembelian | H118: Tetap
A119: SBY | B119: 114 | C119: ARIS DWI PURNOMO | D119: Staff Purchasing | E119: Staff/Operator | F119: Pembelian | G119: Pembelian | H119: Tetap
A120: SBY | B120: 115 | C120: UNTUNG WANTOYO | D120: Ekspedisi | E120: Staff/Operator | F120: Product Planning Control | G120: PPIC | H120: Tetap
A121: SBY | B121: 116 | C121: YAYAN SETIYO NUGROHO | D121: Kadiv PPIC | E121: Kasi/Wakasi/Kadiv/W akadiv/Koordinator | F121: Product Planning Control | G121: PPIC | H121: Tetap
A122: SBY | B122: 117 | C122: ASEP GUNAWAN | D122: Karu Gudang Bahan Baku | E122: Karu/Wakaru | F122: Product Planning Control | G122: Gudang B.Baku | H122: Tetap
A123: SBY | B123: 118 | C123: SUPRAPTO | D123: Staff Gudang Bahan Baku | E123: Staff/Operator | F123: Product Planning Control | G123: Gudang B.Baku | H123: Tetap
A124: SBY | B124: 119 | C124: TOMI SULISTIONO | D124: Staff Gudang Bahan Baku | E124: Staff/Operator | F124: Product Planning Control | G124: Gudang B.Baku | H124: Tetap
A125: SBY | B125: 120 | C125: ERIK ENGGAR PRASTYAWAN | D125: Staff Gudang Barang Jadi | E125: Staff/Operator | F125: Product Planning Control | G125: PPIC | H125: Tetap
... A201: SBY | B201: 196 | C201: SRI HANDAYANI | D201: Piutang | E201: Staff/Operator | F201: Accounting/Finan ce | G201: Piutang | H201: Kontrak 3
A202: SBY | B202: 197 | C202: ALFIAN IBNU SINA | D202: Staff Accounting | E202: Staff/Operator | F202: Accounting/Finan ce | G202: Akuntansi | H202: Kontrak 1 | I202: 1
A203: SBY | B203: 198 | C203: RADINA PRESTICA HIDAYAH | D203: Staff Accounting | E203: Staff/Operator | F203: Accounting/Finan ce | G203: Akuntansi | H203: Kontrak 3
...

Sheet Weekly
A1: BIAYA TENAGA KERJA SBU COMMERCIAL PRINTING
A2: BULAN MARET 2022
A4: COST CENTER SDM | B4: BEKASI | F4: BASO | J4: NGANJUK | N4: JEMBER | R4: BALI | V4: ALIANSI | Z4: SURABAYA
B5: Minggu 1 | D5: Minggu 2 | F5: Minggu 1 | H5: Minggu 2 | J5: Minggu 1 | L5: Minggu 2 | N5: Minggu 1 | P5: Minggu 2 | R5: Minggu 1 | T5: Minggu 2 | V5: Minggu 1 | X5: Minggu 2 | Z5: Minggu 1 | AB5: Minggu 2
B6: SDM | C6: BIAYA | D6: SDM | E6: BIAYA | F6: SDM | G6: BIAYA | H6: SDM | I6: BIAYA | J6: SDM | K6: BIAYA | L6: SDM | M6: BIAYA | N6: SDM | O6: BIAYA | P6: SDM | Q6: BIAYA | R6: SDM | S6: BIAYA | T6: SDM | U6: BIAYA | V6: SDM | W6: BIAYA | X6: SDM | Y6: BIAYA | Z6: SDM | AA6: BIAYA | AB6: SDM | AC6: BIAYA
A7: Tetap | B7: 16 | C7: 21055892 | D7: 16 | E7: 21055892 | F7: =27+1 -> 28 | G7: =26823891+1556362 -> 28380253 | H7: =27+1 -> 28 | I7: =26823891+1556362 -> 28380253 | J7: 24 | K7: 23770653 | L7: 24 | M7: 23770653 | N7: 8 | O7: 7885114 | P7: 8 | Q7: 7885114 | R7: 12 | S7: 14239193 | T7: 12 | U7: 14239193 | V7: 10 | W7: 13770459 | X7: 10 | Y7: 13770459 | Z7: 105 | AA7: 134221683 | AB7: 105 | AC7: 134221683
A8: Kontrak | B8: 9 | C8: 15634679 | D8: 9 | E8: 15634679 | F8: =4+1 -> 5 | G8: =7063704+2862769 -> 9926473 | H8: =4+1 -> 5 | I8: =7063704+2862769 -> 9926473 | J8: 5 | K8: 11090615 | L8: 5 | M8: 11090615 | N8: 1 | O8: 1157522 | P8: 1 | Q8: 1157522 | R8: 3 | S8: 3774162 | T8: 3 | U8: 3774162 | V8: 2 | W8: 2318236 | X8: 2 | Y8: 2318236 | Z8: 25 | AA8: 44147314 | AB8: 25 | AC8: 44147314
A9: Harian Lepas | R9: 3 | S9: 7166617 | Z9: 13 | AA9: 55910000 | AB9: 6 | AC9: 27845000
A10: Outsourcing | R10: 0 | S10: 0 | Z10: 6 | AA10: 24069213 | AB10: 3 | AC10: 12208037
A11: Omset

Sheet NOTE
B5: Jadwal pertemuan HC , para GM dgn mas rudi JP
B6: rencana kebutuhan tenaker
B10: TMG JOB ORDER, ADA BULAN LOW SEASON ( JAN - AWAL MARET ) DAN ADA HIGH SEASON
B11: REGULER & PROJEK
B13: KEBUTUHAN TENAGA KERJA :
B14: TENAKER DI SUSUN MENURUT PEKERJAAN REGULER --- > FIX COST
B15: KEBUTUHAN TENAKER YG SIFATNYA PROJEK DI SUSUN / DIRENCANAKAN SERTA DI LAPORKAN TERSENDIRI------> VARIABLE COST
B17: FIX COST :
A18: A | B18: MEMPUNYAI SKILL DAN TIDAK MUDAH DI GANTIKAN
A19: B | B19: OPERATOR MESIN
A20: C | B20: HARUS ADA SECARA JUMLAH
B23: VARIABLE COST :
A24: A | B24: SAAT ADA PROYEK
A25: B | B25: SAAT ADA TAMBAHAN OMZET - KONDISIONAL
B28: UP DATE LAPORAN SUSUNAN TENAKER
B30: CATATAN :
B31: chalenge kemapanan
B32: minimum th lalu saat ini beda
B33: lonjakan naik pemakluman , saat turun harus segera
B34: kewenangan penambahan tenaker untuk hl dan borongan ?
B40: mengadakan meeting off line dgn direksi secara detail sebelum hari kamis
B44: replace , tenaker yg tidak produktif atau "virus negativ"

Sheet sby update
A1: IDEAL KEBUTUHAN SDM PERKOM 2024 | AD1: IDEAL KEBUTUHAN SDM PERKOM 2023
A2: CABANG SURABAYA | AD2: CABANG SURABAYA
A3: NO | B3: DIVISI | D3: MESIN | E3: KEBUTUHAN (ORANG) | F3: SHIFT | G3: FIX | K3: VARIABEL -- PROJEK | N3: SHIFT | O3: BIAYA (RP) | P3: EXISTING | T3: BIAYA (RP) | W3: OUTPUT/OMSET (RP) | X3: RASIO (%) | Z3: KETERANGAN | AD3: NO | AE3: DIVISI | AG3: MESIN | AH3: KEBUTUHAN (ORANG) | AI3: SHIFT | AJ3: FIX | AN3: VARIABEL -- PROJEK | AQ3: SHIFT | AR3: BIAYA (RP) | AS3: EXISTING | AW3: BIAYA (RP) | AZ3: OUTPUT/OMSET (RP) | BA3: RASIO (%) | BC3: KETERANGAN
G4: TETAP | H4: KONTRAK | I4: OS/HL | J4: TOTAL | K4: OS/HL | L4: KET | M4: TOTAL | P4: TETAP | Q4: KONTRAK | R4: OS/HL | S4: total | T4: TETAP | U4: KONTRAK | V4: OS/HL | AJ4: TETAP | AK4: KONTRAK | AL4: OS/HL | AM4: TOTAL | AN4: OS/HL | AO4: KET | AP4: TOTAL | AS4: TETAP | AT4: KONTRAK | AU4: OS/HL | AV4: total | AW4: TETAP | AX4: KONTRAK | AY4: OS/HL
A5: TOTAL SDM/BIAYA | E5: =SUM(E6:E91) -> 273 | G5: =SUM(G6:G91) -> 109 | H5: =SUM(H6:H91) -> 27 | I5: =SUM(I6:I91) -> 137 | J5: =SUM(J6:J91) -> 273 | K5: =SUM(K6:K91) -> 83 | M5: =SUM(M6:M91) -> 83 | P5: =SUM(P6:P91) -> 102 | Q5: =SUM(Q6:Q91) -> 27 | R5: =SUM(R6:R91) -> 167 | S5: =SUM(S6:S91) -> 296 | T5: 531336731 | U5: 170439257 | V5: =SUM(V6:V91) -> 0 | AD5: TOTAL SDM/BIAYA | AH5: =SUM(AH6:AH91) -> 273 | AJ5: =SUM(AJ6:AJ91) -> 109 | AK5: =SUM(AK6:AK91) -> 27 | AL5: =SUM(AL6:AL91) -> 137 | AM5: =SUM(AM6:AM91) -> 273 | AN5: =SUM(AN6:AN91) -> 83 | AP5: =SUM(AP6:AP91) -> 83 | AS5: =SUM(AS6:AS91) -> 102 | AT5: =SUM(AT6:AT91) -> 27 | AU5: =SUM(AU6:AU91) -> 167 | AV5: =SUM(AV6:AV91) -> 296 | AW5: 531336731 | AX5: 170439257 | AY5: =SUM(AY6:AY91) -> 0
A6: 1 | B6: GM | E6: 1 | G6: 1 | J6: =SUM(G6:I6) -> 1 | M6: =K6 | Q6: 1 | S6: =SUM(P6:R6) -> 1 | Y6: =S6-E6 -> 0 | AD6: 1 | AE6: GM | AH6: 1 | AJ6: 1 | AM6: =SUM(AJ6:AL6) -> 1 | AP6: =AN6 | AT6: 1 | AV6: =SUM(AS6:AU6) -> 1 | BB6: =AV6-AH6 -> 0
A7: 2 | B7: MANAGER | E7: 1 | G7: 1 | J7: =SUM(G7:I7) -> 1 | M7: =K7 | Q7: 1 | S7: =SUM(P7:R7) -> 1 | Y7: =S7-E7 -> 0 | AD7: 2 | AE7: MANAGER | AH7: 1 | AJ7: 1 | AM7: =SUM(AJ7:AL7) -> 1 | AP7: =AN7 | AT7: 1 | AV7: =SUM(AS7:AU7) -> 1 | BB7: =AV7-AH7 -> 0
A8: 3 | B8: ASMEN | E8: =SUM(G8:I8) -> 1 | G8: 1 | J8: =SUM(G8:I8) -> 1 | M8: =K8 | S8: =SUM(P8:R8) -> 0 | Y8: =S8-E8 -> -1 | AD8: 3 | AE8: ASMEN | AH8: =SUM(AJ8:AL8) -> 1 | AJ8: 1 | AM8: =SUM(AJ8:AL8) -> 1 | AP8: =AN8 | AV8: =SUM(AS8:AU8) -> 0 | BB8: =AV8-AH8 -> -1
A9: 4 | B9: KEUANGAN | D9: ACC | E9: =SUM(G9:I9) -> 2 | F9: 1 | G9: 1 | H9: 1 | J9: =SUM(G9:I9) -> 2 | M9: =K9 | N9: 1 | P9: 1 | Q9: 1 | S9: =SUM(P9:R9) -> 2 | Y9: =S9-E9 -> 0 | AD9: 4 | AE9: KEUANGAN | AG9: ACC | AH9: =SUM(AJ9:AL9) -> 2 | AI9: 1 | AJ9: 1 | AK9: 1 | AM9: =SUM(AJ9:AL9) -> 2 | AP9: =AN9 | AQ9: 1 | AS9: 1 | AT9: 1 | AV9: =SUM(AS9:AU9) -> 2 | BB9: =AV9-AH9 -> 0
D10: KASIR/KEU | E10: =SUM(G10:I10) -> 1 | F10: 1 | G10: 1 | J10: =SUM(G10:I10) -> 1 | M10: =K10 | N10: 1 | Q10: 1 | R10: 1 | S10: =SUM(P10:R10) -> 2 | Y10: =S10-E10 -> 1 | AG10: KASIR/KEU | AH10: =SUM(AJ10:AL10) -> 1 | AI10: 1 | AJ10: 1 | AM10: =SUM(AJ10:AL10) -> 1 | AP10: =AN10 | AQ10: 1 | AT10: 1 | AU10: 1 | AV10: =SUM(AS10:AU10) -> 2 | BB10: =AV10-AH10 -> 1
D11: INVOICING | E11: =SUM(G11:I11) -> 1 | F11: 1 | H11: 1 | J11: =SUM(G11:I11) -> 1 | M11: =K11 | N11: 1 | Q11: 1 | S11: =SUM(P11:R11) -> 1 | Y11: =S11-E11 -> 0 | AG11: INVOICING | AH11: =SUM(AJ11:AL11) -> 1 | AI11: 1 | AK11: 1 | AM11: =SUM(AJ11:AL11) -> 1 | AP11: =AN11 | AQ11: 1 | AT11: 1 | AV11: =SUM(AS11:AU11) -> 1 | BB11: =AV11-AH11 -> 0
D12: TRESURY | E12: =SUM(G12:I12) -> 2 | F12: 1 | G12: 2 | J12: =SUM(G12:I12) -> 2 | M12: =K12 | N12: 1 | P12: 2 | S12: =SUM(P12:R12) -> 2 | Y12: =S12-E12 -> 0 | AG12: TRESURY | AH12: =SUM(AJ12:AL12) -> 2 | AI12: 1 | AJ12: 2 | AM12: =SUM(AJ12:AL12) -> 2 | AP12: =AN12 | AQ12: 1 | AS12: 2 | AV12: =SUM(AS12:AU12) -> 2 | BB12: =AV12-AH12 -> 0
A13: 5 | B13: PURCHASING | D13: PURCHASING | E13: =SUM(G13:I13) -> 3 | F13: 1 | G13: 2 | H13: 1 | J13: =SUM(G13:I13) -> 3 | M13: =K13 | N13: 1 | P13: 2 | Q13: 1 | S13: =SUM(P13:R13) -> 3 | Y13: =S13-E13 -> 0 | AD13: 5 | AE13: PURCHASING | AG13: PURCHASING | AH13: =SUM(AJ13:AL13) -> 3 | AI13: 1 | AJ13: 2 | AK13: 1 | AM13: =SUM(AJ13:AL13) -> 3 | AP13: =AN13 | AQ13: 1 | AS13: 2 | AT13: 1 | AV13: =SUM(AS13:AU13) -> 3 | BB13: =AV13-AH13 -> 0
B14: MARKETING | D14: ADM MARKETING | E14: =SUM(G14:I14) -> 1 | F14: 1 | G14: 1 | J14: =SUM(G14:I14) -> 1 | K14: 1 | L14: E KATALOG 6-12 | M14: =K14 -> 1 | N14: 1 | P14: 1 | S14: =SUM(P14:R14) -> 1 | Y14: =S14-E14 -> 0 | AE14: MARKETING | AG14: ADM MARKETING | AH14: =SUM(AJ14:AL14) -> 1 | AI14: 1 | AJ14: 1 | AM14: =SUM(AJ14:AL14) -> 1 | AN14: 1 | AO14: E KATALOG 6-12 | AP14: =AN14 -> 1 | AQ14: 1 | AS14: 1 | AV14: =SUM(AS14:AU14) -> 1 | BB14: =AV14-AH14 -> 0
D15: MARKETING PROYEK | E15: =SUM(G15:I15) -> 2 | F15: 1 | G15: 2 | J15: =SUM(G15:I15) -> 2 | M15: =K15 | N15: 1 | P15: 2 | S15: =SUM(P15:R15) -> 2 | Y15: =S15-E15 -> 0 | AG15: MARKETING PROYEK | AH15: =SUM(AJ15:AL15) -> 2 | AI15: 1 | AJ15: 2 | AM15: =SUM(AJ15:AL15) -> 2 | AP15: =AN15 | AQ15: 1 | AS15: 2 | AV15: =SUM(AS15:AU15) -> 2 | BB15: =AV15-AH15 -> 0
D16: MARKETING | E16: =SUM(G16:I16) -> 20 | F16: 1 | G16: 12 | H16: 8 | J16: =SUM(G16:I16) -> 20 | M16: =K16 | N16: 1 | P16: 12 | Q16: 4 | S16: =SUM(P16:R16) -> 16 | Y16: =S16-E16 -> -4 | AG16: MARKETING | AH16: =SUM(AJ16:AL16) -> 20 | AI16: 1 | AJ16: 12 | AK16: 8 | AM16: =SUM(AJ16:AL16) -> 20 | AP16: =AN16 | AQ16: 1 | AS16: 12 | AT16: 4 | AV16: =SUM(AS16:AU16) -> 16 | BB16: =AV16-AH16 -> -4
A17: 6 | B17: HC | D17: HRD | E17: =SUM(G17:I17) -> 1 | F17: 1 | G17: 1 | J17: =SUM(G17:I17) -> 1 | M17: =K17 | N17: 1 | Q17: 1 | S17: =SUM(P17:R17) -> 1 | Y17: =S17-E17 -> 0 | AD17: 6 | AE17: HC | AG17: HRD | AH17: =SUM(AJ17:AL17) -> 1 | AI17: 1 | AJ17: 1 | AM17: =SUM(AJ17:AL17) -> 1 | AP17: =AN17 | AQ17: 1 | AT17: 1 | AV17: =SUM(AS17:AU17) -> 1 | BB17: =AV17-AH17 -> 0
D18: UMUM - TAMAN | E18: =SUM(G18:I18) -> 2 | F18: 1 | I18: 2 | J18: =SUM(G18:I18) -> 2 | M18: =K18 | N18: 1 | R18: 2 | S18: =SUM(P18:R18) -> 2 | Y18: =S18-E18 -> 0 | Z18: HL : Taman/Aval = 2, Aval/Sampah = 2, Gedung Komersial/Gudang = 1, Gedung Biru (Web/Reelstand) = 1, Office (3 lantai) = 1 KARYAWAN : Bank, Front Office, Driver, Building | AG18: UMUM - TAMAN | AH18: =SUM(AJ18:AL18) -> 2 | AI18: 1 | AL18: 2 | AM18: =SUM(AJ18:AL18) -> 2 | AP18: =AN18 | AQ18: 1 | AU18: 2 | AV18: =SUM(AS18:AU18) -> 2 | BB18: =AV18-AH18 -> 0 | BC18: HL : Taman/Aval = 2, Aval/Sampah = 2, Gedung Komersial/Gudang = 1, Gedung Biru (Web/Reelstand) = 1, Office (3 lantai) = 1 KARYAWAN : Bank, Front Office, Driver, Building
D19: UMUM - OFFICE | E19: =SUM(G19:I19) -> 2 | F19: 1 | I19: 2 | J19: =SUM(G19:I19) -> 2 | M19: =K19 | R19: 1 | S19: =SUM(P19:R19) -> 1 | Y19: =S19-E19 -> -1 | AG19: UMUM - OFFICE | AH19: =SUM(AJ19:AL19) -> 2 | AI19: 1 | AL19: 2 | AM19: =SUM(AJ19:AL19) -> 2 | AP19: =AN19 | AU19: 1 | AV19: =SUM(AS19:AU19) -> 1 | BB19: =AV19-AH19 -> -1
D20: UMUM - WEB | E20: =SUM(G20:I20) -> 2 | F20: 1 | I20: 2 | J20: =SUM(G20:I20) -> 2 | M20: =K20 | R20: 2 | S20: =SUM(P20:R20) -> 2 | Y20: =S20-E20 -> 0 | AG20: UMUM - WEB | AH20: =SUM(AJ20:AL20) -> 2 | AI20: 1 | AL20: 2 | AM20: =SUM(AJ20:AL20) -> 2 | AP20: =AN20 | AU20: 2 | AV20: =SUM(AS20:AU20) -> 2 | BB20: =AV20-AH20 -> 0
D21: UMUM - FINISHING | E21: =SUM(G21:I21) -> 3 | F21: 1 | I21: 3 | J21: =SUM(G21:I21) -> 3 | M21: =K21 | P21: 1 | R21: 2 | S21: =SUM(P21:R21) -> 3 | Y21: =S21-E21 -> 0 | AG21: UMUM - FINISHING | AH21: =SUM(AJ21:AL21) -> 3 | AI21: 1 | AL21: 3 | AM21: =SUM(AJ21:AL21) -> 3 | AP21: =AN21 | AS21: 1 | AU21: 2 | AV21: =SUM(AS21:AU21) -> 3 | BB21: =AV21-AH21 -> 0
D22: UMUM- DRIVER BANK | E22: =SUM(G22:I22) -> 2 | F22: 1 | G22: 1 | H22: 1 | J22: =SUM(G22:I22) -> 2 | M22: =K22 | Q22: 1 | S22: =SUM(P22:R22) -> 1 | Y22: =S22-E22 -> -1 | AG22: UMUM- DRIVER BANK | AH22: =SUM(AJ22:AL22) -> 2 | AI22: 1 | AJ22: 1 | AK22: 1 | AM22: =SUM(AJ22:AL22) -> 2 | AP22: =AN22 | AT22: 1 | AV22: =SUM(AS22:AU22) -> 1 | BB22: =AV22-AH22 -> -1
D23: UMUM - KOORDINATOR | E23: =SUM(G23:I23) -> 1 | F23: 1 | H23: 1 | J23: =SUM(G23:I23) -> 1 | M23: =K23 | Q23: 1 | S23: =SUM(P23:R23) -> 1 | Y23: =S23-E23 -> 0 | AG23: UMUM - KOORDINATOR | AH23: =SUM(AJ23:AL23) -> 1 | AI23: 1 | AK23: 1 | AM23: =SUM(AJ23:AL23) -> 1 | AP23: =AN23 | AT23: 1 | AV23: =SUM(AS23:AU23) -> 1 | BB23: =AV23-AH23 -> 0
D24: UMUM- ADMIN + CS | E24: =SUM(G24:I24) -> 1 | F24: 1 | G24: 1 | J24: =SUM(G24:I24) -> 1 | M24: =K24 | P24: 1 | S24: =SUM(P24:R24) -> 1 | Y24: =S24-E24 -> 0 | AG24: UMUM- ADMIN + CS | AH24: =SUM(AJ24:AL24) -> 1 | AI24: 1 | AJ24: 1 | AM24: =SUM(AJ24:AL24) -> 1 | AP24: =AN24 | AS24: 1 | AV24: =SUM(AS24:AU24) -> 1 | BB24: =AV24-AH24 -> 0
D25: UMUM - KM WC | E25: =SUM(G25:I25) -> 1 | F25: 1 | I25: 1 | J25: =SUM(G25:I25) -> 1 | M25: =K25 | R25: 1 | S25: =SUM(P25:R25) -> 1 | Y25: =S25-E25 -> 0 | AG25: UMUM - KM WC | AH25: =SUM(AJ25:AL25) -> 1 | AI25: 1 | AL25: 1 | AM25: =SUM(AJ25:AL25) -> 1 | AP25: =AN25 | AU25: 1 | AV25: =SUM(AS25:AU25) -> 1 | BB25: =AV25-AH25 -> 0
D26: SECURITY | E26: =SUM(G26:I26) -> 8 | F26: 3 | I26: 8 | J26: =SUM(G26:I26) -> 8 | M26: =K26 | N26: 3 | R26: 7 | S26: =SUM(P26:R26) -> 7 | Y26: =S26-E26 -> -1 | AG26: SECURITY | AH26: =SUM(AJ26:AL26) -> 8 | AI26: 3 | AL26: 8 | AM26: =SUM(AJ26:AL26) -> 8 | AP26: =AN26 | AQ26: 3 | AU26: 7 | AV26: =SUM(AS26:AU26) -> 7 | BB26: =AV26-AH26 -> -1
A27: 7 | B27: PPIC | D27: PLANNING | E27: =SUM(G27:I27) -> 4 | F27: 1 | G27: 3 | H27: 1 | J27: =SUM(G27:I27) -> 4 | M27: =K27 | N27: 1 | P27: 1 | Q27: 1 | S27: =SUM(P27:R27) -> 2 | Y27: =S27-E27 -> -2 | AD27: 7 | AE27: PPIC | AG27: PLANNING | AH27: =SUM(AJ27:AL27) -> 4 | AI27: 1 | AJ27: 3 | AK27: 1 | AM27: =SUM(AJ27:AL27) -> 4 | AP27: =AN27 | AQ27: 1 | AS27: 1 | AT27: 1 | AV27: =SUM(AS27:AU27) -> 2 | BB27: =AV27-AH27 -> -2
D28: MANUFAKTUR | E28: =SUM(G28:I28) -> 1 | F28: 1 | G28: 1 | J28: =SUM(G28:I28) -> 1 | M28: =K28 | P28: 1 | S28: =SUM(P28:R28) -> 1 | Y28: =S28-E28 -> 0 | AG28: MANUFAKTUR | AH28: =SUM(AJ28:AL28) -> 1 | AI28: 1 | AJ28: 1 | AM28: =SUM(AJ28:AL28) -> 1 | AP28: =AN28 | AS28: 1 | AV28: =SUM(AS28:AU28) -> 1 | BB28: =AV28-AH28 -> 0
D29: GUDANG BAHAN BAKU + SPAREPART | E29: =SUM(G29:I29) -> 7 | F29: 3 | G29: 5 | I29: 2 | J29: =SUM(G29:I29) -> 7 | M29: =K29 | N29: 3 | P29: 6 | R29: 2 | S29: =SUM(P29:R29) -> 8 | Y29: =S29-E29 -> 1 | AG29: GUDANG BAHAN BAKU + SPAREPART | AH29: =SUM(AJ29:AL29) -> 7 | AI29: 3 | AJ29: 5 | AL29: 2 | AM29: =SUM(AJ29:AL29) -> 7 | AP29: =AN29 | AQ29: 3 | AS29: 6 | AU29: 2 | AV29: =SUM(AS29:AU29) -> 8 | BB29: =AV29-AH29 -> 1
D30: GUDANG BARANG JADI | E30: =SUM(G30:I30) -> 2 | F30: 1 | G30: 1 | I30: 1 | J30: =SUM(G30:I30) -> 2 | K30: 1 | L30: KURMER | M30: =K30 -> 1 | N30: 1 | P30: 2 | R30: 1 | S30: =SUM(P30:R30) -> 3 | Y30: =S30-E30 -> 1 | AG30: GUDANG BARANG JADI | AH30: =SUM(AJ30:AL30) -> 2 | AI30: 1 | AJ30: 1 | AL30: 1 | AM30: =SUM(AJ30:AL30) -> 2 | AN30: 1 | AO30: KURMER | AP30: =AN30 -> 1 | AQ30: 1 | AS30: 2 | AU30: 1 | AV30: =SUM(AS30:AU30) -> 3 | BB30: =AV30-AH30 -> 1
D31: EKSPEDISI- 3 MOBIL | E31: =SUM(G31:I31) -> 5 | F31: 1 | G31: 3 | I31: 2 | J31: =SUM(G31:I31) -> 5 | M31: =K31 | N31: 1 | P31: 2 | R31: 2 | S31: =SUM(P31:R31) -> 4 | Y31: =S31-E31 -> -1 | AG31: EKSPEDISI- 3 MOBIL | AH31: =SUM(AJ31:AL31) -> 5 | AI31: 1 | AJ31: 3 | AL31: 2 | AM31: =SUM(AJ31:AL31) -> 5 | AP31: =AN31 | AQ31: 1 | AS31: 2 | AU31: 2 | AV31: =SUM(AS31:AU31) -> 4 | BB31: =AV31-AH31 -> -1
A32: 8 | B32: QC | D32: QC - JP | E32: =SUM(G32:I32) -> 1 | F32: 1 | G32: 1 | J32: =SUM(G32:I32) -> 1 | M32: =K32 | N32: 3 | P32: 2 | R32: 3 | S32: =SUM(P32:R32) -> 5 | Y32: =S32-E32 -> 4 | AD32: 8 | AE32: QC | AG32: QC - JP | AH32: =SUM(AJ32:AL32) -> 1 | AI32: 1 | AJ32: 1 | AM32: =SUM(AJ32:AL32) -> 1 | AP32: =AN32 | AQ32: 3 | AS32: 2 | AU32: 3 | AV32: =SUM(AS32:AU32) -> 5 | BB32: =AV32-AH32 -> 4
D33: QC - KOMERSIAL | E33: =SUM(G33:I33) -> 5 | F33: 3 | H33: 2 | I33: 3 | J33: =SUM(G33:I33) -> 5 | M33: =K33 | Q33: 2 | S33: =SUM(P33:R33) -> 2 | Y33: =S33-E33 -> -3 | AG33: QC - KOMERSIAL | AH33: =SUM(AJ33:AL33) -> 5 | AI33: 3 | AK33: 2 | AL33: 3 | AM33: =SUM(AJ33:AL33) -> 5 | AP33: =AN33 | AT33: 2 | AV33: =SUM(AS33:AU33) -> 2 | BB33: =AV33-AH33 -> -3
A34: 9 | B34: TEKNIK | D34: MEKANIK | E34: =SUM(G34:I34) -> 14 | F34: 3 | G34: 8 | H34: 3 | I34: 3 | J34: =SUM(G34:I34) -> 14 | M34: =K34 | N34: 3 | P34: 8 | Q34: 2 | R34: 3 | S34: =SUM(P34:R34) -> 13 | Y34: =S34-E34 -> -1 | AD34: 9 | AE34: TEKNIK | AG34: MEKANIK | AH34: =SUM(AJ34:AL34) -> 14 | AI34: 3 | AJ34: 8 | AK34: 3 | AL34: 3 | AM34: =SUM(AJ34:AL34) -> 14 | AP34: =AN34 | AQ34: 3 | AS34: 8 | AT34: 2 | AU34: 3 | AV34: =SUM(AS34:AU34) -> 13 | BB34: =AV34-AH34 -> -1
D35: ELEKTRIK | E35: =SUM(G35:I35) -> 7 | F35: 3 | G35: 6 | H35: 1 | J35: =SUM(G35:I35) -> 7 | M35: =K35 | N35: 3 | P35: 6 | Q35: 2 | R35: 3 | S35: =SUM(P35:R35) -> 11 | Y35: =S35-E35 -> 4 | AG35: ELEKTRIK | AH35: =SUM(AJ35:AL35) -> 7 | AI35: 3 | AJ35: 6 | AK35: 1 | AM35: =SUM(AJ35:AL35) -> 7 | AP35: =AN35 | AQ35: 3 | AS35: 6 | AT35: 2 | AU35: 3 | AV35: =SUM(AS35:AU35) -> 11 | BB35: =AV35-AH35 -> 4
A36: 10 | B36: IT | D36: JARINGAN | E36: =SUM(G36:I36) -> 2 | F36: 1 | G36: 2 | J36: =SUM(G36:I36) -> 2 | M36: =K36 | N36: 1 | P36: 2 | S36: =SUM(P36:R36) -> 2 | Y36: =S36-E36 -> 0 | AD36: 10 | AE36: IT | AG36: JARINGAN | AH36: =SUM(AJ36:AL36) -> 2 | AI36: 1 | AJ36: 2 | AM36: =SUM(AJ36:AL36) -> 2 | AP36: =AN36 | AQ36: 1 | AS36: 2 | AV36: =SUM(AS36:AU36) -> 2 | BB36: =AV36-AH36 -> 0
A37: 11 | B37: PRACETAK | C37: 1 | D37: KODAK 1- JP KOM | E37: =SUM(G37:I37) -> 2 | F37: 3 | G37: 1 | I37: 1 | J37: =SUM(G37:I37) -> 2 | M37: =K37 | N37: 1 | P37: 1 | S37: =SUM(P37:R37) -> 1 | Y37: =S37-E37 -> -1 | AD37: 11 | AE37: PRACETAK | AF37: 1 | AG37: KODAK 1- JP KOM | AH37: =SUM(AJ37:AL37) -> 2 | AI37: 3 | AJ37: 1 | AL37: 1 | AM37: =SUM(AJ37:AL37) -> 2 | AP37: =AN37 | AQ37: 1 | AS37: 1 | AV37: =SUM(AS37:AU37) -> 1 | BB37: =AV37-AH37 -> -1
C38: 2 | D38: KODAK 2- JP KOM | E38: =SUM(G38:I38) -> 1 | F38: 3 | G38: 1 | J38: =SUM(G38:I38) -> 1 | M38: =K38 | N38: 3 | P38: 1 | S38: =SUM(P38:R38) -> 1 | Y38: =S38-E38 -> 0 | AF38: 2 | AG38: KODAK 2- JP KOM | AH38: =SUM(AJ38:AL38) -> 1 | AI38: 3 | AJ38: 1 | AM38: =SUM(AJ38:AL38) -> 1 | AP38: =AN38 | AQ38: 3 | AS38: 1 | AV38: =SUM(AS38:AU38) -> 1 | BB38: =AV38-AH38 -> 0
C39: 3 | D39: SCREEN 1 - JP | E39: =SUM(G39:I39) -> 1 | F39: 3 | G39: 1 | J39: =SUM(G39:I39) -> 1 | M39: =K39 | N39: 2 | P39: 1 | R39: 1 | S39: =SUM(P39:R39) -> 2 | Y39: =S39-E39 -> 1 | AF39: 3 | AG39: SCREEN 1 - JP | AH39: =SUM(AJ39:AL39) -> 1 | AI39: 3 | AJ39: 1 | AM39: =SUM(AJ39:AL39) -> 1 | AP39: =AN39 | AQ39: 2 | AS39: 1 | AU39: 1 | AV39: =SUM(AS39:AU39) -> 2 | BB39: =AV39-AH39 -> 1
C40: 4 | D40: A8T- JP KOM | E40: =SUM(G40:I40) -> 1 | F40: 3 | G40: 1 | J40: =SUM(G40:I40) -> 1 | M40: =K40 | N40: 3 | P40: 1 | S40: =SUM(P40:R40) -> 1 | Y40: =S40-E40 -> 0 | AF40: 4 | AG40: A8T- JP KOM | AH40: =SUM(AJ40:AL40) -> 1 | AI40: 3 | AJ40: 1 | AM40: =SUM(AJ40:AL40) -> 1 | AP40: =AN40 | AQ40: 3 | AS40: 1 | AV40: =SUM(AS40:AU40) -> 1 | BB40: =AV40-AH40 -> 0
...

Sheet SBY
A1: IDEAL KEBUTUHAN SDM PERKOM 2025
A2: CABANG SURABAYA | L2: 0.05 | R2: average upah dan dikalikan jumlah sdm
A3: NO | B3: DIVISI | C3: MESIN | D3: KEBUTUHAN | I3: SHIFT | J3: BIAYA (RP) | N3: EXISTING | S3: BIAYA (RP) | W3: OUTPUT/OMSET (RP) | X3: RASIO (%) | Y3: KETERANGAN
D4: TETAP | E4: KONTRAK | F4: OS FIX | G4: OS VAR | H4: TOTAL | J4: TETAP | K4: KONTRAK | L4: OS/FIX COST | M4: OS/VAR COST | N4: TETAP | O4: KONTRAK | P4: OS FIX | Q4: OS VAR | R4: total | S4: TETAP | T4: KONTRAK | U4: OS/FIX COST | V4: OS/VAR COST
A5: TOTAL SDM/BIAYA | D5: =SUM(D6:D110) -> 119 | E5: =SUM(E6:E110) -> 11 | F5: =SUM(F6:F110) -> 182 | G5: =SUM(G6:G110) -> 270 | H5: =SUM(H6:H110) -> 582 | J5: =SUM(J6:J110) -> 0 | K5: =SUM(K6:K110) -> 0 | L5: =SUM(L6:L110) -> 4.4338781e+08 | M5: =SUM(M6:M110) -> 500631250 | N5: =SUM(N6:N110) -> 101 | O5: =SUM(O6:O110) -> 23 | P5: =SUM(P6:P110) -> 114 | Q5: =SUM(Q6:Q110) -> 204 | ... V5: =SUM(V6:V110) -> 360125000 | Y5: Selisih Tetap/Kontrak
A6: 1 | B6: GM | D6: 1 | H6: =SUM(D6:G6) -> 1 | O6: 1 | R6: =SUM(N6:Q6) -> 1 | AB6: =SUM(N6:O6)-SUM(D6:E6) -> 0
A7: 2 | B7: MANAGER | H7: =SUM(D7:G7) -> 0 | R7: =SUM(N7:Q7) -> 0 | AB7: =SUM(N7:O7)-SUM(D7:E7) -> 0
A8: 3 | B8: ASMEN | D8: 2 | H8: =SUM(D8:G8) -> 2 | N8: 1 | O8: 1 | R8: =SUM(N8:Q8) -> 2 | AB8: =SUM(N8:O8)-SUM(D8:E8) -> 0
A9: 4 | B9: KEUANGAN | C9: ACC | D9: 3 | E9: 1 | H9: =SUM(D9:G9) -> 4 | I9: 1 | L9: =U9*(1+$L$2) -> 4200000 | M9: =V9*(1+$L$2) -> 0 | O9: 3 | P9: 1 | R9: =SUM(N9:Q9) -> 4 | U9: =200000*20*P9 -> 4000000 | AB9: =SUM(N9:O9)-SUM(D9:E9) -> -1
C10: KASIR/KEU | E10: 1 | H10: =SUM(D10:G10) -> 1 | I10: 1 | L10: =U10*(1+$L$2) -> 0 | M10: =V10*(1+$L$2) -> 0 | O10: 1 | R10: =SUM(N10:Q10) -> 1 | AB10: =SUM(N10:O10)-SUM(D10:E10) -> 0
C11: INVOICING | D11: 1 | H11: =SUM(D11:G11) -> 1 | I11: 1 | L11: =U11*(1+$L$2) -> 0 | M11: =V11*(1+$L$2) -> 0 | N11: 1 | R11: =SUM(N11:Q11) -> 1 | AB11: =SUM(N11:O11)-SUM(D11:E11) -> 0
C12: TRESURY | D12: 2 | H12: =SUM(D12:G12) -> 2 | I12: 1 | L12: =U12*(1+$L$2) -> 0 | M12: =V12*(1+$L$2) -> 0 | N12: 1 | O12: 1 | R12: =SUM(N12:Q12) -> 2 | AB12: =SUM(N12:O12)-SUM(D12:E12) -> 0
A13: 2 | B13: PURCHASING | C13: PURCHASING | D13: 2 | H13: =SUM(D13:G13) -> 2 | I13: 1 | L13: =U13*(1+$L$2) -> 0 | M13: =V13*(1+$L$2) -> 0 | N13: 2 | R13: =SUM(N13:Q13) -> 2 | AB13: =SUM(N13:O13)-SUM(D13:E13) -> 0
B14: MARKETING | C14: ADM MARKETING | D14: 1 | F14: 2 | H14: =SUM(D14:G14) -> 3 | I14: 1 | L14: =U14*(1+$L$2) -> 6720000 | M14: =V14*(1+$L$2) -> 0 | N14: 1 | P14: 2 | R14: =SUM(N14:Q14) -> 3 | U14: =160000*20*2 -> 6400000 | AB14: =SUM(N14:O14)-SUM(D14:E14) -> 0
C15: MARKETING PROYEK | D15: 2 | H15: =SUM(D15:G15) -> 2 | I15: 1 | L15: =U15*(1+$L$2) -> 0 | M15: =V15*(1+$L$2) -> 0 | N15: 2 | R15: =SUM(N15:Q15) -> 2 | AB15: =SUM(N15:O15)-SUM(D15:E15) -> 0
C16: MARKETING | D16: 9 | E16: 4 | H16: =SUM(D16:G16) -> 13 | I16: 1 | L16: =U16*(1+$L$2) -> 3412500 | M16: =V16*(1+$L$2) -> 0 | N16: 9 | O16: 3 | P16: 1 | R16: =SUM(N16:Q16) -> 13 | U16: =130000*25*1 -> 3250000 | AB16: =SUM(N16:O16)-SUM(D16:E16) -> -1
A17: 4 | B17: HC | C17: HRD | D17: 1 | H17: =SUM(D17:G17) -> 1 | I17: 1 | L17: =U17*(1+$L$2) -> 0 | M17: =V17*(1+$L$2) -> 0 | N17: 1 | R17: =SUM(N17:Q17) -> 1 | AB17: =SUM(N17:O17)-SUM(D17:E17) -> 0
C18: GA/UMUM | D18: 5 | H18: =SUM(D18:G18) -> 5 | I18: 1 | L18: =U18*(1+$L$2) -> 0 | M18: =V18*(1+$L$2) -> 0 | N18: 3 | O18: 2 | R18: =SUM(N18:Q18) -> 5 | Y18: HL : Taman/Aval = 2, Kamar mandi = 1, Gedung Komersial/Gudang = 3, Gedung Biru & Basement (Web/Reelstand) = 4, Office (3 lantai) = 2 KARYAWAN : Bank, Front Office, Driver, Building | AB18: =SUM(N18:O18)-SUM(D18:E18) -> 0
C19: TAMAN/AVAL | F19: 2 | H19: =SUM(D19:G19) -> 2 | I19: 1 | L19: =U19*(1+$L$2) -> 4501875 | M19: =V19*(1+$L$2) -> 0 | P19: 2 | R19: =SUM(N19:Q19) -> 2 | U19: =85750*25*P19 -> 4287500 | AB19: =SUM(N19:O19)-SUM(D19:E19) -> 0
C20: KAMAR MANDI | F20: 1 | H20: =SUM(D20:G20) -> 1 | I20: 1 | L20: =U20*(1+$L$2) -> 2598750 | M20: =V20*(1+$L$2) -> 0 | P20: 1 | R20: =SUM(N20:Q20) -> 1 | U20: =99000*25*P20 -> 2475000 | AB20: =SUM(N20:O20)-SUM(D20:E20) -> 0
C21: GEDUNG KOMERSIAL/GUDANG | F21: 3 | H21: =SUM(D21:G21) -> 3 | I21: 1 | L21: =U21*(1+$L$2) -> 6752812.5 | M21: =V21*(1+$L$2) -> 0 | P21: 3 | R21: =SUM(N21:Q21) -> 3 | U21: =85750*25*P21 -> 6431250 | AB21: =SUM(N21:O21)-SUM(D21:E21) -> 0
C22: GEDUNG BIRU & BASEMENT (Web/Reelstand) | F22: 3 | H22: =SUM(D22:G22) -> 3 | I22: 2 | L22: =U22*(1+$L$2) -> 6752812.5 | M22: =V22*(1+$L$2) -> 0 | P22: 3 | R22: =SUM(N22:Q22) -> 3 | U22: =85750*25*P22 -> 6431250 | AB22: =SUM(N22:O22)-SUM(D22:E22) -> 0
C23: OFFICE 3 LT | F23: 3 | H23: =SUM(D23:G23) -> 3 | I23: 1 | L23: =U23*(1+$L$2) -> 6181875 | M23: =V23*(1+$L$2) -> 0 | P23: 3 | R23: =SUM(N23:Q23) -> 3 | U23: =78500*25*P23 -> 5887500 | AB23: =SUM(N23:O23)-SUM(D23:E23) -> 0
C24: SECURITY | F24: 7 | H24: =SUM(D24:G24) -> 7 | I24: 4 | L24: =U24*(1+$L$2) -> 30135000 | M24: =V24*(1+$L$2) -> 0 | P24: 7 | R24: =SUM(N24:Q24) -> 7 | U24: =164000*25*P24 -> 28700000 | AB24: =SUM(N24:O24)-SUM(D24:E24) -> 0
A25: 5 | B25: PPIC | C25: PLANNING | D25: 4 | E25: 1 | F25: 1 | H25: =SUM(D25:G25) -> 6 | I25: 1 | L25: =U25*(1+$L$2) -> 2100000 | M25: =V25*(1+$L$2) -> 0 | N25: 4 | P25: 1 | R25: =SUM(N25:Q25) -> 5 | U25: =80000*25*P25 -> 2000000 | AB25: =SUM(N25:O25)-SUM(D25:E25) -> -1
C26: GUDANG BAHAN BAKU + SPAREPART | D26: 6 | G26: 2 | H26: =SUM(D26:G26) -> 8 | I26: 3 | L26: =U26*(1+$L$2) -> 0 | M26: =V26*(1+$L$2) -> 3937500 | N26: 6 | Q26: 2 | R26: =SUM(N26:Q26) -> 8 | U26: =75000*25*P26 -> 0 | V26: =75000*25*Q26 -> 3750000 | AB26: =SUM(N26:O26)-SUM(D26:E26) -> 0
C27: GUDANG BARANG JADI | D27: 3 | F27: 1 | G27: 3 | H27: =SUM(D27:G27) -> 7 | I27: 2 | L27: =U27*(1+$L$2) -> 2441250 | M27: =V27*(1+$L$2) -> 7323750 | N27: 3 | P27: 1 | Q27: 3 | R27: =SUM(N27:Q27) -> 7 | U27: =93000*25*P27 -> 2325000 | V27: =93000*25*Q27 -> 6975000 | AB27: =SUM(N27:O27)-SUM(D27:E27) -> 0
C28: EKSPEDISI | D28: 1 | G28: 2 | H28: =SUM(D28:G28) -> 3 | I28: 1 | L28: =U28*(1+$L$2) -> 0 | M28: =V28*(1+$L$2) -> 4882500 | N28: 1 | Q28: 2 | R28: =SUM(N28:Q28) -> 3 | V28: =93000*25*Q28 -> 4650000 | AB28: =SUM(N28:O28)-SUM(D28:E28) -> 0
A29: 6 | B29: R&D | C29: R&D | E29: 1 | F29: 1 | H29: =SUM(D29:G29) -> 2 | I29: 3 | M29: =V29*(1+$L$2) -> 0 | R29: =SUM(N29:Q29) -> 0 | U29: =91667*25*P29 -> 0 | AB29: =SUM(N29:O29)-SUM(D29:E29) -> -1
A30: 6 | B30: QA | C30: QC | D30: 3 | F30: 3 | H30: =SUM(D30:G30) -> 6 | I30: 3 | L30: =U30*(1+$L$2) -> 7218776.2 | M30: =V30*(1+$L$2) -> 0 | N30: 1 | O30: 2 | P30: 3 | R30: =SUM(N30:Q30) -> 6 | U30: =91667*25*P30 -> 6875025 | AB30: =SUM(N30:O30)-SUM(D30:E30) -> 0
A31: 7 | B31: TEKNIK | C31: MEKANIK | D31: 10 | F31: 5 | H31: =SUM(D31:G31) -> 15 | I31: 3 | L31: =U31*(1+$L$2) -> 14700000 | M31: =V31*(1+$L$2) -> 0 | N31: 8 | O31: 2 | P31: 5 | R31: =SUM(N31:Q31) -> 15 | U31: =112000*25*P31 -> 14000000 | AB31: =SUM(N31:O31)-SUM(D31:E31) -> 0
C32: ELEKTRIK | D32: 6 | E32: 1 | H32: =SUM(D32:G32) -> 7 | I32: 3 | L32: =U32*(1+$L$2) -> 0 | M32: =V32*(1+$L$2) -> 0 | N32: 6 | R32: =SUM(N32:Q32) -> 6 | AB32: =SUM(N32:O32)-SUM(D32:E32) -> -1
B33: IT | D33: 2 | H33: =SUM(D33:G33) -> 2 | I33: 1 | L33: =U33*(1+$L$2) -> 0 | M33: =V33*(1+$L$2) -> 0 | N33: 2 | R33: =SUM(N33:Q33) -> 2 | AB33: =SUM(N33:O33)-SUM(D33:E33) -> 0
A34: 8 | B34: PRACETAK | C34: KODAK 1 | D34: 5 | F34: 1 | H34: =SUM(D34:G34) -> 6 | I34: 1 | K34: =4874132*E34 -> 0 | L34: =U34*(1+$L$2) -> 3648750 | M34: =V34*(1+$L$2) -> 0 | N34: 5 | P34: 1 | R34: =SUM(N34:Q34) -> 6 | U34: =139000*25*P34 -> 3475000 | Y34: 2 | AB34: =SUM(N34:O34)-SUM(D34:E34) -> 0
C35: KODAK 2 | I35: 3 | L35: =U35*(1+$L$2) -> 0 | M35: =V35*(1+$L$2) -> 0 | AB35: =SUM(N35:O35)-SUM(D35:E35) -> 0
C36: SCREEN 1 | I36: 2 | L36: =U36*(1+$L$2) -> 0 | M36: =V36*(1+$L$2) -> 0 | AB36: =SUM(N36:O36)-SUM(D36:E36) -> 0
C37: A8T | I37: 3 | L37: =U37*(1+$L$2) -> 0 | M37: =V37*(1+$L$2) -> 0 | AB37: =SUM(N37:O37)-SUM(D37:E37) -> 0
C38: AVALON | I38: 1 | L38: =U38*(1+$L$2) -> 0 | M38: =V38*(1+$L$2) -> 0 | AB38: =SUM(N38:O38)-SUM(D38:E38) -> 0
A39: 3 | C39: MD | D39: 1 | E39: 1 | H39: =SUM(D39:G39) -> 2 | I39: 1 | L39: =U39*(1+$L$2) -> 0 | M39: =V39*(1+$L$2) -> 0 | N39: 1 | O39: 1 | R39: =SUM(N39:Q39) -> 2 | AB39: =SUM(N39:O39)-SUM(D39:E39) -> 0
A40: a | B40: SHEET | C40: KOMORI 1 | D40: 3 | F40: 5 | H40: =SUM(D40:G40) -> 8 | I40: 3 | L40: =U40*(1+$L$2) -> 11494481 | M40: =V40*(1+$L$2) -> 0 | N40: 3 | P40: 5 | R40: =SUM(N40:Q40) -> 8 | U40: =87577*25*P40 -> 10947125 | AB40: =SUM(N40:O40)-SUM(D40:E40) -> 0
...

Sheet BKS
A1: IDEAL KEBUTUHAN SDM PERKOM 2024 | W1: SELISIH | AB1: IDEAL KEBUTUHAN SDM PERKOM 2023 | AO1: SELISIH
A2: CABANG BEKASI (GUDANG SENTRAL) | L2: 0.05 | N2: =SUBTOTAL(9,N6:N14) -> 0 | O2: =SUBTOTAL(9,O6:O14) -> 1 | P2: =SUBTOTAL(9,P6:P14) -> 13 | S2: =SUM(N2:P2) -> 14 | U2: w32 | W2: =78-65 -> 13 | AB2: CABANG BEKASI | AH2: =SUBTOTAL(9,AH6:AH38) -> 18 | AI2: =SUBTOTAL(9,AI6:AI38) -> 9 | AJ2: =SUBTOTAL(9,AJ6:AJ38) -> 56.6 | AL2: =SUM(AH2:AJ2) -> 83.6 | AO2: =78-65 -> 13
A3: NO | B3: DIVISI | C3: MESIN | D3: Kebutuhan (Orang) | I3: SHIFT | J3: BIAYA (RP) | N3: EXISTING | S3: BIAYA (RP) | W3: OUTPUT/OMSET (RP) | X3: RASIO (%) | Y3: KETERANGAN | AB3: NO | AC3: DIVISI | AD3: MESIN | AE3: Kebutuhan (Orang) | AF3: SHIFT | AG3: BIAYA (RP) | AH3: EXISTING | AL3: BIAYA (RP) | AO3: OUTPUT/OMSET (RP) | AP3: RASIO (%) | AQ3: KETERANGAN
D4: TETAP | E4: KONTRAK | F4: OS FIX | G4: OS VAR | H4: total | J4: TETAP | K4: KONTRAK | L4: OS/FIX COST | M4: OS/VAR COST | N4: TETAP | O4: KONTRAK | P4: OS FIX | Q4: OS VAR | R4: total | S4: TETAP | T4: KONTRAK | U4: OS/FIX COST | V4: OS/VAR COST | AH4: TETAP | AI4: KONTRAK | AJ4: OS/HL | AK4: total | AL4: TETAP | AM4: KONTRAK | AN4: OS/HL
A5: TOTAL SDM/BIAYA | D5: =SUBTOTAL(9,D6:D14) -> 0 | E5: =SUBTOTAL(9,E6:E14) -> 1 | F5: =SUBTOTAL(9,F6:F14) -> 13 | G5: =SUBTOTAL(9,G6:G14) -> 6 | H5: =SUBTOTAL(9,H6:H14) -> 14 | L5: =SUBTOTAL(9,L6:L14) -> 37780851 | M5: =SUBTOTAL(9,M6:M14) -> 32881356 | N5: =SUBTOTAL(9,N6:N14) -> 0 | O5: =SUBTOTAL(9,O6:O14) -> 1 | P5: =SUBTOTAL(9,P6:P14) -> 13 | Q5: =SUBTOTAL(9,Q6:Q14) -> 0 | R5: =SUBTOTAL(9,R6:R14) -> 14 | S5: 84223569 | T5: 60488716 | U5: =SUBTOTAL(9,U6:U14) -> 35981763 | AB5: TOTAL SDM/BIAYA | AE5: =SUBTOTAL(9,AE6:AE38) -> 84 | AH5: =SUBTOTAL(9,AH6:AH38) -> 18 | AI5: =SUBTOTAL(9,AI6:AI38) -> 9 | AJ5: =SUBTOTAL(9,AJ6:AJ38) -> 56.6 | AL5: 84223569 | AM5: 60488716 | AN5: =SUBTOTAL(9,AN6:AN38) -> 0
A6: 1 | B6: GA/UMUM | C6: GA/UMUM | F6: 1 | H6: =SUM(D6:F6) -> 1 | L6: =U6*(1+$L$2) -> 2100000 | P6: 1 | R6: =SUM(N6:P6) -> 1 | U6: =80000*25*P6 -> 2000000 | AC6: BM | AE6: 1 | AF6: 1 | AH6: 1 | AK6: =SUM(AH6:AJ6) -> 1
C7: SECURITY | F7: 1 | H7: =SUM(D7:F7) -> 1 | L7: =U7*(1+$L$2) -> 5480226.2 | P7: 1 | R7: =SUM(N7:P7) -> 1 | U7: =5219263*P7 -> 5219263 | AC7: KADIV PRODUKSI | AE7: 1 | AF7: 1 | AI7: 1 | AK7: =SUM(AH7:AJ7) -> 1
B8: MARKETING | C8: MARKETINIG | F8: 1 | H8: =SUM(D8:F8) -> 1 | L8: =U8*(1+$L$2) -> 3937500 | P8: 1 | R8: =SUM(N8:P8) -> 1 | U8: =150000*25*P8 -> 3750000
A9: 2 | B9: GUDANG SENTRAL | C9: ADMIN GUDANG | F9: 2 | H9: =SUM(D9:F9) -> 2 | L9: =U9*(1+$L$2) -> 7087500 | P9: 2 | R9: =SUM(N9:P9) -> 2 | U9: =135000*25*P9 -> 6750000 | AC9: KARU PRODUKSI | AE9: 1 | AF9: 1 | AI9: 1 | AK9: =SUM(AH9:AJ9) -> 1 | AQ9: QC SHIFT PAGI
C10: GUDANG | E10: 1 | F10: 1 | H10: =SUM(D10:F10) -> 2 | K10: =T10*(1+$L$2) -> 5776803.9 | L10: =U10*(1+$L$2) -> 3688125 | O10: 1 | P10: 1 | R10: =SUM(N10:P10) -> 2 | T10: =5501718*O10 -> 5501718 | U10: =140500*25*P10 -> 3512500
C11: SORTIR GUDANG | F11: 1 | G11: 1 | H11: =SUM(D11:F11) -> 1 | L11: =U11*(1+$L$2) -> 2231250 | M11: =5480226*G11 -> 5480226 | P11: 1 | R11: =SUM(N11:P11) -> 1 | U11: =85000*25*P11 -> 2125000 | V11: =65000*25*Q11 -> 0 | AB11: 1 | AC11: KEUANGAN | AD11: ACC | AE11: 1 | AF11: 1 | AI11: 1 | AK11: =SUM(AH11:AJ11) -> 1
C12: PENATAAN GUDANG | F12: 2 | G12: 2 | H12: =SUM(D12:F12) -> 2 | L12: =U12*(1+$L$2) -> 4200000 | M12: =5480226*G12 -> 10960452 | P12: 2 | R12: =SUM(N12:P12) -> 2 | U12: =80000*25*P12 -> 4000000 | V12: =65000*25*Q12 -> 0 | AD12: KASIR/KEU | AE12: 2 | AF12: 1 | AI12: 2 | AK12: =SUM(AH12:AJ12) -> 2
C13: LOADING/UNLOADING | F13: 3 | G13: 3 | H13: =SUM(D13:F13) -> 3 | L13: =U13*(1+$L$2) -> 5118750 | M13: =5480226*G13 -> 16440678 | P13: 3 | R13: =SUM(N13:P13) -> 3 | U13: =65000*25*P13 -> 4875000 | V13: =65000*25*Q13 -> 0 | AD13: TRESURY/UMUM PENAGIHAN | AE13: 1 | AF13: 1 | AJ13: 1 | AK13: =SUM(AH13:AJ13) -> 1
C14: DRIVER EKSPEDISI | F14: 1 | H14: =SUM(D14:F14) -> 1 | L14: =U14*(1+$L$2) -> 3937500 | P14: 1 | R14: =SUM(N14:P14) -> 1 | U14: =150000*25*P14 -> 3750000 | AB14: 2 | AC14: PURCHASING | AE14: 2 | AF14: 1 | AH14: 1 | AJ14: 1 | AK14: =SUM(AH14:AJ14) -> 2
D15: =SUM(D6:D14) -> 0 | E15: =SUM(E6:E14) -> 1 | F15: =SUM(F6:F14) -> 13 | G15: =SUM(G6:G14) -> 6 | H15: =SUM(H6:H14) -> 14 | K15: =SUM(K6:K14) -> 5776803.9 | L15: =SUM(L6:L14) -> 37780851 | M15: =SUM(M6:M14) -> 32881356 | N15: =SUM(N6:N14) -> 0 | O15: =SUM(O6:O14) -> 1 | P15: =SUM(P6:P14) -> 13 | Q15: =SUM(Q6:Q14) -> 0 | R15: =SUM(R6:R14) -> 14 | T15: =SUM(T6:T14) -> 5501718 | U15: =SUM(U6:U14) -> 35981763 | V15: =SUM(V6:V14) -> 0 | AB15: 3 | AC15: MARKETING | AK15: =SUM(AH15:AJ15) -> 0
AB16: 4 | AC16: HC | AD16: HRD | AE16: 1 | AF16: 1 | AH16: 1 | AK16: =SUM(AH16:AJ16) -> 1
AD17: GA/UMUM | AE17: 3 | AF17: 3 | AJ17: 3 | AK17: =SUM(AH17:AJ17) -> 3 | AQ17: OFFICE, PRODUKSI, LAPANGAN
AD18: SECURITY | AE18: 4 | AF18: 2 | AJ18: 1.6 | AK18: =SUM(AH18:AJ18) -> 1.6
AB19: 5 | AC19: PPIC | AD19: PLANNING | AE19: 1 | AF19: 1 | AI19: 1 | AK19: =SUM(AH19:AJ19) -> 1
AD20: GUDANG BAHAN BAKU | AE20: 1 | AF20: 1 | AH20: 1 | AK20: =SUM(AH20:AJ20) -> 1
AD21: GUDANG BARANG JADI | AE21: 1 | AF21: 1 | AH21: 1 | AK21: =SUM(AH21:AJ21) -> 1
AD22: EKSPEDISI | AE22: 3 | AF22: 1 | AJ22: 3 | AK22: =SUM(AH22:AJ22) -> 3
AB23: 6 | AC23: QA | AD23: QC | AE23: 2 | AF23: 2 | AH23: 1 | AK23: =SUM(AH23:AJ23) -> 1 | AQ23: QC SHIFT MALAM
AB24: 7 | AC24: TEKNIK | AD24: MEKANIK | AE24: 4 | AF24: 3 | AH24: 2 | AI24: 1 | AJ24: 1 | AK24: =SUM(AH24:AJ24) -> 4
AD25: ELEKTRIK | AE25: 1 | AF25: 2 | AH25: 1 | AK25: =SUM(AH25:AJ25) -> 1
AB26: 8 | AC26: PRACETAK | AD26: KODAK 1 | AE26: 2 | AF26: 2 | AH26: 1 | AI26: 1 | AJ26: 1 | AK26: =SUM(AH26:AJ26) -> 3 | AQ26: PRACETAK, EDITOR MATERI
AD27: AVALON | AE27: 1 | AF27: 1 | AH27: 1 | AK27: =SUM(AH27:AJ27) -> 1
AB28: 9 | AC28: SHEET | AD28: MITSUBISHI | AE28: 9 | AF28: 3 | AH28: 2 | AJ28: 7 | AK28: =SUM(AH28:AJ28) -> 9
AB29: 10 | AC29: WEB | AD29: UNIVERSAL 630 | AE29: 12 | AF29: 3 | AH29: 2 | AI29: 1 | AJ29: 9 | AK29: =SUM(AH29:AJ29) -> 12
AB30: 11 | AC30: FINISHING KOMERSIAL | AD30: LIPAT STHAL | AE30: 3 | AF30: 3 | AJ30: 3 | AK30: =SUM(AH30:AJ30) -> 3
AD31: LIPAT PM | AK31: =SUM(AH31:AJ31) -> 0
AD32: LIPAT MBO | AK32: =SUM(AH32:AJ32) -> 0
AD33: TIGRA | AE33: 8 | AF33: 2 | AH33: 2 | AJ33: 6 | AK33: =SUM(AH33:AJ33) -> 8 | AQ33: PLAN MOVING KE BAWEN
AD34: STICTHING MULLER | AE34: 8 | AF34: 2 | AH34: 1 | AJ34: 7 | AK34: =SUM(AH34:AJ34) -> 8
AD35: POTONG ITOTECH | AE35: 1 | AF35: 1 | AJ35: 3 | AK35: =SUM(AH35:AJ35) -> 3
AD36: POTONG POLAR | AK36: =SUM(AH36:AJ36) -> 0
AD37: SORTIR DAN PACKING | AE37: 10 | AF37: 2 | AJ37: 10 | AK37: =SUM(AH37:AJ37) -> 10
AE39: =SUM(AE6:AE38) -> 84 | AH39: =SUM(AH6:AH38) -> 18 | AI39: =SUM(AI6:AI38) -> 9 | AJ39: =SUM(AJ6:AJ38) -> 56.6 | AK39: =SUM(AK6:AK38) -> 83.6
AJ40: =AE39-AK39 -> 0.4 | AK40: =AK39/AE39 -> 0.9952381

Sheet DPS
A1: IDEAL KEBUTUHAN SDM PERKOM 2025 | Y1: IDEAL KEBUTUHAN SDM PERKOM 2023
A2: CABANG DENPASAR | O2: PROGNOSIS | Y2: CABANG DENPASAR | AH2: PROGNOSIS
A3: NO | B3: DIVISI | C3: MESIN | D3: KEBUTUHAN | I3: SHIFT | J3: EXISTING | O3: BIAYA (RP) | R3: REALISASI | U3: OUTPUT/OMSET (RP) | V3: RASIO (%) | W3: SELISIH SDM | Y3: NO | Z3: DIVISI | AA3: MESIN | AB3: KEBUTUHAN (ORANG) | AC3: BIAYA (RP) | AD3: EXISTING | AH3: BIAYA (RP) | AK3: REALISASI | AN3: OUTPUT/OMSET (RP) | AO3: RASIO (%)
D4: TETAP | E4: KONTRAK | F4: OS FIX | G4: OS VAR | H4: TOTAL | J4: TETAP | K4: KONTRAK | L4: OS FIX | M4: OS VAR | N4: total | O4: TETAP | P4: KONTRAK | Q4: OS/HL | R4: MINGGU 1 | S4: MINGGU 2 | T4: MINGGU 3 | AD4: TETAP | AE4: KONTRAK | AF4: OS/HL | AG4: total | AH4: TETAP | AI4: KONTRAK | AJ4: OS/HL | AK4: MINGGU 1 | AL4: MINGGU 2 | AM4: MINGGU 3
A5: TOTAL SDM/BIAYA | J5: =SUM(J6:J39) -> 11 | K5: =SUM(K6:K39) -> 3 | L5: =SUM(L6:L39) -> 23 | O5: 58320345 | P5: 19687458 | Q5: =SUM(Q6:Q58) -> 51079350 | V5: =SUM(O5:Q5)/U5 -> #DIV/0! | Y5: TOTAL SDM/BIAYA | AB5: =SUM(AB6:AB39) -> 32 | AC5: =SUM(AC6:AC39) -> 0 | AD5: =SUM(AD6:AD39) -> 12 | AE5: =SUM(AE6:AE39) -> 4 | AF5: =SUM(AF6:AF39) -> 16 | AH5: 58320345 | AI5: 19687458 | AJ5: =SUM(AJ6:AJ58) -> 51079350 | AO5: =SUM(AH5:AJ5)/AN5 -> #DIV/0!
A6: 1 | B6: KEUANGAN | C6: ACC | D6: 1 | H6: =SUM(D6:G6) -> 1 | I6: 1 | J6: 1 | N6: =SUM(J6:M6) -> 1 | W6: =H6-N6 -> 0 | Y6: 1 | Z6: KEUANGAN | AA6: ACC | AB6: 1 | AE6: 1 | AG6: =SUM(AD6:AF6) -> 1
C7: KASIR/KEU | D7: 1 | H7: =SUM(D7:G7) -> 1 | I7: 1 | J7: 1 | N7: =SUM(J7:M7) -> 1 | W7: =H7-N7 -> 0 | AA7: KASIR/KEU | AB7: 1 | AD7: 1 | AG7: =SUM(AD7:AF7) -> 1
C8: TREASURY/PIUTANG | F8: 1 | H8: =SUM(D8:G8) -> 1 | I8: 1 | L8: 1 | N8: =SUM(J8:M8) -> 1 | Q8: 2629125 | W8: =H8-N8 -> 0 | AA8: TRESURY | AB8: 2 | AD8: 1 | AF8: 1 | AG8: =SUM(AD8:AF8) -> 2 | AJ8: 2629125
A9: 2 | B9: PURCHASING | H9: =SUM(D9:G9) -> 0 | N9: =SUM(J9:M9) -> 0 | W9: =H9-N9 -> 0 | Y9: 2 | Z9: PURCHASING | AG9: =SUM(AD9:AF9) -> 0
A10: 3 | B10: MARKETING | F10: 3 | H10: =SUM(D10:G10) -> 3 | I10: 1 | L10: 3 | N10: =SUM(J10:M10) -> 3 | W10: =H10-N10 -> 0 | Y10: 3 | Z10: MARKETING | AG10: =SUM(AD10:AF10) -> 0
B11: ADMIN MARKETING | F11: 1 | H11: =SUM(D11:G11) -> 1 | L11: 1 | N11: =SUM(J11:M11) -> 1
A12: 4 | B12: HC | C12: HRD | H12: =SUM(D12:G12) -> 0 | N12: =SUM(J12:M12) -> 0 | W12: =H12-N12 -> 0 | Y12: 4 | Z12: HC | AA12: HRD | AG12: =SUM(AD12:AF12) -> 0
C13: GA/UMUM : KANTOR | F13: 2 | H13: =SUM(D13:G13) -> 2 | I13: 1 | L13: 2 | N13: =SUM(J13:M13) -> 2 | Q13: 2316625 | W13: =H13-N13 -> 0 | AA13: GA/UMUM | AB13: 1 | AF13: 1 | AG13: =SUM(AD13:AF13) -> 1 | AJ13: 2316625
C14: GA/UMUM : PRODUKSI | W14: =H14-N14 -> 0
C15: GA/UMUM : AFVAL | W15: =H15-N15 -> 0
C16: SECURITY | F16: 4 | H16: =SUM(D16:G16) -> 4 | I16: 1 & 2 | L16: 4 | N16: =SUM(J16:M16) -> 4 | Q16: 19246500 | W16: =H16-N16 -> 0 | AA16: SECURITY | AB16: 4 | AF16: 4 | AG16: =SUM(AD16:AF16) -> 4 | AJ16: 19246500
A17: 5 | B17: PPIC | C17: PLANNING | D17: 1 | F17: 1 | H17: =SUM(D17:G17) -> 2 | I17: 1 | J17: 1 | L17: 1 | N17: =SUM(J17:M17) -> 2 | Q17: 2629125 | W17: =H17-N17 -> 0 | Y17: 5 | Z17: PPIC | AA17: PLANNING | AB17: 2 | AD17: 1 | AF17: 1 | AG17: =SUM(AD17:AF17) -> 2 | AJ17: 2629125
C18: GUDANG BAHAN BAKU | D18: 1 | H18: =SUM(D18:G18) -> 1 | I18: 1 | J18: 1 | N18: =SUM(J18:M18) -> 1 | W18: =H18-N18 -> 0 | AA18: GUDANG BAHAN BAKU | AB18: 1 | AD18: 1 | AG18: =SUM(AD18:AF18) -> 1
C19: GUDANG BARANG JADI | H19: =SUM(D19:G19) -> 0 | N19: =SUM(J19:M19) -> 0 | W19: =H19-N19 -> 0 | AA19: GUDANG BARANG JADI | AG19: =SUM(AD19:AF19) -> 0
C20: EKSPEDISI | F20: 1 | H20: =SUM(D20:G20) -> 1 | I20: 1 | L20: 1 | N20: =SUM(J20:M20) -> 1 | Q20: 2466625 | W20: =H20-N20 -> 0 | AA20: Ekspedisi | AB20: 1 | AF20: 1 | AG20: =SUM(AD20:AF20) -> 1 | AJ20: 2466625
A21: 6 | B21: QA | C21: QC | H21: =SUM(D21:G21) -> 0 | N21: =SUM(J21:M21) -> 0 | W21: =H21-N21 -> 0 | Y21: 6 | Z21: QA | AA21: QC | AG21: =SUM(AD21:AF21) -> 0
A22: 7 | B22: TEKNIK | C22: MEKANIK | D22: 1 | E22: 1 | F22: 1 | H22: =SUM(D22:G22) -> 3 | I22: 1 &2 | J22: 1 | K22: 1 | L22: 1 | N22: =SUM(J22:M22) -> 3 | Q22: 3365375 | W22: =H22-N22 -> 0 | Y22: 7 | Z22: TEKNIK | AA22: MEKANIK | AB22: 3 | AD22: 2 | AF22: 1 | AG22: =SUM(AD22:AF22) -> 3 | AJ22: 3365375
C23: ELEKTRIK | F23: 2 | H23: =SUM(D23:G23) -> 2 | I23: 1 & 2 | L23: 2 | N23: =SUM(J23:M23) -> 2 | W23: =H23-N23 -> 0 | AA23: ELEKTRIK | AB23: 1 | AE23: 1 | AG23: =SUM(AD23:AF23) -> 1
A24: 8 | B24: PRACETAK | C24: CTP AVALON A8T | D24: 2 | F24: 2 | H24: =SUM(D24:G24) -> 4 | I24: 1 | J24: 2 | L24: 2 | N24: =SUM(J24:M24) -> 4 | Q24: 4844500 | W24: =H24-N24 -> 0 | Y24: 8 | Z24: PRACETAK | AA24: CTP Thermal 1 | AB24: 4 | AD24: 2 | AF24: 2 | AG24: =SUM(AD24:AF24) -> 4 | AJ24: 4844500
C25: CTP AVALON 1823 | I25: 2 | W25: =H25-N25 -> 0 | AA25: CTP Thermal 2 | AG25: =SUM(AD25:AF25) -> 0
A26: 9 | B26: SHEET | C26: KOMORI | D26: 1 | F26: 2 | H26: =SUM(D26:G26) -> 3 | I26: 1 | J26: 1 | L26: 1 | N26: =SUM(J26:M26) -> 2 | Q26: 3352875 | W26: =H26-N26 -> 1 | Y26: 9 | Z26: SHEET | AA26: KOMORI | AB26: 2 | AD26: 1 | AF26: 1 | AG26: =SUM(AD26:AF26) -> 2 | AJ26: 3352875
A27: 10 | B27: WEB | C27: LINE GOSS SSC 3 TOWER | D27: 3 | F27: 4 | H27: =SUM(D27:G27) -> 7 | I27: 2 | J27: 3 | L27: 4 | N27: =SUM(J27:M27) -> 7 | Q27: 10228600 | W27: =H27-N27 -> 0 | Y27: 10 | Z27: WEB | AA27: GOSS SSC | AB27: 7 | AD27: 3 | AF27: 4 | AG27: =SUM(AD27:AF27) -> 7 | AJ27: 10228600
C28: LINE GOSS SSC 1 TOWER | N28: =SUM(J28:M28) -> 0 | W28: =H28-N28 -> 0 | AA28: SHARPLINE | AG28: =SUM(AD28:AF28) -> 0
A29: 11 | B29: FINISHING KOMERSIAL | C29: TRIMER YOSHINO | D29: 1 | E29: 1 | H29: =SUM(D29:G39) -> 8 | I29: 1 | K29: 2 | N29: =SUM(J29:M39) -> 8 | W29: =H29-N29 -> 0 | Y29: 11 | Z29: FINISHING KOMERSIAL | AA29: TRIMER YOSHINO | AB29: 2 | AE29: 2 | AG29: =SUM(AD29:AF29) -> 2
C30: STITCHING OSAKA | W30: =H30-N30 -> 0 | AA30: STITCHING | AG30: =SUM(AD30:AF30) -> 0
C31: LIPAT PURPLE MAGNA | W31: =H31-N31 -> 0 | AA31: LIPAT PURPLE MAGNA | AG31: =SUM(AD31:AF31) -> 0
C32: POTONG SHLM LONG 104 | W32: =H32-N32 -> 0 | AA32: POTONG SHLM 1 | AG32: =SUM(AD32:AF32) -> 0
C33: POTONG SHLM QZ920 B | W33: =H33-N33 -> 0 | AA33: POTONG SHLM 2 | AG33: =SUM(AD33:AF33) -> 0
C34: BINDING TIGRA | G34: 6 | M34: 6 | W34: =H34-N34 -> 0 | AA34: BENDING TIGRA | AG34: =SUM(AD34:AF34) -> 0
C35: SISIP GATEHERED 001 | W35: =H35-N35 -> 0 | AA35: SISIP GATEHERED 001 | AG35: =SUM(AD35:AF35) -> 0
C36: SHRINK | W36: =H36-N36 -> 0 | AA36: SHRINK | AG36: =SUM(AD36:AF36) -> 0
C37: CUTTING/PLONG | W37: =H37-N37 -> 0 | AA37: CUTTING | AG37: =SUM(AD37:AF37) -> 0
C38: LAMINASI (GLOSSY &DOFF) | W38: =H38-N38 -> 0
C39: UV/glossy | W39: =H39-N39 -> 0 | AA39: UV/glossy | AG39: =SUM(AD39:AF39) -> 0
D40: =SUM(D6:D39) -> 12 | E40: =SUM(E6:E39) -> 2 | F40: =SUM(F6:F39) -> 24 | G40: =SUM(G6:G39) -> 6 | H40: =SUM(H6:H39) -> 44 | J40: =SUM(J6:J39) -> 11 | K40: =SUM(K6:K39) -> 3 | L40: =SUM(L6:L39) -> 23 | M40: =SUM(M6:M39) -> 6 | N40: =SUM(N6:N39) -> 43 | O40: =SUM(O6:O29) -> 0 | R40: =SUM(R6:R29) -> 0 | S40: =SUM(S6:S29) -> 0 | T40: =SUM(T6:T29) -> 0 | W40: =SUM(W6:W37) -> 1 | AB40: =SUM(AB6:AB37) -> 32 | AD40: =SUM(AD6:AD37) -> 12 | AE40: =SUM(AE6:AE37) -> 4 | AF40: =SUM(AF6:AF37) -> 16 | AG40: =SUM(AG6:AG37) -> 32 | AH40: =SUM(AH6:AH29) -> 0 | AK40: =SUM(AK6:AK29) -> 0 | AL40: =SUM(AL6:AL29) -> 0 | AM40: =SUM(AM6:AM29) -> 0
...

Sheet BWN
A1: IDEAL KEBUTUHAN SDM PERKOM 2025
A2: CABANG BAWEN SOLO
A3: NO | B3: DIVISI | C3: MESIN | D3: KEBUTUHAN | J3: EXISTING | Q3: BIAYA | T3: OUTPUT/OMSET (RP) | U3: RASIO (%)
D4: SHIFT | E4: TETAP | F4: KONTRAK | G4: OS FIX | H4: OS VAR | I4: TOTAL | J4: SHIFT | K4: TETAP | L4: KONTRAK | M4: OS FIX | N4: OS VAR | O4: OS BOR | P4: TOTAL | Q4: TETAP | R4: KONTRAK | S4: OS/HL | V4: KURANG | W4: NOTE
A5: TOTAL SDM/BIAYA | E5: =SUM(E6:E76) -> 37 | F5: =SUM(F6:F76) -> 14 | G5: =SUM(G6:G76) -> 91 | H5: =SUM(H6:H76) -> 183 | I5: =SUM(I6:I76) -> 325 | K5: =SUM(K6:K76) -> 36 | L5: =SUM(L6:L76) -> 9 | M5: =SUM(M6:M76) -> 71 | N5: =SUM(N6:N76) -> 97 | O5: =SUM(O6:O76) -> 33 | P5: =SUM(P6:P76) -> 246
A6: 1 | B6: GM | D6: 1 | E6: 1 | I6: =SUM(E6:H6) -> 1 | J6: 1 | L6: 1 | P6: =SUM(K6:O6) -> 1 | V6: =#REF!-P6 -> #REF! | Y6: =P6-I6 -> 0 | Z6: =SUM(K6:L6)-SUM(E6:F6) -> 0
A7: 2 | B7: ASMEN | D7: 1 | E7: 1 | F7: 1 | I7: =SUM(E7:H7) -> 2 | J7: 1 | L7: 2 | P7: =SUM(K7:O7) -> 2 | V7: =#REF!-P7 -> #REF! | Y7: =P7-I7 -> 0 | Z7: =SUM(K7:L7)-SUM(E7:F7) -> 0
A8: 3 | B8: KEUANGAN | C8: ACC | D8: 1 | E8: 1 | I8: =SUM(E8:H8) -> 1 | J8: 1 | K8: 1 | P8: =SUM(K8:O8) -> 1 | V8: =#REF!-P8 -> #REF! | Y8: =P8-I8 -> 0 | Z8: =SUM(K8:L8)-SUM(E8:F8) -> 0
C9: KASIR/KEU | D9: 1 | G9: 1 | I9: =SUM(E9:H9) -> 1 | J9: 1 | M9: 1 | P9: =SUM(K9:O9) -> 1 | V9: =#REF!-P9 -> #REF! | Y9: =P9-I9 -> 0 | Z9: =SUM(K9:L9)-SUM(E9:F9) -> 0
C10: INVOICING | D10: 1 | G10: 1 | I10: =SUM(E10:H10) -> 1 | J10: 1 | M10: 1 | P10: =SUM(K10:O10) -> 1 | V10: =#REF!-P10 -> #REF! | W10: DIBANTU PSG | Y10: =P10-I10 -> 0 | Z10: =SUM(K10:L10)-SUM(E10:F10) -> 0
C11: TRESURY | D11: 1 | E11: 1 | I11: =SUM(E11:H11) -> 1 | J11: 1 | K11: 1 | P11: =SUM(K11:O11) -> 1 | V11: =#REF!-P11 -> #REF! | Y11: =P11-I11 -> 0 | Z11: =SUM(K11:L11)-SUM(E11:F11) -> 0
A12: 2 | B12: PURCHASING | C12: PURCHASING | D12: 1 | F12: 1 | I12: =SUM(E12:H12) -> 1 | J12: 1 | L12: 1 | P12: =SUM(K12:O12) -> 1 | V12: =#REF!-P12 -> #REF! | Y12: =P12-I12 -> 0 | Z12: =SUM(K12:L12)-SUM(E12:F12) -> 0
A13: 3 | B13: MARKETING | C13: MD | D13: 1 | G13: 1 | I13: =SUM(E13:H13) -> 1 | P13: =SUM(K13:O13) -> 0 | V13: =#REF!-P13 -> #REF! | Y13: =P13-I13 -> -1 | Z13: =SUM(K13:L13)-SUM(E13:F13) -> 0
C14: ADM MARKETING | D14: 1 | G14: 1 | I14: =SUM(E14:H14) -> 1 | J14: 1 | M14: 1 | P14: =SUM(K14:O14) -> 1 | V14: =#REF!-P14 -> #REF! | Y14: =P14-I14 -> 0 | Z14: =SUM(K14:L14)-SUM(E14:F14) -> 0
C15: MARKETING PROYEK | D15: 1 | I15: =SUM(E15:H15) -> 0 | P15: =SUM(K15:O15) -> 0 | V15: =#REF!-P15 -> #REF! | Y15: =P15-I15 -> 0 | Z15: =SUM(K15:L15)-SUM(E15:F15) -> 0
C16: MARKETING | D16: 1 | E16: 4 | F16: 1 | I16: =SUM(E16:H16) -> 5 | J16: 1 | K16: 4 | L16: 1 | P16: =SUM(K16:O16) -> 5 | V16: =#REF!-P16 -> #REF! | Y16: =P16-I16 -> 0 | Z16: =SUM(K16:L16)-SUM(E16:F16) -> 0
A17: 4 | B17: HC | C17: HRD | D17: 1 | E17: 1 | I17: =SUM(E17:H17) -> 1 | J17: 1 | K17: 1 | P17: =SUM(K17:O17) -> 1 | V17: =#REF!-P17 -> #REF! | Y17: =P17-I17 -> 0 | Z17: =SUM(K17:L17)-SUM(E17:F17) -> 0
C18: GA | D18: 1 | E18: 1 | I18: =SUM(E18:H18) -> 1 | J18: 1 | K18: 1 | P18: =SUM(K18:O18) -> 1 | V18: =#REF!-P18 -> #REF! | Y18: =P18-I18 -> 0 | Z18: =SUM(K18:L18)-SUM(E18:F18) -> 0
C19: GA/UMUM : KANTOR | D19: 1 | G19: 1 | I19: =SUM(E19:H19) -> 1 | J19: 1 | M19: 1 | P19: =SUM(K19:O19) -> 1 | V19: =#REF!-P19 -> #REF! | Y19: =P19-I19 -> 0 | Z19: =SUM(K19:L19)-SUM(E19:F19) -> 0
C20: GA/UMUM : SAPU PEL PRODUKSI | D20: 2 | G20: 1 | H20: 1 | I20: =SUM(E20:H20) -> 2 | J20: 1 | M20: 1 | P20: =SUM(K20:O20) -> 1 | Y20: =P20-I20 -> -1 | Z20: =SUM(K20:L20)-SUM(E20:F20) -> 0
C21: GA/UMUM : AVAL | D21: 3 | G21: 6 | H21: 2 | I21: =SUM(E21:H21) -> 8 | J21: 2 | M21: 5 | P21: =SUM(K21:O21) -> 5 | Y21: =P21-I21 -> -3 | Z21: =SUM(K21:L21)-SUM(E21:F21) -> 0
C22: SECURITY | D22: 3 | G22: =8+3 -> 11 | I22: =SUM(E22:H22) -> 11 | J22: 3 | M22: =7+3 -> 10 | P22: =SUM(K22:O22) -> 10 | V22: =#REF!-P22 -> #REF! | Y22: =P22-I22 -> -1 | Z22: =SUM(K22:L22)-SUM(E22:F22) -> 0
A23: 5 | B23: PPIC | C23: PLANNING | D23: 2 | E23: 1 | F23: 1 | G23: 1 | I23: =SUM(E23:H23) -> 3 | J23: 1 | K23: 1 | M23: 2 | P23: =SUM(K23:O23) -> 3 | V23: =#REF!-P23 -> #REF! | Y23: =P23-I23 -> 0 | Z23: =SUM(K23:L23)-SUM(E23:F23) -> -1
C24: INVENTORY CONTROL, MANUFACTURE | D24: 1 | E24: 1 | G24: 1 | I24: =SUM(E24:H24) -> 2 | J24: 1 | K24: 1 | M24: 1 | P24: =SUM(K24:O24) -> 2 | Y24: =P24-I24 -> 0 | Z24: =SUM(K24:L24)-SUM(E24:F24) -> 0
C25: GUDANG BAHAN BAKU + SPAREPART | D25: 2 | E25: 3 | G25: 1 | I25: =SUM(E25:H25) -> 4 | J25: 2 | K25: 3 | M25: 1 | P25: =SUM(K25:O25) -> 4 | V25: =#REF!-P25 -> #REF! | Y25: =P25-I25 -> 0 | Z25: =SUM(K25:L25)-SUM(E25:F25) -> 0
C26: GUDANG BARANG JADI | D26: 2 | E26: 1 | G26: 1 | I26: =SUM(E26:H26) -> 2 | J26: 1 | K26: 1 | P26: =SUM(K26:O26) -> 1 | V26: =#REF!-P26 -> #REF! | Y26: =P26-I26 -> -1 | Z26: =SUM(K26:L26)-SUM(E26:F26) -> 0
C27: EKSPEDISI - DRIVER | D27: 1 | H27: 1 | I27: =SUM(E27:H27) -> 1 | J27: 1 | N27: 1 | P27: =SUM(K27:O27) -> 1 | V27: =#REF!-P27 -> #REF! | Y27: =P27-I27 -> 0 | Z27: =SUM(K27:L27)-SUM(E27:F27) -> 0
C28: GUDANG SENTRAL BAWEN | D28: 2 | G28: 6 | I28: =SUM(E28:H28) -> 6 | J28: 1 | M28: 6 | P28: =SUM(K28:O28) -> 6 | Y28: =P28-I28 -> 0 | Z28: =SUM(K28:L28)-SUM(E28:F28) -> 0
A29: 6 | B29: IT | C29: IT | D29: 1 | F29: 1 | I29: =SUM(E29:H29) -> 1 | P29: =SUM(K29:O29) -> 0 | Y29: =P29-I29 -> -1 | Z29: =SUM(K29:L29)-SUM(E29:F29) -> -1
A30: 7 | B30: QA | C30: QC | D30: 3 | F30: 1 | G30: 2 | I30: =SUM(E30:H30) -> 3 | J30: 2 | M30: 1 | P30: =SUM(K30:O30) -> 1 | V30: =#REF!-P30 -> #REF! | W30: PROSES REKRUT | Y30: =P30-I30 -> -2 | Z30: =SUM(K30:L30)-SUM(E30:F30) -> -1
A31: 8 | B31: TEKNIK | C31: WAKADIV | D31: 1 | E31: 1 | I31: =SUM(E31:H31) -> 1 | J31: 1 | K31: 1 | P31: =SUM(K31:O31) -> 1 | V31: =#REF!-P31 -> #REF! | Y31: =P31-I31 -> 0 | Z31: =SUM(K31:L31)-SUM(E31:F31) -> 0
C32: MEKANIK | D32: 3 | E32: 5 | F32: 1 | G32: 2 | I32: =SUM(E32:H32) -> 8 | J32: 3 | K32: 5 | M32: 3 | P32: =SUM(K32:O32) -> 8 | Y32: =P32-I32 -> 0 | Z32: =SUM(K32:L32)-SUM(E32:F32) -> -1
C33: ELEKTRIK | D33: 3 | E33: 1 | G33: 3 | I33: =SUM(E33:H33) -> 4 | J33: 3 | K33: 1 | M33: 3 | P33: =SUM(K33:O33) -> 4 | V33: =#REF!-P33 -> #REF! | Y33: =P33-I33 -> 0 | Z33: =SUM(K33:L33)-SUM(E33:F33) -> 0
A34: 9 | B34: PRACETAK | C34: DESAIN GRAFIS | D34: 2 | E34: 1 | G34: 1 | I34: =SUM(E34:H34) -> 2 | J34: 2 | K34: 1 | M34: 1 | P34: =SUM(K34:O34) -> 2 | V34: =#REF!-P34 -> #REF! | Y34: =P34-I34 -> 0 | Z34: =SUM(K34:L34)-SUM(E34:F34) -> 0
C35: CTP THERMAL AGFA 1 | D35: 3 | E35: 1 | G35: 2 | I35: =SUM(E35:H35) -> 3 | J35: 3 | K35: 1 | M35: 1 | N35: 1 | P35: =SUM(K35:O35) -> 3 | Y35: =P35-I35 -> 0 | Z35: =SUM(K35:L35)-SUM(E35:F35) -> 0
C36: CTP THERMAL AGFA 2 | D36: 3 | G36: 2 | I36: =SUM(E36:H36) -> 2 | J36: 3 | M36: 2 | P36: =SUM(K36:O36) -> 2 | V36: =#REF!-P36 -> #REF! | Y36: =P36-I36 -> 0 | Z36: =SUM(K36:L36)-SUM(E36:F36) -> 0
C37: CTCP CRON 2 | I37: =SUM(E37:H37) -> 0 | P37: =SUM(K37:O37) -> 0 | V37: =#REF!-P37 -> #REF! | Y37: =P37-I37 -> 0 | Z37: =SUM(K37:L37)-SUM(E37:F37) -> 0
A38: 10 | B38: SHEET | C38: KOORDINATOR | D38: 1 | E38: 1 | I38: =SUM(E38:H38) -> 1 | J38: 1 | K38: 1 | P38: =SUM(K38:O38) -> 1 | V38: =#REF!-P38 -> #REF! | Y38: =P38-I38 -> 0 | Z38: =SUM(K38:L38)-SUM(E38:F38) -> 0
C39: KOMORI 1 | D39: 3 | E39: 1 | F39: 1 | G39: 2 | H39: 5 | I39: =SUM(E39:H39) -> 9 | J39: 3 | K39: 1 | L39: 1 | M39: 2 | N39: 5 | P39: =SUM(K39:O39) -> 9 | Y39: =P39-I39 -> 0 | Z39: =SUM(K39:L39)-SUM(E39:F39) -> 0
C40: KOMORI 2 | D40: 3 | E40: 1 | G40: 2 | H40: 6 | I40: =SUM(E40:H40) -> 9 | J40: 3 | K40: 1 | M40: 2 | N40: 6 | P40: =SUM(K40:O40) -> 9 | V40: =#REF!-P40 -> #REF! | Y40: =P40-I40 -> 0 | Z40: =SUM(K40:L40)-SUM(E40:F40) -> 0
...

Sheet NGK
A1: IDEAL KEBUTUHAN SDM PERKOM 2025
A2: CABANG NGANJUK
A3: NO | B3: DIVISI | C3: MESIN | D3: KEBUTUHAN | J3: BIAYA (RP) | K3: EXISTING | Q3: BIAYA (RP) | T3: OUTPUT/OMSET (RP) | U3: RASIO (%)
D4: SHIFT | E4: TETAP | F4: KONTRAK | G4: OS FIX | H4: OS VAR (HL & BOR) | I4: TOTAL | K4: SHIFT | L4: TETAP | M4: KONTRAK | N4: OS FIX | O4: OS VAR (HL & BOR) | P4: TOTAL | Q4: TETAP | R4: KONTRAK | S4: OS/HL | V4: SELISIH SDM
A5: TOTAL SDM/BIAYA | E5: =SUM(E6:E51) -> 14 | F5: =SUM(F6:F51) -> 1 | G5: =SUM(G6:G51) -> 30 | H5: =SUM(H6:H51) -> 74 | I5: =SUM(I6:I51) -> 118 | L5: =SUM(L6:L51) -> 13 | M5: =SUM(M6:M51) -> 1 | N5: =SUM(N6:N51) -> 19 | O5: =SUM(O6:O51) -> 65 | P5: =SUM(P6:P51) -> 97 | Q5: 95082611 | R5: 41612458 | S5: =SUM(S6:S51) -> 0
A6: 1 | B6: GM | D6: 1 | E6: 1 | I6: =SUM(E6:H6) -> 1 | K6: 1 | M6: 1 | P6: =SUM(L6:O6) -> 1 | V6: =P6-I6 -> 0 | Z6: =SUM(L6:M6)-SUM(E6:F6) -> 0
A7: 2 | B7: KEUANGAN | C7: ACC | D7: 1 | I7: =SUM(E7:H7) -> 0 | K7: 1 | P7: =SUM(L7:O7) -> 0 | V7: =P7-I7 -> 0 | Z7: =SUM(L7:M7)-SUM(E7:F7) -> 0
C8: KASIR/KEU | D8: 1 | E8: 1 | I8: =SUM(E8:H8) -> 1 | K8: 1 | L8: 1 | P8: =SUM(L8:O8) -> 1 | V8: =P8-I8 -> 0 | Z8: =SUM(L8:M8)-SUM(E8:F8) -> 0
C9: TRESURY | D9: 1 | E9: 1 | I9: =SUM(E9:H9) -> 1 | K9: 1 | L9: 1 | P9: =SUM(L9:O9) -> 1 | V9: =P9-I9 -> 0 | Z9: =SUM(L9:M9)-SUM(E9:F9) -> 0
A10: 3 | B10: PURCHASING | D10: 1 | E10: 1 | I10: =SUM(E10:H10) -> 1 | K10: 1 | L10: 1 | P10: =SUM(L10:O10) -> 1 | V10: =P10-I10 -> 0 | Z10: =SUM(L10:M10)-SUM(E10:F10) -> 0
A11: 4 | B11: MARKETING | I11: =SUM(E11:H11) -> 0 | K11: 1 | P11: =SUM(L11:O11) -> 0 | V11: =P11-I11 -> 0 | Z11: =SUM(L11:M11)-SUM(E11:F11) -> 0
A12: 5 | B12: HC | C12: HRD | D12: 1 | I12: =SUM(E12:H12) -> 0 | P12: =SUM(L12:O12) -> 0 | V12: =P12-I12 -> 0 | Z12: =SUM(L12:M12)-SUM(E12:F12) -> 0
C13: GA/UMUM - KANTOR | D13: 1 | G13: 1 | I13: =SUM(E13:H13) -> 1 | K13: 1 | N13: 1 | P13: =SUM(L13:O13) -> 1 | V13: =P13-I13 -> 0 | Z13: =SUM(L13:M13)-SUM(E13:F13) -> 0
C14: GA/UMUM - PRODUKSI | D14: 3 | E14: 1 | G14: 5 | I14: =SUM(E14:H14) -> 6 | K14: 2 | L14: 1 | N14: 2 | P14: =SUM(L14:O14) -> 3 | V14: =P14-I14 -> -3 | Z14: =SUM(L14:M14)-SUM(E14:F14) -> 0
C15: SECURITY | D15: 3 | G15: 4 | I15: =SUM(E15:H15) -> 4 | K15: 3 | N15: 4 | P15: =SUM(L15:O15) -> 4 | V15: =P15-I15 -> 0 | Z15: =SUM(L15:M15)-SUM(E15:F15) -> 0
A16: 6 | B16: PPIC | C16: PLANNING, MANUFACTURE | D16: 1 | G16: 1 | I16: =SUM(E16:H16) -> 1 | K16: 1 | N16: 1 | P16: =SUM(L16:O16) -> 1 | V16: =P16-I16 -> 0 | Z16: =SUM(L16:M16)-SUM(E16:F16) -> 0
C17: INVENTORY CONTROL | D17: 1 | E17: 1 | G17: 1 | I17: =SUM(E17:H17) -> 2 | L17: 1 | N17: 1 | P17: =SUM(L17:O17) -> 2 | V17: =P17-I17 -> 0 | Z17: =SUM(L17:M17)-SUM(E17:F17) -> 0
C18: GUDANG BAHAN BAKU | D18: 2 | G18: 2 | I18: =SUM(E18:H18) -> 2 | K18: 1 | N18: 1 | P18: =SUM(L18:O18) -> 1 | V18: =P18-I18 -> -1 | Z18: =SUM(L18:M18)-SUM(E18:F18) -> 0
C19: GUDANG SPAREPART | D19: 1 | G19: 1 | I19: =SUM(E19:H19) -> 1 | K19: 1 | P19: =SUM(L19:O19) -> 0 | V19: =P19-I19 -> -1 | Z19: =SUM(L19:M19)-SUM(E19:F19) -> 0
C20: GUDANG BARANG JADI | D20: 1 | H20: 1 | I20: =SUM(E20:H20) -> 1 | K20: 1 | N20: 1 | P20: =SUM(L20:O20) -> 1 | V20: =P20-I20 -> 0 | Z20: =SUM(L20:M20)-SUM(E20:F20) -> 0
B21: EKSPEDISI | C21: DRIVER | I21: =SUM(E21:H21) -> 0 | K21: 1 | P21: =SUM(L21:O21) -> 0 | V21: =P21-I21 -> 0 | Z21: =SUM(L21:M21)-SUM(E21:F21) -> 0
A22: 7 | B22: IT | D22: 1 | G22: 1 | K22: 1 | N22: 1 | Z22: =SUM(L22:M22)-SUM(E22:F22) -> 0
A23: 8 | B23: QA | C23: QC | D23: 2 | F23: 1 | G23: 2 | I23: =SUM(E23:H23) -> 3 | K23: 1 | P23: =SUM(L23:O23) -> 0 | V23: =P23-I23 -> -3 | Z23: =SUM(L23:M23)-SUM(E23:F23) -> -1
A24: 9 | B24: TEKNIK | C24: MEKANIK | D24: 3 | E24: 2 | G24: 2 | I24: =SUM(E24:H24) -> 4 | K24: 2 | L24: 2 | N24: 1 | P24: =SUM(L24:O24) -> 3 | V24: =P24-I24 -> -1 | Z24: =SUM(L24:M24)-SUM(E24:F24) -> 0
C25: ELEKTRIK | D25: 3 | E25: 1 | G25: 2 | I25: =SUM(E25:H25) -> 3 | K25: 2 | L25: 1 | N25: 1 | P25: =SUM(L25:O25) -> 2 | V25: =P25-I25 -> -1 | Z25: =SUM(L25:M25)-SUM(E25:F25) -> 0
A26: 10 | B26: PRACETAK/MD | C26: SCREEN 1 | D26: 3 | G26: 1 | I26: =SUM(E26:H26) -> 1 | K26: 3 | N26: 1 | P26: =SUM(L26:O26) -> 1 | V26: =P26-I26 -> 0 | Z26: =SUM(L26:M26)-SUM(E26:F26) -> 0
C27: AVALON | D27: 3 | G27: 1 | I27: =SUM(E27:H27) -> 1 | K27: 3 | P27: =SUM(L27:O27) -> 0 | V27: =P27-I27 -> -1 | Z27: =SUM(L27:M27)-SUM(E27:F27) -> 0
A28: 11 | B28: SHEET | C28: KOMORI 1 | D28: 3 | E28: 1 | G28: 2 | H28: 3 | I28: =SUM(E28:H28) -> 6 | K28: 3 | L28: 1 | N28: 1 | O28: 1 | P28: =SUM(L28:O28) -> 3 | V28: =P28-I28 -> -3 | Z28: =SUM(L28:M28)-SUM(E28:F28) -> 0
