Workbook

Sheet 10.24 MAPPING KARAH
C3: DATA TAHUN 2025 | E3: PACK KARAH
C4: DEPARTEMEN | D4: POSISI | E4: KEBUTUHAN | K4: EXISTING
E5: Tetap Fix | F5: Kontrak Fix | G5: OS Fix | H5: OS Variabel | I5: TOTAL KEBUTUHAN (Jumlah) | J5: TOTAL KEBUTUHAN (Nominal) | K5: Tetap Fix | L5: Kontrak Fix | M5: OS Fix | N5: OS Variabel | O5: TOTAL EXISTING (Jumlah) | P5: TOTAL EXISTING (Nominal)
C8: GM | D8: GM | F8: 1 | I8: =SUM(E8:H8) -> 1 | L8: 1 | O8: =SUM(K8:N8) -> 1
C9: Manager/BM/OM | D9: OM | E9: 1 | I9: =SUM(E9:H9) -> 1 | K9: 1 | O9: =SUM(K9:N9) -> 1
D10: STAFF HRD | F10: 1 | I10: =SUM(E10:H10) -> 1 | L10: 1 | O10: =SUM(K10:N10) -> 1
D11: GA/UMUM : AREA PRODUKSI | G11: 2 | I11: =SUM(E11:H11) -> 2 | M11: 1 | O11: =SUM(K11:N11) -> 1
D12: SECURITY | G12: 2 | I12: =SUM(E12:H12) -> 2 | M12: 2 | O12: =SUM(K12:N12) -> 2
C13: PEMASARAN | D13: KADIV MARKETING | E13: 1 | I13: =SUM(E13:H13) -> 1 | K13: 1 | O13: =SUM(K13:N13) -> 1
D14: MARKETING | E14: 2 | F14: 1 | I14: =SUM(E14:H14) -> 3 | K14: 2 | L14: 1 | O14: =SUM(K14:N14) -> 3
D15: ADMIN MKT | G15: 1 | I15: =SUM(E15:H15) -> 1 | M15: 1 | O15: =SUM(K15:N15) -> 1
D16: MARKETING SUPPORT | I16: =SUM(E16:H16) -> 0 | O16: =SUM(K16:N16) -> 0
C17: PPIC | D17: KADIV PPIC | E17: 1 | I17: =SUM(E17:H17) -> 1 | K17: 1 | O17: =SUM(K17:N17) -> 1
D18: STAFF PPIC | I18: =SUM(E18:H18) -> 0 | O18: =SUM(K18:N18) -> 0
D19: ADM PPIC | G19: 2 | I19: =SUM(E19:H19) -> 2 | M19: 2 | O19: =SUM(K19:N19) -> 2
D20: STAFF GBB | F20: 1 | G20: 2 | I20: =SUM(E20:H20) -> 3 | L20: 1 | M20: 2 | O20: =SUM(K20:N20) -> 3
D21: STAFF GBJ | E21: 2 | I21: =SUM(E21:H21) -> 2 | K21: 2 | O21: =SUM(K21:N21) -> 2
D22: EKSPEDISI - ADMIN EKSPEDISI | G22: 4 | I22: =SUM(E22:H22) -> 4 | M22: 4 | O22: =SUM(K22:N22) -> 4
D23: MATERIAL HANDLING | G23: 1 | I23: =SUM(E23:H23) -> 1 | M23: 1 | O23: =SUM(K23:N23) -> 1
C24: ACC & FINANCE | D24: KADIV ACCOUNTING | E24: 1 | I24: =SUM(E24:H24) -> 1 | K24: 1 | O24: =SUM(K24:N24) -> 1
D25: KEUANGAN KASIR | G25: 1 | I25: =SUM(E25:H25) -> 1 | M25: 1 | O25: =SUM(K25:N25) -> 1
C26: PEMBELIAN | D26: PEMBELIAN | F26: 1 | I26: =SUM(E26:H26) -> 1 | L26: 1 | O26: =SUM(K26:N26) -> 1
C27: QC | D27: KADIV QC | F27: 1 | I27: =SUM(E27:H27) -> 1 | L27: 1 | O27: =SUM(K27:N27) -> 1
D28: QC | E28: 1 | F28: 2 | G28: 4 | I28: =SUM(E28:H28) -> 7 | L28: 2 | M28: 1 | O28: =SUM(K28:N28) -> 3
C29: D&D | D29: KADIV D&D | E29: 1 | I29: =SUM(E29:H29) -> 1 | K29: 1 | O29: =SUM(K29:N29) -> 1
D30: STAFF D&D | E30: 2 | F30: 1 | I30: =SUM(E30:H30) -> 3 | K30: 2 | L30: 1 | O30: =SUM(K30:N30) -> 3
C31: PRODUKSI | D31: KADIV/ WAKADIV PRODUKSI | F31: 1 | I31: =SUM(E31:H31) -> 1 | L31: 1 | O31: =SUM(K31:N31) -> 1
D32: KARU/WAKARU PRODUKSI | E32: 2 | F32: 1 | I32: =SUM(E32:H32) -> 3 | K32: 2 | L32: 1 | O32: =SUM(K32:N32) -> 3
D33: ADM PRODUKSI | G33: 1 | I33: =SUM(E33:H33) -> 1 | M33: 1 | O33: =SUM(K33:N33) -> 1
D34: PRE PRESS (PROCESSOR GRAFMAC) | E34: 1 | F34: 3 | I34: =SUM(E34:H34) -> 4 | K34: 1 | L34: 3 | O34: =SUM(K34:N34) -> 4
D35: PRE PRESS (PLATMAKER CTP AGFA) | I35: =SUM(E35:H35) -> 0 | O35: =SUM(K35:N35) -> 0
D36: PRE PRESS (DIGITAL PROOFING DF4408) | I36: =SUM(E36:H36) -> 0 | O36: =SUM(K36:N36) -> 0
D37: PRE PRESS (PLOTTER SUPERSONIC) | I37: =SUM(E37:H37) -> 0 | O37: =SUM(K37:N37) -> 0
D38: MESIN POTONG (POLAR 137EMC-MON) | G38: 6 | I38: =SUM(E38:H38) -> 6 | M38: 6 | O38: =SUM(K38:N38) -> 6
D39: CETAK SHEET (HEIDELBERGH) | E39: 1 | F39: 1 | G39: 5 | I39: =SUM(E39:H39) -> 7 | K39: 1 | L39: 1 | M39: 4 | O39: =SUM(K39:N39) -> 6
D40: CETAK SHEET (KOENIG & BAUER) | F40: 3 | G40: 14 | I40: =SUM(E40:H40) -> 17 | L40: 2 | M40: 9 | O40: =SUM(K40:N40) -> 11
D41: DIECUT/PUNCH MACHINE (ETERNA) | F41: 1 | G41: 5 | I41: =SUM(E41:H41) -> 6 | L41: 1 | M41: 3 | O41: =SUM(K41:N41) -> 4
D42: DIECUT/PUNCH MACHINE (BRAUSSE) | F42: 1 | G42: 4 | I42: =SUM(E42:H42) -> 5 | L42: 1 | M42: 4 | O42: =SUM(K42:N42) -> 5
D43: VARNISH MACHINE (UV HOCK 1060) | E43: 1 | G43: 3 | I43: =SUM(E43:H43) -> 4 | K43: 1 | M43: 3 | O43: =SUM(K43:N43) -> 4
D44: KOPEK (WASTE STRIPPER MACHINE) | H44: 6 | I44: =SUM(E44:H44) -> 6 | N44: 6 | O44: =SUM(K44:N44) -> 6
...

Sheet 10.24 MAPPING TWL
C3: DATA TAHUN 2025 | E3: TEMA WADAH LESTARI
C4: DEPARTEMEN | D4: POSISI | E4: KEBUTUHAN | K4: EXISTING
E5: Tetap Fix | F5: Kontrak Fix | G5: OS Fix | H5: OS Variabel | I5: TOTAL KEBUTUHAN (Jumlah) | J5: TOTAL KEBUTUHAN (Nominal) | K5: Tetap Fix | L5: Kontrak Fix | M5: OS Fix | N5: OS Variabel | O5: TOTAL EXISTING (Jumlah) | P5: TOTAL EXISTING (Nominal)
C8: Manager/BM/OM | D8: OM | E8: 1 | I8: =SUM(E8:H8) -> 1 | K8: 1 | O8: =SUM(K8:N8) -> 1
C9: HRD UMUM | D9: KARU HRD | E9: 1 | I9: =SUM(E9:H9) -> 1 | K9: 1 | O9: =SUM(K9:N9) -> 1
D10: KARU GA | E10: 1 | I10: =SUM(E10:H10) -> 1 | K10: 1 | O10: =SUM(K10:N10) -> 1
D11: GA/UMUM : AREA KANTOR | G11: 1 | I11: =SUM(E11:H11) -> 1 | M11: 1 | O11: =SUM(K11:N11) -> 1
D12: GA/UMUM : AREA PRODUKSI | G12: 2 | I12: =SUM(E12:H12) -> 2 | M12: 2 | O12: =SUM(K12:N12) -> 2
D13: GA/UMUM : AFVAL | G13: 1 | I13: =SUM(E13:H13) -> 1 | M13: 1 | O13: =SUM(K13:N13) -> 1
D14: SECURITY | G14: 7 | I14: =SUM(E14:H14) -> 7 | M14: 7 | O14: =SUM(K14:N14) -> 7
C15: PEMASARAN | D15: KADIV MARKETING | E15: 1 | I15: =SUM(E15:H15) -> 1 | K15: 1 | O15: =SUM(K15:N15) -> 1
D16: MARKETING | E16: 4 | I16: =SUM(E16:H16) -> 4 | K16: 4 | O16: =SUM(K16:N16) -> 4
D17: ADMIN MKT | G17: 1 | I17: =SUM(E17:H17) -> 1 | M17: 1 | O17: =SUM(K17:N17) -> 1
D18: MARKETING SUPPORT | G18: 1 | I18: =SUM(E18:H18) -> 1 | M18: 1 | O18: =SUM(K18:N18) -> 1
C19: IT | D19: STAFF IT | E19: 1 | I19: =SUM(E19:H19) -> 1 | L19: 1 | O19: =SUM(K19:N19) -> 1
C20: PPIC | D20: KARU PPIC | E20: 1 | I20: =SUM(E20:H20) -> 1 | K20: 1 | O20: =SUM(K20:N20) -> 1
D21: KARU GUDANG | E21: 1 | I21: =SUM(E21:H21) -> 1 | K21: 1 | O21: =SUM(K21:N21) -> 1
D22: STAFF GBB | E22: 1 | I22: =SUM(E22:H22) -> 1 | K22: 1 | O22: =SUM(K22:N22) -> 1
D23: STAFF GBJ | G23: 1 | I23: =SUM(E23:H23) -> 1 | M23: 1 | O23: =SUM(K23:N23) -> 1
D24: EKSPEDISI - ADMIN EKSPEDISI | E24: 1 | I24: =SUM(E24:H24) -> 1 | K24: 1 | O24: =SUM(K24:N24) -> 1
D25: EKSPEDISI - SOPIR/DRIVER | G25: 3 | I25: =SUM(E25:H25) -> 3 | M25: 3 | O25: =SUM(K25:N25) -> 3
D26: EKSPEDISI - HELPER/LOADING | H26: 8 | I26: =SUM(E26:H26) -> 8 | N26: 8 | O26: =SUM(K26:N26) -> 8
C27: ACC & FINANCE | D27: KADIV ACCOUNTING | E27: 1 | I27: =SUM(E27:H27) -> 1 | K27: 1 | O27: =SUM(K27:N27) -> 1
D28: KEUANGAN KASIR | E28: 1 | I28: =SUM(E28:H28) -> 1 | K28: 1 | O28: =SUM(K28:N28) -> 1
D29: KARU PIUTANG | E29: 1 | I29: =SUM(E29:H29) -> 1 | K29: 1 | O29: =SUM(K29:N29) -> 1
D30: PENAGIHAN | E30: 0 | I30: =SUM(E30:H30) -> 0 | K30: 0 | O30: =SUM(K30:N30) -> 0 | Q30: MUTASI KE MARKETING
C31: PEMBELIAN | D31: PEMBELIAN | E31: 0 | I31: =SUM(E31:H31) -> 0 | K31: 0 | O31: =SUM(K31:N31) -> 0 | Q31: DOUBLE JOB DGN ADM. EKSPEDISI
C32: QC | D32: QC | E32: 1 | G32: 1 | I32: =SUM(E32:H32) -> 2 | K32: 1 | M32: 1 | O32: =SUM(K32:N32) -> 2
C33: PRODUKSI | D33: KADIV/ WAKADIV PRODUKSI | E33: 1 | I33: =SUM(E33:H33) -> 1 | L33: 1 | O33: =SUM(K33:N33) -> 1
D34: KARU/WAKARU PRODUKSI | E34: 3 | I34: =SUM(E34:H34) -> 3 | K34: 3 | O34: =SUM(K34:N34) -> 3
D35: ADMIN PRODUKSI | G35: 1 | I35: =SUM(E35:H35) -> 1 | M35: 1 | O35: =SUM(K35:N35) -> 1
D36: MESIN POTONG 1 | G36: 3 | I36: =SUM(E36:H36) -> 3 | M36: 3 | O36: =SUM(K36:N36) -> 3 | Q36: Shift 1,2,3
D37: MESIN POTONG 2 | G37: 3 | I37: =SUM(E37:H37) -> 3 | M37: 3 | O37: =SUM(K37:N37) -> 3 | Q37: Shift 1,2,3
D38: MESIN POTONG 3 | G38: 3 | I38: =SUM(E38:H38) -> 3 | M38: 3 | O38: =SUM(K38:N38) -> 3 | Q38: Shift 1,2,3
D39: DIECUT 1 (JEIL) | G39: 6 | I39: =SUM(E39:H39) -> 6 | M39: 6 | O39: =SUM(K39:N39) -> 6 | Q39: Shift 1,2,3
D40: DIECUT 2 (RDC) | G40: 4 | I40: =SUM(E40:H40) -> 4 | O40: =SUM(K40:N40) -> 0
D41: KOPEK DIE CUT 1/HITUNG LEMBAR | H41: 18 | I41: =SUM(E41:H41) -> 18 | N41: 18 | O41: =SUM(K41:N41) -> 18 | Q41: Shift 1,2,3
D42: KOPEK DIE CUT 2/HITUNG LEMBAR | H42: 18 | I42: =SUM(E42:H42) -> 18 | O42: =SUM(K42:N42) -> 0
D43: SHEETER | G43: 6 | I43: =SUM(E43:H43) -> 6 | M43: 6 | O43: =SUM(K43:N43) -> 6 | Q43: Shift 1,2,3
D44: LAMINASI | E44: 2 | F44: 1 | G44: 3 | I44: =SUM(E44:H44) -> 6 | K44: 2 | L44: 1 | M44: 3 | O44: =SUM(K44:N44) -> 6 | Q44: Shift 1,2,3
...

Sheet 10.24 MAPPING PACK BEKASI
C3: DATA TAHUN 2025 | E3: PACKAGING BEKASI
C4: DEPARTEMEN | D4: POSISI | E4: KEBUTUHAN | K4: EXISTING
E5: Tetap Fix | F5: Kontrak Fix | G5: OS Fix | H5: OS Variabel | I5: TOTAL KEBUTUHAN (Jumlah) | J5: TOTAL KEBUTUHAN (Nominal) | K5: Tetap Fix | L5: Kontrak Fix | M5: OS Fix | N5: OS Variabel | O5: TOTAL EXISTING (Jumlah) | P5: TOTAL EXISTING (Nominal)
C8: GM | D8: GM | I8: =SUM(E8:H8) -> 0 | O8: =SUM(K8:N8) -> 0
C9: Manager/BM/OM | D9: OM | I9: =SUM(E9:H9) -> 0 | O9: =SUM(K9:N9) -> 0
D10: ASMEN | E10: 1 | I10: =SUM(E10:H10) -> 1 | K10: 1 | O10: =SUM(K10:N10) -> 1
C11: HRD UMUM | D11: KARU HRD | I11: =SUM(E11:H11) -> 0 | O11: =SUM(K11:N11) -> 0
D12: STAFF HRD | F12: 1 | I12: =SUM(E12:H12) -> 1 | L12: 1 | O12: =SUM(K12:N12) -> 1
D13: KARU GA | E13: 1 | I13: =SUM(E13:H13) -> 1 | K13: 1 | O13: =SUM(K13:N13) -> 1
D14: GA/UMUM : AREA KANTOR | I14: =SUM(E14:H14) -> 0 | O14: =SUM(K14:N14) -> 0
D15: GA/UMUM : AREA PRODUKSI | G15: 3 | I15: =SUM(E15:H15) -> 3 | M15: 3 | O15: =SUM(K15:N15) -> 3
D16: GA/UMUM : AFVAL | G16: 1 | I16: =SUM(E16:H16) -> 1 | M16: 1 | O16: =SUM(K16:N16) -> 1
D17: SECURITY | G17: 2 | I17: =SUM(E17:H17) -> 2 | M17: 2 | O17: =SUM(K17:N17) -> 2
C18: PEMASARAN | D18: KADIV MARKETING | F18: 1 | I18: =SUM(E18:H18) -> 1 | L18: 1 | O18: =SUM(K18:N18) -> 1
D19: MARKETING | F19: 2 | I19: =SUM(E19:H19) -> 2 | L19: 1 | O19: =SUM(K19:N19) -> 1
D20: ADMIN MKT | E20: 1 | I20: =SUM(E20:H20) -> 1 | K20: 1 | O20: =SUM(K20:N20) -> 1
D21: MARKETING SUPPORT | I21: =SUM(E21:H21) -> 0 | O21: =SUM(K21:N21) -> 0
C22: IT | D22: STAFF IT | I22: =SUM(E22:H22) -> 0 | O22: =SUM(K22:N22) -> 0
C23: PPIC | D23: KADIV PPIC | I23: =SUM(E23:H23) -> 0 | O23: =SUM(K23:N23) -> 0
D24: KARU PPIC | I24: =SUM(E24:H24) -> 0 | O24: =SUM(K24:N24) -> 0
D25: STAFF PPIC | F25: 1 | I25: =SUM(E25:H25) -> 1 | L25: 1 | O25: =SUM(K25:N25) -> 1
D26: ADM PPIC | G26: 1 | I26: =SUM(E26:H26) -> 1 | M26: 1 | O26: =SUM(K26:N26) -> 1
D27: KARU GUDANG | I27: =SUM(E27:H27) -> 0 | O27: =SUM(K27:N27) -> 0
D28: STAFF GBB | E28: 1 | I28: =SUM(E28:H28) -> 1 | K28: 1 | O28: =SUM(K28:N28) -> 1
D29: STAFF GUDANG SPAREPART | F29: 1 | I29: =SUM(E29:H29) -> 1 | L29: 1 | O29: =SUM(K29:N29) -> 1
D30: STAFF GBJ | G30: 2 | I30: =SUM(E30:H30) -> 2 | M30: 2 | O30: =SUM(K30:N30) -> 2
D31: STAFF EKSPEDISI | E31: 1 | I31: =SUM(E31:H31) -> 1 | K31: 1 | O31: =SUM(K31:N31) -> 1
D32: EKSPEDISI - ADMIN EKSPEDISI | G32: 1 | I32: =SUM(E32:H32) -> 1 | M32: 1 | O32: =SUM(K32:N32) -> 1
D33: EKSPEDISI - SOPIR/DRIVER | G33: 3 | I33: =SUM(E33:H33) -> 3 | M33: 3 | O33: =SUM(K33:N33) -> 3
D34: EKSPEDISI - HELPER/LOADING | I34: =SUM(E34:H34) -> 0 | O34: =SUM(K34:N34) -> 0
D35: MATERIAL HANDLING | G35: 1 | I35: =SUM(E35:H35) -> 1 | M35: 1 | O35: =SUM(K35:N35) -> 1
C36: ACC & FINANCE | D36: KADIV ACCOUNTING | I36: =SUM(E36:H36) -> 0 | O36: =SUM(K36:N36) -> 0
D37: STAFF ACCOUNTING | F37: 1 | I37: =SUM(E37:H37) -> 1 | L37: 1 | O37: =SUM(K37:N37) -> 1
D38: KEUANGAN | G38: 2 | I38: =SUM(E38:H38) -> 2 | M38: 2 | O38: =SUM(K38:N38) -> 2
D39: KASIR | I39: =SUM(E39:H39) -> 0 | O39: =SUM(K39:N39) -> 0
D40: KARU PIUTANG | I40: =SUM(E40:H40) -> 0 | O40: =SUM(K40:N40) -> 0
D41: STAFF PIUTANG | I41: =SUM(E41:H41) -> 0 | O41: =SUM(K41:N41) -> 0
D42: PENAGIHAN | I42: =SUM(E42:H42) -> 0 | O42: =SUM(K42:N42) -> 0
D43: INVOICING | I43: =SUM(E43:H43) -> 0 | O43: =SUM(K43:N43) -> 0
C44: PEMBELIAN | D44: PEMBELIAN | E44: 1 | G44: 1 | I44: =SUM(E44:H44) -> 2 | K44: 1 | M44: 1 | O44: =SUM(K44:N44) -> 2
...

Sheet 10.24 MAPPING SHOPPINGBAG
C3: DATA TAHUN 2025 | E3: SHOPPING BAG
C4: DEPARTEMEN | D4: POSISI | E4: KEBUTUHAN | K4: EXISTING
E5: Tetap Fix | F5: Kontrak Fix | G5: OS Fix | H5: OS Variabel | I5: TOTAL KEBUTUHAN (Jumlah) | J5: TOTAL KEBUTUHAN (Nominal) | K5: Tetap Fix | L5: Kontrak Fix | M5: OS Fix | N5: OS Variabel | O5: TOTAL EXISTING (Jumlah) | P5: TOTAL EXISTING (Nominal)
C8: GM | D8: GM | I8: =SUM(E8:H8) -> 0 | O8: =SUM(K8:N8) -> 0
C9: Manager/BM/OM | D9: OM | E9: 1 | I9: =SUM(E9:H9) -> 1 | K9: 1 | O9: =SUM(K9:N9) -> 1
D10: ASMEN | I10: =SUM(E10:H10) -> 0 | O10: =SUM(K10:N10) -> 0
C11: HRD UMUM | D11: KARU HRD | I11: =SUM(E11:H11) -> 0 | O11: =SUM(K11:N11) -> 0
D12: STAFF HRD | I12: =SUM(E12:H12) -> 0 | O12: =SUM(K12:N12) -> 0
D13: KARU GA | I13: =SUM(E13:H13) -> 0 | O13: =SUM(K13:N13) -> 0
D14: GA/UMUM : AREA KANTOR | G14: 1 | I14: =SUM(E14:H14) -> 1 | M14: 1 | O14: =SUM(K14:N14) -> 1
D15: GA/UMUM : AREA PRODUKSI | G15: 4 | I15: =SUM(E15:H15) -> 4 | M15: 4 | O15: =SUM(K15:N15) -> 4
D16: GA/UMUM : AFVAL | F16: 1 | G16: 1 | I16: =SUM(E16:H16) -> 2 | L16: 1 | M16: 1 | O16: =SUM(K16:N16) -> 2
D17: SECURITY | G17: 2 | I17: =SUM(E17:H17) -> 2 | M17: 2 | O17: =SUM(K17:N17) -> 2
C18: PEMASARAN | D18: KADIV MARKETING | I18: =SUM(E18:H18) -> 0 | O18: =SUM(K18:N18) -> 0
D19: MARKETING | E19: 3 | F19: 5 | I19: =SUM(E19:H19) -> 8 | K19: 3 | L19: 3 | O19: =SUM(K19:N19) -> 6
D20: ADMIN MKT | E20: 1 | G20: 2 | I20: =SUM(E20:H20) -> 3 | K20: 1 | M20: 2 | O20: =SUM(K20:N20) -> 3
D21: MARKETING SUPPORT | I21: =SUM(E21:H21) -> 0 | O21: =SUM(K21:N21) -> 0
C22: IT | D22: STAFF IT | I22: =SUM(E22:H22) -> 0 | O22: =SUM(K22:N22) -> 0
C23: PPIC | D23: KADIV PPIC | I23: =SUM(E23:H23) -> 0 | O23: =SUM(K23:N23) -> 0
D24: KARU PPIC | I24: =SUM(E24:H24) -> 0 | O24: =SUM(K24:N24) -> 0
D25: STAFF PPIC | E25: 1 | I25: =SUM(E25:H25) -> 1 | K25: 1 | O25: =SUM(K25:N25) -> 1
D26: ADM PPIC | G26: 1 | I26: =SUM(E26:H26) -> 1 | M26: 1 | O26: =SUM(K26:N26) -> 1
D27: KARU GUDANG | I27: =SUM(E27:H27) -> 0 | O27: =SUM(K27:N27) -> 0
D28: STAFF GBB | G28: 1 | I28: =SUM(E28:H28) -> 1 | M28: 1 | O28: =SUM(K28:N28) -> 1
D29: GBB - ADMIN GBB | G29: 1 | I29: =SUM(E29:H29) -> 1 | M29: 1 | O29: =SUM(K29:N29) -> 1
D30: STAFF GUDANG SPAREPART | I30: =SUM(E30:H30) -> 0 | O30: =SUM(K30:N30) -> 0
D31: STAFF GBJ | F31: 1 | G31: 1 | I31: =SUM(E31:H31) -> 2 | L31: 1 | M31: 1 | O31: =SUM(K31:N31) -> 2
D32: EKSPEDISI - ADMIN EKSPEDISI | I32: =SUM(E32:H32) -> 0 | O32: =SUM(K32:N32) -> 0
D33: EKSPEDISI - SOPIR/DRIVER | G33: 4 | I33: =SUM(E33:H33) -> 4 | M33: 4 | O33: =SUM(K33:N33) -> 4
D34: EKSPEDISI - HELPER/LOADING | G34: 2 | I34: =SUM(E34:H34) -> 2 | M34: 2 | O34: =SUM(K34:N34) -> 2
D35: MATERIAL HANDLING | G35: 1 | I35: =SUM(E35:H35) -> 1 | M35: 1 | O35: =SUM(K35:N35) -> 1
C36: ACC & FINANCE | D36: KADIV ACCOUNTING | E36: 1 | I36: =SUM(E36:H36) -> 1 | K36: 1 | O36: =SUM(K36:N36) -> 1
D37: STAFF ACCOUNTING | I37: =SUM(E37:H37) -> 0 | O37: =SUM(K37:N37) -> 0
D38: KEUANGAN | G38: 1 | I38: =SUM(E38:H38) -> 1 | M38: 1 | O38: =SUM(K38:N38) -> 1
D39: KASIR | E39: 1 | F39: 1 | I39: =SUM(E39:H39) -> 2 | K39: 1 | O39: =SUM(K39:N39) -> 1
D40: KARU PIUTANG | I40: =SUM(E40:H40) -> 0 | O40: =SUM(K40:N40) -> 0
D41: STAFF PIUTANG | G41: 1 | I41: =SUM(E41:H41) -> 1 | M41: 1 | O41: =SUM(K41:N41) -> 1
D42: PENAGIHAN | I42: =SUM(E42:H42) -> 0 | O42: =SUM(K42:N42) -> 0
D43: INVOICING | G43: 1 | I43: =SUM(E43:H43) -> 1 | M43: 1 | O43: =SUM(K43:N43) -> 1
C44: PEMBELIAN | D44: PEMBELIAN | I44: =SUM(E44:H44) -> 0 | O44: =SUM(K44:N44) -> 0
...

Sheet 2025. RESUME PLAN
A1: PEMETAAN SDM SBU PACKAGING
A2: PERIODE TAHUN 2025
A4: CABANG | B4: KEBUTUHAN SDM | H4: EXISTING SDM | M4: SELISIH
B5: TETAP | C5: KONTRAK | D5: OS FIX | E5: OS VARIABEL | F5: JUMLAH | G5: KETERANGAN | H5: TETAP | I5: KONTRAK | J5: OS FIX | K5: OS VARIABEL | L5: JUMLAH
A6: PACKAGING SURABAYA | B6: ='10.24 MAPPING KARAH'!E55 -> 23 | C6: ='10.24 MAPPING KARAH'!F55 -> 22 | D6: ='10.24 MAPPING KARAH'!G55 -> 84 | E6: ='10.24 MAPPING KARAH'!H55 -> 38 | F6: =SUM(B6:E6) -> 167 | G6: Op. KBA, QC, Prepress, Gluer | H6: ='10.24 MAPPING KARAH'!K55 -> 22 | I6: ='10.24 MAPPING KARAH'!L55 -> 19 | J6: ='10.24 MAPPING KARAH'!M55 -> 71 | K6: ='10.24 MAPPING KARAH'!N55 -> 38 | L6: =SUM(H6:K6) -> 150 | M6: =F6-L6 -> 17
A7: PACKAGING BEKASI | B7: ='10.24 MAPPING PACK BEKASI'!E73 -> 20 | C7: ='10.24 MAPPING PACK BEKASI'!F73 -> 15 | D7: ='10.24 MAPPING PACK BEKASI'!G73 -> 50 | E7: ='10.24 MAPPING PACK BEKASI'!H73 -> 55 | F7: ='10.24 MAPPING PACK BEKASI'!I73 -> 140 | G7: Mekanik, Marketing | H7: ='10.24 MAPPING PACK BEKASI'!K73 -> 20 | I7: ='10.24 MAPPING PACK BEKASI'!L73 -> 12 | J7: ='10.24 MAPPING PACK BEKASI'!M73 -> 51 | K7: ='10.24 MAPPING PACK BEKASI'!N73 -> 55 | L7: =SUM(H7:K7) -> 138 | M7: =F7-L7 -> 2
A8: SHOPPINGBAG | B8: ='10.24 MAPPING SHOPPINGBAG'!E73 -> 18 | C8: ='10.24 MAPPING SHOPPINGBAG'!F73 -> 25 | D8: ='10.24 MAPPING SHOPPINGBAG'!G73 -> 93 | E8: ='10.24 MAPPING SHOPPINGBAG'!H73 -> 102 | F8: =SUM(B8:E8) -> 238 | G8: Product Engineering, MKT, 2 operator, Kasir | H8: ='10.24 MAPPING SHOPPINGBAG'!K73 -> 18 | I8: ='10.24 MAPPING SHOPPINGBAG'!L73 -> 21 | J8: ='10.24 MAPPING SHOPPINGBAG'!M73 -> 92 | K8: ='10.24 MAPPING SHOPPINGBAG'!N73 -> 102 | L8: =SUM(H8:K8) -> 233 | M8: =F8-L8 -> 5
A9: TWL | B9: ='10.24 MAPPING TWL'!E52 -> 25 | C9: ='10.24 MAPPING TWL'!F52 -> 2 | D9: ='10.24 MAPPING TWL'!G52 -> 52 | E9: ='10.24 MAPPING TWL'!H52 -> 74 | F9: =SUM(B9:E9) -> 153 | G9: Diajukan kry tetap 2 karyawan (PHL tambah 22 orang untuk mesin die cut baru) | H9: ='10.24 MAPPING TWL'!K52 -> 23 | I9: ='10.24 MAPPING TWL'!L52 -> 4 | J9: ='10.24 MAPPING TWL'!M52 -> 48 | K9: ='10.24 MAPPING TWL'!N52 -> 56 | L9: =SUM(H9:K9) -> 131 | M9: =F9-L9 -> 22
A10: TOTAL SBU PACKAGING | B10: =SUM(B6:B9) -> 86 | C10: =SUM(C6:C9) -> 64 | D10: =SUM(D6:D9) -> 279 | E10: =SUM(E6:E9) -> 269 | F10: =SUM(F6:F9) -> 698 | H10: =SUM(H6:H9) -> 83 | I10: =SUM(I6:I9) -> 56 | J10: =SUM(J6:J9) -> 262 | K10: =SUM(K6:K9) -> 251 | L10: =SUM(L6:L9) -> 652 | M10: =SUM(M6:M9) -> 46
A12: BIAYA GAJI PER BULAN SDM SBU PACKAGING
A13: CABANG | B13: KEBUTUHAN SDM | H13: EXISTING SDM | M13: SELISIH | N13: PLAN OMZET | O13: % BIAYA SDM KEBUTUHAN | P13: % BIAYA SDM EXISTING | Q13: GAJI T/K SAJA 2025 | R13: THR 2025 | S13: BPJS (Perusahaan) 2025 | T13: Rawat Jalan 2025 | U13: Rawat Inap 2025
B14: TETAP | C14: KONTRAK | D14: OS FIX | E14: OS VARIABEL | F14: JUMLAH | G14: KETERANGAN | H14: TETAP | I14: KONTRAK | J14: OS FIX | K14: OS VARIABEL | L14: JUMLAH | Q14: Per Bulan | R14: Per Bulan | S14: Per Bulan | T14: Per Bulan | U14: Per Bulan
A15: PACKAGING SURABAYA | B15: =(5%*H15)+H15 -> 1.4270609e+08 | C15: =(5%*I15)+I15+(2*5000000) -> 1.3064057e+08 | D15: =(5%*J15)+J15+(2*100000) -> 183293750 | E15: =(5%*K15)+K15 -> 74812500 | F15: =SUM(B15:E15) -> 5.3145291e+08 | H15: =133160562+2750000 -> 135910562 | I15: =112095782+2800000 -> 114895782 | J15: =(30*130000*25)+(41*75000*25) -> 174375000 | K15: =(38*75000*25) -> 71250000 | L15: =SUM(H15:K15) -> 496431344 | M15: =F15-L15 -> 35021567 | N15: 3000000000 | O15: =F15/N15 -> 0.17715097 | P15: =L15/N15 -> 0.16547711 | Q15: 257519161 | R15: =(Q15/12)+(D15/12)+(E15/12) -> 42968784 | S15: =(10.89%*Q15)+(2%*D15)+(2%*E15) -> 33205962 | T15: =1%*Q15 -> 2575191.6 | U15: =1.5%*Q15 -> 3862787.4
A16: PACKAGING BEKASI | B16: =(5%*H16)+H16 -> 1.3104297e+08 | C16: =(5%*I16)+I16+(3*5500000) -> 98112650 | D16: =(5%*J16)+J16 -> 137812500 | E16: =(5%*K16)+K16 -> 101062500 | F16: =SUM(B16:E16) -> 4.6803062e+08 | H16: =122902833+1900000 -> 124802833 | I16: =76176333+1550000 -> 77726333 | J16: =(22*140000*25)+(31*70000*25) -> 131250000 | K16: =70000*55*25 -> 96250000 | L16: =SUM(H16:K16) -> 430029166 | M16: =F16-L16 -> 38001458 | N16: 2700000000 | O16: =F16/N16 -> 0.17334468 | P16: =L16/N16 -> 0.15927006 | Q16: 209033124 | R16: =(Q16/12)+(D16/12)+(E16/12) -> 37325677 | S16: =(10.89%*Q16)+(2%*D16)+(2%*E16) -> 27541207 | T16: =1%*Q16 -> 2090331.2 | U16: =1.5%*Q16 -> 3135496.9
A17: SHOPPINGBAG | B17: =(5%*H17)+H17 -> 1.3582093e+08 | C17: =(5%*I17)+I17+(4*5500000) -> 1.4037568e+08 | D17: =(5%*J17)+J17 -> 187031250 | E17: =(5%*K17)+K17 -> 174037500 | F17: =SUM(B17:E17) -> 6.3726536e+08 | H17: =126203267+3150000 -> 129353267 | I17: =111938745+800000 -> 112738745 | J17: =(125000*15*25)+(70000*75*25) -> 178125000 | K17: =65000*102*25 -> 165750000 | L17: =SUM(H17:K17) -> 585967012 | M17: =F17-L17 -> 51298351 | N17: 2500000000 | O17: =F17/N17 -> 0.25490614 | P17: =L17/N17 -> 0.2343868 | Q17: 250049113 | R17: =(Q17/12)+(D17/12)+(E17/12) -> 50926489 | S17: =(10.89%*Q17)+(2%*D17)+(2%*E17) -> 34451723 | T17: =1%*Q17 -> 2500491.1 | U17: =1.5%*Q17 -> 3750736.7
A18: TWL | B18: =(5%*H18)+H18 -> 1.1668357e+08 | C18: =(5%*I18)+I18 -> 19218255 | D18: =(5%*J18)+J18+6000000 -> 95617500 | E18: =(5%*K18)+K18+27000000 -> 115423125 | F18: =SUM(B18:E18) -> 3.4694245e+08 | G18: - | H18: =107877207+3250000 -> 111127207 | I18: 18303100 | J18: 85350000 | K18: 84212500 | L18: =SUM(H18:K18) -> 298992807 | M18: =F18-L18 -> 47949640 | N18: 4000000000 | O18: =F18/N18 -> 0.086735612 | P18: =L18/N18 -> 0.074748202 | Q18: 132489322 | R18: =(Q18/12)+(D18/12)+(E18/12) -> 28627496 | S18: =(10.89%*Q18)+(2%*D18)+(2%*E18) -> 18648900 | T18: =1%*Q18 -> 1324893.2 | U18: =1.5%*Q18 -> 1987339.8
A19: TOTAL SBU PACKAGING | B19: =SUM(B15:B18) -> 5.2625356e+08 | C19: =SUM(C15:C18) -> 388347158 | D19: =SUM(D15:D18) -> 603755000 | E19: =SUM(E15:E18) -> 465335625 | F19: =SUM(F15:F18) -> 1983691345 | H19: =SUM(H15:H18) -> 501193869 | I19: =SUM(I15:I18) -> 323663960 | J19: =SUM(J15:J18) -> 569100000 | K19: =SUM(K15:K18) -> 417462500 | L19: =SUM(L15:L18) -> 1811420329 | M19: =F19-L19 -> 1.7227102e+08 | Q19: =SUM(Q15:Q18) -> 849090720 | R19: =SUM(R15:R18) -> 1.5984845e+08 | S19: =SUM(S15:S18) -> 1.1384779e+08 | T19: =SUM(T15:T18) -> 8490907.2 | U19: =SUM(U15:U18) -> 12736361
A23: RESUME JUMLAH TENAGA KERJA 2025
A24: KEBUTUHAN VS EXISTING
A25: Cabang | B25: Kebutuhan tetap/kontrak | C25: Kebutuhan os | D25: Total kebutuhan Keseluruhan | E25: Existing tetap/kontrak | F25: Existing os | G25: Total existing keseluruhan | H25: Rasio kebutuhan/existing karyawan | I25: Rasio kebutuhan/existing os | J25: DEVIASI
J26: Jumlah All | K26: Rasio All
A27: Packaging Surabaya | B27: =B6+C6 -> 45 | C27: =D6+E6 -> 122 | D27: =SUM(B27:C27) -> 167 | E27: =H6+I6 -> 41 | F27: =J6+K6 -> 109 | G27: =SUM(E27:F27) -> 150 | H27: =(E27-B27)/B27 -> -0.088888889 | I27: =(F27-C27)/C27 -> -0.10655738 | J27: =G27-D27 -> -17 | K27: =(G27-D27)/D27 -> -0.10179641
A28: Packaging Bekasi | B28: =B7+C7 -> 35 | C28: =D7+E7 -> 105 | D28: =SUM(B28:C28) -> 140 | E28: =H7+I7 -> 32 | F28: =J7+K7 -> 106 | G28: =SUM(E28:F28) -> 138 | H28: =(E28-B28)/B28 -> -0.085714286 | I28: =(F28-C28)/C28 -> 0.0095238095 | J28: =G28-D28 -> -2 | K28: =(G28-D28)/D28 -> -0.014285714
A29: Shoppingbag | B29: =B8+C8 -> 43 | C29: =D8+E8 -> 195 | D29: =SUM(B29:C29) -> 238 | E29: =H8+I8 -> 39 | F29: =J8+K8 -> 194 | G29: =SUM(E29:F29) -> 233 | H29: =(E29-B29)/B29 -> -0.093023256 | I29: =(F29-C29)/C29 -> -0.0051282051 | J29: =G29-D29 -> -5 | K29: =(G29-D29)/D29 -> -0.021008403
A30: TWL | B30: =B9+C9 -> 27 | C30: =D9+E9 -> 126 | D30: =SUM(B30:C30) -> 153 | E30: =H9+I9 -> 27 | F30: =J9+K9 -> 104 | G30: =SUM(E30:F30) -> 131 | H30: =(E30-B30)/B30 -> 0 | I30: =(F30-C30)/C30 -> -0.17460317 | J30: =G30-D30 -> -22 | K30: =(G30-D30)/D30 -> -0.14379085
A31: SBU PACKAGING | B31: =SUM(B27:B30) -> 150 | C31: =SUM(C27:C30) -> 548 | D31: =SUM(D27:D30) -> 698 | E31: =SUM(E27:E30) -> 139 | F31: =SUM(F27:F30) -> 513 | G31: =SUM(G27:G30) -> 652 | H31: =(E31-B31)/B31 -> -0.073333333 | I31: =(F31-C31)/C31 -> -0.063868613 | J31: =SUM(J26:J30) -> -46 | K31: =(G31-D31)/D31 -> -0.065902579
A33: BIAYA SDM
A34: Cabang | B34: Kebutuhan Fix cost karyawan | C34: Kebutuhan Fix cost OS | D34: Total Kebutuhan Biaya | E34: Existing Fix Cost Karyawan | F34: Existing Fix Cost PHL | G34: Total Biaya Existing | H34: rasio fix cost karyawan | I34: rasio fix cost OS | J34: Omset/bulan | K34: Biaya/Omset
A35: Packaging Surabaya | B35: =B15+C15 -> 2.7334666e+08 | C35: =D15+E15 -> 258106250 | D35: =$B$35+C35 -> 5.3145291e+08 | E35: =H15+I15 -> 250806344 | F35: =J15+K15 -> 245625000 | G35: =E35+F35 -> 496431344 | H35: =(E35-B35)/B35 -> -0.082460554 | I35: =(F35-C35)/C35 -> -0.048357024 | J35: 3000000000 | K35: =G35/J35 -> 0.16547711
A36: Packaging Bekasi | B36: =B16+C16 -> 2.2915562e+08 | C36: =D16+E16 -> 238875000 | D36: =B36+C36 -> 4.6803062e+08 | E36: =H16+I16 -> 202529166 | F36: =J16+K16 -> 227500000 | G36: =E36+F36 -> 430029166 | H36: =(E36-B36)/B36 -> -0.11619378 | I36: =(F36-C36)/C36 -> -0.047619048 | J36: 2700000000 | K36: =G36/J36 -> 0.15927006
A37: Shoppingbag | B37: =B17+C17 -> 2.7619661e+08 | C37: =D17+E17 -> 361068750 | D37: =B37+C37 -> 6.3726536e+08 | E37: =H17+I17 -> 242092012 | F37: =J17+K17 -> 343875000 | G37: =E37+F37 -> 585967012 | H37: =(E37-B37)/B37 -> -0.12347943 | I37: =(F37-C37)/C37 -> -0.047619048 | J37: 2500000000 | K37: =G37/J37 -> 0.2343868
A38: TWL | B38: =B18+C18 -> 1.3590182e+08 | C38: =D18+E18 -> 211040625 | D38: =B38+C38 -> 3.4694245e+08 | E38: =H18+I18 -> 129430307 | F38: =J18+K18 -> 169562500 | G38: =E38+F38 -> 298992807 | H38: =(E38-B38)/B38 -> -0.047619048 | I38: =(F38-C38)/C38 -> -0.19654095 | J38: 4000000000 | K38: =G38/J38 -> 0.074748202
A39: SBU PACKAGING | B39: =SUM(B35:B38) -> 9.1460072e+08 | C39: =SUM(C35:C38) -> 1069090625 | D39: =SUM(D35:D38) -> 1983691345 | E39: =SUM(E35:E38) -> 824857829 | F39: =SUM(F35:F38) -> 986562500 | G39: =SUM(G35:G38) -> 1811420329 | H39: =(E39-B39)/B39 -> -0.098122481 | I39: =(F39-C39)/C39 -> -0.077194695 | J39: =SUM(J34:J38) -> 12200000000 | K39: =(G39-D39)/D39 -> -0.08684366
A52: JUMLAH DATA OS SBU PACKAGING AKTIF
A53: CABANG | B53: JUMLAH | C53: Plan
A54: PACKAGING SURABAYA | B54: ='MAPPING ALL CABANG'!M92+'MAPPING ALL CABANG'!N92 -> 127
A55: PACKAGING BEKASI | B55: ='MAPPING ALL CABANG'!Y92+'MAPPING ALL CABANG'!Z92 -> 100
A56: SHOPPINGBAG | B56: ='MAPPING ALL CABANG'!AK92+'MAPPING ALL CABANG'!AL92 -> 135
A57: TEMAPACK | B57: ='MAPPING ALL CABANG'!AW92+'MAPPING ALL CABANG'!AX92 -> 0
A58: TWL | B58: ='SDM TWL 2024'!F136 -> 98 | C58: -
...

Sheet KRY 2024
A1: Page 8 | B1: DATA KARYAWAN TMG - PACKAGING
J2: Status Karyawan | K2: AwalMasuk | L2: Awal/Periode | M2: Akhir/Sd | N2: TahunPengangkatan
D3: Nama Pegawai | E3: No Registrasi | F3: Jabatan | G3: Level | H3: Departemen | I3: Cost Center | O3: AwalDiangkat | S3: TanggalLahir
B4: No | C4: NIP | P4: Status | Q4: Pendidikan | R4: L/P
B5: 1 | C5: 0800773 | D5: ERI SURYA WATI | E5: 0108143 | F5: Kadiv Accounting | G5: Kasi/Wakasi/Kadiv/W akadiv/Koordinator | H5: Accounting/Finan ce | I5: Akuntansi | J5: Tetap | K5: 11-JAN-08 | L5: 01-JAN-12 | N5: 01-JAN-12 | O5: 2012 | P5: TK / 1 | Q5: S1 | R5: P | S5: 05-FEB-86
B6: 2 | C6: 1914410 | D6: RIANISKA_KARAH | E6: 011900364 | F6: Staff HRD | G6: Staff/Operator | H6: HRD & Umum | I6: HRD | J6: Tetap | K6: 01-JAN-19 | L6: 01-JAN-19 | N6: 01-JAN-19 | O6: 2019 | P6: TK / 0 | R6: L
B7: 3 | C7: 1701339 | D7: AHMAD ALAND ANANTA | E7: 011700210 | F7: Operational Manager | G7: Manager | H7: Manager/Branch Manager | I7: Branch Manager | J7: Tetap | K7: 25-JUL-17 | L7: 01-JAN-19 | N7: 01-JAN-19 | O7: 2019 | P7: K / 2 | Q7: MM | R7: L | S7: 03-NOV-92
B8: 4 | C8: 1701333 | D8: YISKA AVIYANTI | E8: 011700181 | F8: Kadiv Marketing | G8: Kasi/Wakasi/Kadiv/W akadiv/Koordinator | H8: Pemasaran | I8: Pemasaran | J8: Tetap | K8: 05-JUN-17 | L8: 01-JUL-19 | N8: 01-JUL-19 | O8: 2019 | P8: TK / 2 | Q8: D3 | R8: P | S8: 19-DEC-79
B9: 5 | C9: 1914272 | D9: SUPRIYATIN | E9: 011900002 | F9: Marketing | G9: Staff/Operator | H9: Pemasaran | I9: Pemasaran | J9: Tetap | K9: 01-JUL-19 | L9: 01-SEP-20 | N9: 01-SEP-20 | O9: 2020 | P9: TK / 2 | Q9: S1 | R9: P | S9: 24-NOV-87
B10: 6 | C10: 2214702 | D10: YONGKI INDRA LESMANA | E10: 012200015 | F10: Marketing | G10: Staff/Operator | H10: Pemasaran | I10: Pemasaran | J10: Tetap | K10: 01-JAN-22 | L10: 01-JAN-22 | N10: 01-JAN-22 | O10: 2022 | P10: K / 2 | Q10: S1 | R10: L | S10: 04-JUN-92
B11: 7 | C11: 0600912 | D11: JUMADI ADI WIJAYA | E11: 1106600 | F11: Gudang Barang Jadi | G11: Staff/Operator | H11: Product Planning Control | I11: Gudang B.Jadi | J11: Tetap | K11: 26-JAN-06 | L11: 01-JAN-12 | N11: 01-JAN-12 | O11: 2012 | P11: K / 2 | Q11: SMKN | R11: L | S11: 23-OCT-86
B12: 8 | C12: 2114683 | D12: INDRA VIRONIKE | E12: 012100269 | F12: Kadiv PPIC | G12: Kasi/Wakasi/Kadiv/W akadiv/Koordinator | H12: Product Planning Control | I12: PPIC | J12: Tetap | K12: 22-DEC-21 | L12: 01-JAN-23 | N12: 01-JAN-23 | O12: 2023 | P12: K / 3 | Q12: S1 | R12: L | S12: 08-FEB-87
B13: 9 | C13: 0700609 | D13: BUDI DWI SETIONO | E13: 0107024 | F13: Staff PPIC | G13: Staff/Operator | H13: Product Planning Control | I13: PPIC | J13: Tetap | K13: 08-JAN-07 | L13: 01-JAN-10 | N13: 01-JAN-10 | O13: 2010 | P13: K / 2 | Q13: SMK-GF | R13: L | S13: 01-AUG-88
B14: 10 | C14: 2214701 | D14: WILDAN FIRMANSYAH | E14: 012200016 | F14: Desain Grafis | G14: Staff/Operator | H14: Produksi | I14: Pra Cetak | J14: Tetap | K14: 01-JAN-22 | L14: 01-JAN-22 | N14: 01-JAN-22 | O14: 2022 | P14: TK / 1 | Q14: S1 | R14: L | S14: 19-OCT-93
B15: 11 | C15: 2114518 | D15: FAJAR KRISWANTO | E15: 012100031 | F15: Finishing | G15: Staff/Operator | H15: Produksi | I15: Finishing | J15: Tetap | K15: 01-JAN-21 | L15: 01-JAN-24 | N15: 01-JAN-24 | O15: 2024 | P15: K / 1 | Q15: SMK | R15: L | S15: 10-MAR-88
B16: 12 | C16: 1501252 | D16: HENDRO BASUKI | E16: 011500508 | F16: Finishing | G16: Staff/Operator | H16: Produksi | I16: Finishing | J16: Tetap | K16: 22-JUL-15 | L16: 25-JUL-19 | N16: 25-JUL-19 | O16: 2019 | P16: TK / 0 | Q16: SMK | R16: L | S16: 28-JUN-80
B17: 13 | C17: HL60061 | D17: IRFAN MAHMUDI | E17: 1106569 | F17: Finishing | G17: Staff/Operator | H17: Produksi | I17: Finishing | J17: Tetap | K17: 20-JUN-05 | L17: 01-JUL-15 | N17: 01-JUL-15 | O17: 2015 | P17: TK / 2 | Q17: SMK | R17: L | S17: 18-JUL-85
B18: 14 | C18: 0700710 | D18: MUKHAMAD FAHZRI | E18: 1207005 | F18: Finishing | G18: Staff/Operator | H18: Produksi | I18: Finishing | J18: Tetap | K18: 13-DEC-07 | L18: 01-JAN-10 | N18: 01-JAN-10 | O18: 2010 | P18: K / 2 | Q18: SMK-GF | R18: L | S18: 21-APR-88
B19: 15 | C19: 0801018 | D19: HAFID ZAINUDIN | E19: 0108213 | F19: Karu Finishing | G19: Karu/Wakaru | H19: Produksi | I19: Finishing | J19: Tetap | K19: 01-JAN-08 | L19: 01-JUN-14 | N19: 01-JUN-14 | O19: 2014 | P19: K / 2 | Q19: SMK | R19: L | S19: 20-JAN-84
B20: 16 | C20: 1501249 | D20: DIDIK SANTOSO | E20: 011500320 | F20: Karu Produksi | G20: Karu/Wakaru | H20: Produksi | I20: Sheet | J20: Tetap | K20: 25-MAY-15 | L20: 01-AUG-17 | N20: 01-AUG-17 | O20: 2017 | P20: TK / 2 | Q20: SMK-GF | R20: L | S20: 06-FEB-78
B21: 17 | C21: 0500668 | D21: AGUS SUPIADI | E21: 1106559 | F21: Op. Cetak Sheet | G21: Staff/Operator | H21: Produksi | I21: Sheet | J21: Tetap | K21: 19-MAY-05 | L21: 01-JAN-11 | N21: 01-JAN-11 | O21: 2011 | P21: K / 3 | Q21: SLTA | R21: L | S21: 16-AUG-83
B22: 18 | C22: 1501261 | D22: KURNIAWAN HARIADI | E22: 011500674 | F22: Op. Cetak Sheet | G22: Staff/Operator | H22: Produksi | I22: Sheet | J22: Tetap | K22: 02-NOV-15 | L22: 01-JAN-21 | N22: 01-JAN-21 | O22: 2021 | P22: K / 1 | Q22: SMKN | R22: L | S22: 03-APR-92 | T22: RESIGN
B23: 19 | C23: 2114519 | D23: PUSPITA RIZKI ANDININGRUM | E23: 012100032 | F23: Staff D&D | G23: Staff/Operator | H23: Produksi | I23: Pra Cetak | J23: Tetap | K23: 01-JAN-21 | L23: 01-JAN-24 | N23: 01-JAN-24 | O23: 2024 | P23: TK / 0 | Q23: S1 | R23: P | S23: 02-JUN-94
B24: 20 | C24: 0500519 | D24: DARYANTO | E24: 1106188 | F24: Kadiv R&D QC | G24: Kasi/Wakasi/Kadiv/W akadiv/Koordinator | H24: Q C | I24: QC | J24: Tetap | K24: 15-DEC-05 | L24: 01-JAN-08 | N24: 01-JAN-08 | O24: 2008 | P24: K / 2 | Q24: D3 | R24: L | S24: 08-SEP-83
B25: 21 | C25: 0700719 | D25: FERIK MURDIANTO | E25: 1207007 | F25: Staff R&D dan QC | G25: Staff/Operator | H25: Q C | I25: QC | J25: Tetap | K25: 17-DEC-07 | L25: 01-JAN-10 | N25: 01-JAN-10 | O25: 2010 | P25: K / 2 | Q25: SMK-GF | R25: L | S25: 13-NOV-87
B26: 22 | C26: 1501251 | D26: BIMAS IRVAN ADE PRASETIA | E26: 011500499 | F26: Elektrik | G26: Staff/Operator | H26: Teknik | I26: Elektrik | J26: Tetap | K26: 01-JUL-15 | L26: 01-JAN-19 | N26: 01-JAN-19 | O26: 2019 | P26: TK / 0 | Q26: SMK | R26: L | S26: 11-DEC-94
B27: 23 | C27: 2114654 | D27: RACHMAD WAHYU ALAMSAH | E27: 012100237 | F27: Karu Elektrik | G27: Karu/Wakaru | H27: Teknik | I27: Elektrik | J27: Tetap | K27: 01-AUG-21 | L27: 01-JAN-23 | N27: 01-JAN-23 | O27: 2023 | P27: K / 2 | Q27: D3 | R27: L | S27: 22-FEB-78
B28: 24 | C28: 0800680 | D28: FEBRI SUGIARTO | E28: 0108135 | F28: Mekanik | G28: Staff/Operator | H28: Teknik | I28: Mekanik | J28: Tetap | K28: 01-JAN-08 | L28: 01-JAN-11 | N28: 01-JAN-11 | O28: 2011 | P28: K / 1 | Q28: SMK | R28: L | S28: 26-FEB-88
B29: 25 | C29: 0800917 | D29: MUHAMMAD YUNUS | E29: 0108154 | F29: Mekanik | G29: Staff/Operator | H29: Teknik | I29: Mekanik | J29: Tetap | K29: 01-JAN-08 | L29: 01-JAN-14 | N29: 01-JAN-14 | O29: 2014 | P29: K / 1 | Q29: SMK | R29: L | S29: 21-NOV-87
D30: Jumlah | K30: 25 Orang
B31: 1 | C31: 2114591 | D31: EDI SUWIGNYO HASYIM | E31: 012100170 | F31: General Manager Packaging | G31: General Manager | H31: General Manager | I31: General Manager | J31: Kontrak pasca pensiun | K31: 01-AUG-21 | L31: 01-JAN-24 | M31: 31-DEC-24 | P31: K / 2 | Q31: SMU | R31: L | S31: 23-MAR-73
B32: 2 | C32: 2314858 | D32: STELLA GABRIELLE HARNAS | E32: 012300202 | F32: Staff HRD | G32: Staff/Operator | H32: HRD & Umum | I32: HRD | J32: Kontrak 1 | K32: 18-DEC-23 | L32: 18-DEC-23 | M32: 30-JUN-24 | P32: TK / 0 | Q32: MM | R32: P | S32: 04-MAY-91
B33: 3 | C33: 2314814 | D33: PRAMESWARI CHRISNAMURTI | E33: 012300088 | F33: Marketing Support | G33: Staff/Operator | H33: Pemasaran | I33: Administrasi Pemasaran | J33: Kontrak 2 | K33: 01-JUL-23 | L33: 01-JAN-24 | M33: 30-JUN-24 | P33: TK / 0 | Q33: S1 | R33: P | S33: 21-JUL-94
B34: 4 | C34: 2314808 | D34: EKO NUR KHAFID | E34: 012300068 | F34: Staff Purchasing | G34: Staff/Operator | H34: Pembelian | I34: Pembelian | J34: Kontrak 2 | K34: 19-JUN-23 | L34: 01-JAN-24 | M34: 31-DEC-24 | P34: K / 1 | Q34: S1 | R34: L | S34: 04-APR-89
B35: 5 | C35: 2214784 | D35: ADI JAYA | E35: 012300017 | F35: Gudang Bahan Baku | G35: Staff/Operator | H35: Product Planning Control | I35: Gudang B.Baku | J35: Kontrak 2 | K35: 01-APR-22 | L35: 01-JAN-24 | M35: 31-DEC-24 | P35: TK / 0 | Q35: S1 | R35: L | S35: 03-MAR-94
B36: 6 | C36: 2214710 | D36: JEFFRY PRASETYO | E36: 012200029 | F36: Desain Grafis | G36: Staff/Operator | H36: Produksi | I36: Pra Cetak | J36: Kontrak 3 | K36: 16-FEB-22 | L36: 01-SEP-23 | M36: 31-AUG-24 | P36: TK / 0 | Q36: SMK | R36: L | S36: 08-MAY-95
B37: 7 | C37: 2314800 | D37: SALVIAN ILHAM PRAYOGA | E37: 012300039 | F37: Desain Grafis | G37: Staff/Operator | H37: Produksi | I37: Pra Cetak | J37: Kontrak 2 | K37: 10-MAY-23 | L37: 01-JAN-24 | M37: 31-DEC-24 | P37: TK / 0 | Q37: S1 | R37: L | S37: 29-OCT-92
B38: 8 | C38: 2114554 | D38: WAHYU SAPTO ADHI | E38: 012100075 | F38: Desain Grafis | G38: Staff/Operator | H38: Produksi | I38: Pra Cetak | J38: Kontrak 4 | K38: 19-APR-21 | L38: 01-JAN-24 | M38: 31-DEC-24 | P38: TK / 1 | Q38: D3 | R38: L | S38: 26-MAR-76
A39: Page 9 | B39: DATA KARYAWAN TMG - PACKAGING
J40: Status Karyawan | K40: AwalMasuk | L40: Awal/Periode | M40: Akhir/Sd | N40: TahunPengangkatan
...

Sheet MAPPING ALL CABANG
C3: DATA TAHUN 2024 | E3: PACK KARAH | Q3: PACKAGING BEKASI | AC3: SHOPPING BAG | AO3: TEMAPACK | BA3: TEMA WADAH LESTARI | BM3: PACKAGING KOMERSIAL (PACK KARAH + PACK BEKASI) | BY3: SHOPPINGBAG & TEMAPACK | CK3: SBU PACKAGING
C4: DEPARTEMEN | D4: POSISI | E4: KEBUTUHAN | K4: EXISTING | Q4: KEBUTUHAN | W4: EXISTING | AC4: KEBUTUHAN | AI4: EXISTING | AO4: KEBUTUHAN | AU4: EXISTING | BA4: KEBUTUHAN | BG4: EXISTING | BM4: KEBUTUHAN | BS4: EXISTING | CE4: EXISTING | CK4: KEBUTUHAN | CQ4: EXISTING
E5: Tetap Fix | F5: Kontrak Fix | G5: OS Fix | H5: OS Variabel | I5: TOTAL KEBUTUHAN (Jumlah) | J5: TOTAL KEBUTUHAN (Nominal) | K5: Tetap Fix | L5: Kontrak Fix | M5: OS Fix | N5: OS Variabel | O5: TOTAL EXISTING (Jumlah) | P5: TOTAL EXISTING (Nominal) | Q5: Tetap Fix | R5: Kontrak Fix | S5: OS Fix | T5: OS Variabel | U5: TOTAL KEBUTUHAN (Jumlah) | V5: TOTAL KEBUTUHAN (Nominal) | W5: Tetap Fix | X5: Kontrak Fix | Y5: OS Fix | Z5: OS Variabel | AA5: TOTAL EXISTING (Jumlah) | AB5: TOTAL EXISTING (Nominal) | AC5: Tetap Fix | AD5: Kontrak Fix | AE5: OS Fix | AF5: OS Variabel | AG5: TOTAL KEBUTUHAN (Jumlah) | AH5: TOTAL KEBUTUHAN (Nominal) | AI5: Tetap Fix | AJ5: Kontrak Fix | AK5: OS Fix | AL5: OS Variabel | AM5: TOTAL EXISTING (Jumlah) | AN5: TOTAL EXISTING (Nominal) | AO5: Tetap Fix | AP5: Kontrak Fix | AQ5: OS Fix | AR5: OS Variabel | AS5: TOTAL KEBUTUHAN (Jumlah) | AT5: TOTAL KEBUTUHAN (Nominal) | AU5: Tetap Fix | AV5: Kontrak Fix | AW5: OS Fix | AX5: OS Variabel | AY5: TOTAL EXISTING (Jumlah) | AZ5: TOTAL EXISTING (Nominal) | BA5: Tetap Fix | BB5: Kontrak Fix | BC5: OS Fix | BD5: OS Variabel | BE5: TOTAL KEBUTUHAN (Jumlah) | BF5: TOTAL KEBUTUHAN (Nominal) | BG5: Tetap Fix | BH5: Kontrak Fix | BI5: OS Fix | BJ5: OS Variabel | BK5: TOTAL EXISTING (Jumlah) | BL5: TOTAL EXISTING (Nominal) | BM5: Tetap Fix | BN5: Kontrak Fix | BO5: OS Fix | BP5: OS Variabel | BQ5: TOTAL KEBUTUHAN (Jumlah) | BR5: TOTAL KEBUTUHAN (Nominal) | BS5: Tetap Fix | BT5: Kontrak Fix | BU5: OS Fix | BV5: OS Variabel | BW5: TOTAL EXISTING (Jumlah) | BX5: TOTAL EXISTING (Nominal) | BY5: Tetap Fix | BZ5: Kontrak Fix | CA5: OS Fix | CB5: OS Variabel | CC5: TOTAL KEBUTUHAN (Jumlah) | CD5: TOTAL KEBUTUHAN (Nominal) | CE5: Tetap Fix | CF5: Kontrak Fix | CG5: OS Fix | CH5: OS Variabel | CI5: TOTAL EXISTING (Jumlah) | CJ5: TOTAL EXISTING (Nominal) | CK5: Tetap Fix | CL5: Kontrak Fix | CM5: OS Fix | CN5: OS Variabel | CO5: TOTAL KEBUTUHAN (Jumlah) | CP5: TOTAL KEBUTUHAN (Nominal) | CQ5: Tetap Fix | CR5: Kontrak Fix | CS5: OS Fix | CT5: OS Variabel | CU5: TOTAL EXISTING (Jumlah) | CV5: TOTAL EXISTING (Nominal)
C8: GM | D8: GM | F8: 1 | I8: =SUM(E8:H8) -> 1 | L8: 1 | O8: =SUM(K8:N8) -> 1 | U8: =SUM(Q8:T8) -> 0 | AA8: =SUM(W8:Z8) -> 0 | AG8: =SUM(AC8:AF8) -> 0 | AM8: =SUM(AI8:AL8) -> 0 | AS8: =SUM(AO8:AR8) -> 0 | AY8: =SUM(AU8:AX8) -> 0 | BE8: =SUM(BA8:BD8) -> 0 | BK8: =SUM(BG8:BJ8) -> 0 | BM8: =E8+Q8 -> 0 | BN8: =F8+R8 -> 1 | BO8: =G8+S8 -> 0 | BP8: =H8+T8 -> 0 | BQ8: =I8+U8 -> 1 | BR8: =J8+V8 -> 0 | BS8: =K8+W8 -> 0 | BT8: =L8+X8 -> 1 | ... BX8: =P8+AB8 -> 0 | BY8: =AC8+AO8 -> 0 | BZ8: =AD8+AP8 -> 0 | CA8: =AE8+AQ8 -> 0 | CB8: =AF8+AR8 -> 0 | CC8: =AG8+AS8 -> 0 | CD8: =AH8+AT8 -> 0 | CE8: =AI8+AU8 -> 0 | CF8: =AJ8+AV8 -> 0 | ... CJ8: =AN8+AZ8 -> 0 | CK8: =BA8+BM8+BY8 -> 0 | CL8: =BB8+BN8+BZ8 -> 1 | CM8: =BC8+BO8+CA8 -> 0 | CN8: =BD8+BP8+CB8 -> 0 | CO8: =SUM(CK8:CN8) -> 1 | CP8: =BF8+BR8+CD8 -> 0 | CQ8: =BG8+BS8+CE8 -> 0 | CR8: =BH8+BT8+CF8 -> 1 | CS8: =BI8+BU8+CG8 -> 0 | CT8: =BJ8+BV8+CH8 -> 0 | CU8: =SUM(CQ8:CT8) -> 1 | CV8: =BL8+BX8+CJ8 -> 0
C9: Manager/BM/OM | D9: OM | E9: 1 | I9: =SUM(E9:H9) -> 1 | K9: 1 | O9: =SUM(K9:N9) -> 1 | U9: =SUM(Q9:T9) -> 0 | AA9: =SUM(W9:Z9) -> 0 | AC9: 1 | AG9: =SUM(AC9:AF9) -> 1 | AI9: 1 | AM9: =SUM(AI9:AL9) -> 1 | AS9: =SUM(AO9:AR9) -> 0 | AY9: =SUM(AU9:AX9) -> 0 | BA9: 1 | BE9: =SUM(BA9:BD9) -> 1 | BG9: 1 | BK9: =SUM(BG9:BJ9) -> 1 | BM9: =E9+Q9 -> 1 | BN9: =F9+R9 -> 0 | BO9: =G9+S9 -> 0 | BP9: =H9+T9 -> 0 | BQ9: =I9+U9 -> 1 | BR9: =J9+V9 -> 0 | BS9: =K9+W9 -> 1 | BT9: =L9+X9 -> 0 | ... BX9: =P9+AB9 -> 0 | BY9: =AC9+AO9 -> 1 | BZ9: =AD9+AP9 -> 0 | CA9: =AE9+AQ9 -> 0 | CB9: =AF9+AR9 -> 0 | CC9: =AG9+AS9 -> 1 | CD9: =AH9+AT9 -> 0 | CE9: =AI9+AU9 -> 1 | CF9: =AJ9+AV9 -> 0 | ... CJ9: =AN9+AZ9 -> 0 | CK9: =BA9+BM9+BY9 -> 3 | CL9: =BB9+BN9+BZ9 -> 0 | CM9: =BC9+BO9+CA9 -> 0 | CN9: =BD9+BP9+CB9 -> 0 | CO9: =SUM(CK9:CN9) -> 3 | CP9: =BF9+BR9+CD9 -> 0 | CQ9: =BG9+BS9+CE9 -> 3 | CR9: =BH9+BT9+CF9 -> 0 | CS9: =BI9+BU9+CG9 -> 0 | CT9: =BJ9+BV9+CH9 -> 0 | CU9: =SUM(CQ9:CT9) -> 3 | CV9: =BL9+BX9+CJ9 -> 0
D10: ASMEN | I10: =SUM(E10:H10) -> 0 | O10: =SUM(K10:N10) -> 0 | Q10: 1 | U10: =SUM(Q10:T10) -> 1 | W10: 1 | AA10: =SUM(W10:Z10) -> 1 | AG10: =SUM(AC10:AF10) -> 0 | AM10: =SUM(AI10:AL10) -> 0 | AS10: =SUM(AO10:AR10) -> 0 | AY10: =SUM(AU10:AX10) -> 0 | BE10: =SUM(BA10:BD10) -> 0 | BK10: =SUM(BG10:BJ10) -> 0 | BM10: =E10+Q10 -> 1 | BN10: =F10+R10 -> 0 | BO10: =G10+S10 -> 0 | BP10: =H10+T10 -> 0 | BQ10: =I10+U10 -> 1 | BR10: =J10+V10 -> 0 | BS10: =K10+W10 -> 1 | BT10: =L10+X10 -> 0 | ... BX10: =P10+AB10 -> 0 | BY10: =AC10+AO10 -> 0 | BZ10: =AD10+AP10 -> 0 | CA10: =AE10+AQ10 -> 0 | CB10: =AF10+AR10 -> 0 | CC10: =AG10+AS10 -> 0 | CD10: =AH10+AT10 -> 0 | CE10: =AI10+AU10 -> 0 | CF10: =AJ10+AV10 -> 0 | ... CJ10: =AN10+AZ10 -> 0 | CK10: =BA10+BM10+BY10 -> 1 | CL10: =BB10+BN10+BZ10 -> 0 | CM10: =BC10+BO10+CA10 -> 0 | CN10: =BD10+BP10+CB10 -> 0 | CO10: =SUM(CK10:CN10) -> 1 | CP10: =BF10+BR10+CD10 -> 0 | CQ10: =BG10+BS10+CE10 -> 1 | CR10: =BH10+BT10+CF10 -> 0 | CS10: =BI10+BU10+CG10 -> 0 | CT10: =BJ10+BV10+CH10 -> 0 | CU10: =SUM(CQ10:CT10) -> 1 | CV10: =BL10+BX10+CJ10 -> 0
C11: HRD UMUM | D11: KARU HRD | I11: =SUM(E11:H11) -> 0 | O11: =SUM(K11:N11) -> 0 | U11: =SUM(Q11:T11) -> 0 | AA11: =SUM(W11:Z11) -> 0 | AG11: =SUM(AC11:AF11) -> 0 | AM11: =SUM(AI11:AL11) -> 0 | AS11: =SUM(AO11:AR11) -> 0 | AY11: =SUM(AU11:AX11) -> 0 | BA11: 1 | BE11: =SUM(BA11:BD11) -> 1 | BG11: 1 | BK11: =SUM(BG11:BJ11) -> 1 | BM11: =E11+Q11 -> 0 | BN11: =F11+R11 -> 0 | BO11: =G11+S11 -> 0 | BP11: =H11+T11 -> 0 | BQ11: =I11+U11 -> 0 | BR11: =J11+V11 -> 0 | BS11: =K11+W11 -> 0 | BT11: =L11+X11 -> 0 | ... BX11: =P11+AB11 -> 0 | BY11: =AC11+AO11 -> 0 | BZ11: =AD11+AP11 -> 0 | CA11: =AE11+AQ11 -> 0 | CB11: =AF11+AR11 -> 0 | CC11: =AG11+AS11 -> 0 | CD11: =AH11+AT11 -> 0 | CE11: =AI11+AU11 -> 0 | CF11: =AJ11+AV11 -> 0 | ... CJ11: =AN11+AZ11 -> 0 | CK11: =BA11+BM11+BY11 -> 1 | CL11: =BB11+BN11+BZ11 -> 0 | CM11: =BC11+BO11+CA11 -> 0 | CN11: =BD11+BP11+CB11 -> 0 | CO11: =SUM(CK11:CN11) -> 1 | CP11: =BF11+BR11+CD11 -> 0 | CQ11: =BG11+BS11+CE11 -> 1 | CR11: =BH11+BT11+CF11 -> 0 | CS11: =BI11+BU11+CG11 -> 0 | CT11: =BJ11+BV11+CH11 -> 0 | CU11: =SUM(CQ11:CT11) -> 1 | CV11: =BL11+BX11+CJ11 -> 0
D12: STAFF HRD | F12: 1 | I12: =SUM(E12:H12) -> 1 | L12: 1 | O12: =SUM(K12:N12) -> 1 | R12: 1 | U12: =SUM(Q12:T12) -> 1 | X12: 1 | AA12: =SUM(W12:Z12) -> 1 | AG12: =SUM(AC12:AF12) -> 0 | AM12: =SUM(AI12:AL12) -> 0 | AS12: =SUM(AO12:AR12) -> 0 | AY12: =SUM(AU12:AX12) -> 0 | BE12: =SUM(BA12:BD12) -> 0 | BK12: =SUM(BG12:BJ12) -> 0 | BM12: =E12+Q12 -> 0 | BN12: =F12+R12 -> 2 | BO12: =G12+S12 -> 0 | BP12: =H12+T12 -> 0 | BQ12: =I12+U12 -> 2 | BR12: =J12+V12 -> 0 | BS12: =K12+W12 -> 0 | BT12: =L12+X12 -> 2 | ... BX12: =P12+AB12 -> 0 | BY12: =AC12+AO12 -> 0 | BZ12: =AD12+AP12 -> 0 | CA12: =AE12+AQ12 -> 0 | CB12: =AF12+AR12 -> 0 | CC12: =AG12+AS12 -> 0 | CD12: =AH12+AT12 -> 0 | CE12: =AI12+AU12 -> 0 | CF12: =AJ12+AV12 -> 0 | ... CJ12: =AN12+AZ12 -> 0 | CK12: =BA12+BM12+BY12 -> 0 | CL12: =BB12+BN12+BZ12 -> 2 | CM12: =BC12+BO12+CA12 -> 0 | CN12: =BD12+BP12+CB12 -> 0 | CO12: =SUM(CK12:CN12) -> 2 | CP12: =BF12+BR12+CD12 -> 0 | CQ12: =BG12+BS12+CE12 -> 0 | CR12: =BH12+BT12+CF12 -> 2 | CS12: =BI12+BU12+CG12 -> 0 | CT12: =BJ12+BV12+CH12 -> 0 | CU12: =SUM(CQ12:CT12) -> 2 | CV12: =BL12+BX12+CJ12 -> 0
D13: KARU GA | I13: =SUM(E13:H13) -> 0 | O13: =SUM(K13:N13) -> 0 | Q13: 1 | U13: =SUM(Q13:T13) -> 1 | W13: 1 | AA13: =SUM(W13:Z13) -> 1 | AG13: =SUM(AC13:AF13) -> 0 | AM13: =SUM(AI13:AL13) -> 0 | AS13: =SUM(AO13:AR13) -> 0 | AY13: =SUM(AU13:AX13) -> 0 | BA13: 1 | BE13: =SUM(BA13:BD13) -> 1 | BG13: 1 | BK13: =SUM(BG13:BJ13) -> 1 | BM13: =E13+Q13 -> 1 | BN13: =F13+R13 -> 0 | BO13: =G13+S13 -> 0 | BP13: =H13+T13 -> 0 | BQ13: =I13+U13 -> 1 | BR13: =J13+V13 -> 0 | BS13: =K13+W13 -> 1 | BT13: =L13+X13 -> 0 | ... BX13: =P13+AB13 -> 0 | BY13: =AC13+AO13 -> 0 | BZ13: =AD13+AP13 -> 0 | CA13: =AE13+AQ13 -> 0 | CB13: =AF13+AR13 -> 0 | CC13: =AG13+AS13 -> 0 | CD13: =AH13+AT13 -> 0 | CE13: =AI13+AU13 -> 0 | CF13: =AJ13+AV13 -> 0 | ... CJ13: =AN13+AZ13 -> 0 | CK13: =BA13+BM13+BY13 -> 2 | CL13: =BB13+BN13+BZ13 -> 0 | CM13: =BC13+BO13+CA13 -> 0 | CN13: =BD13+BP13+CB13 -> 0 | CO13: =SUM(CK13:CN13) -> 2 | CP13: =BF13+BR13+CD13 -> 0 | CQ13: =BG13+BS13+CE13 -> 2 | CR13: =BH13+BT13+CF13 -> 0 | CS13: =BI13+BU13+CG13 -> 0 | CT13: =BJ13+BV13+CH13 -> 0 | CU13: =SUM(CQ13:CT13) -> 2 | CV13: =BL13+BX13+CJ13 -> 0
D14: UMUM | I14: =SUM(E14:H14) -> 0 | O14: =SUM(K14:N14) -> 0 | R14: 1 | S14: 4 | U14: =SUM(Q14:T14) -> 5 | X14: 1 | Y14: 4 | AA14: =SUM(W14:Z14) -> 5 | AE14: 4 | AG14: =SUM(AC14:AF14) -> 4 | AK14: 4 | AM14: =SUM(AI14:AL14) -> 4 | AS14: =SUM(AO14:AR14) -> 0 | AY14: =SUM(AU14:AX14) -> 0 | BC14: 4 | BE14: =SUM(BA14:BD14) -> 4 | BI14: 4 | BK14: =SUM(BG14:BJ14) -> 4 | BM14: =E14+Q14 -> 0 | BN14: =F14+R14 -> 1 | BO14: =G14+S14 -> 4 | BP14: =H14+T14 -> 0 | BQ14: =I14+U14 -> 5 | BR14: =J14+V14 -> 0 | BS14: =K14+W14 -> 0 | BT14: =L14+X14 -> 1 | ... BX14: =P14+AB14 -> 0 | BY14: =AC14+AO14 -> 0 | BZ14: =AD14+AP14 -> 0 | CA14: =AE14+AQ14 -> 4 | CB14: =AF14+AR14 -> 0 | CC14: =AG14+AS14 -> 4 | CD14: =AH14+AT14 -> 0 | CE14: =AI14+AU14 -> 0 | CF14: =AJ14+AV14 -> 0 | ... CJ14: =AN14+AZ14 -> 0 | CK14: =BA14+BM14+BY14 -> 0 | CL14: =BB14+BN14+BZ14 -> 1 | CM14: =BC14+BO14+CA14 -> 12 | CN14: =BD14+BP14+CB14 -> 0 | CO14: =SUM(CK14:CN14) -> 13 | CP14: =BF14+BR14+CD14 -> 0 | CQ14: =BG14+BS14+CE14 -> 0 | CR14: =BH14+BT14+CF14 -> 1 | CS14: =BI14+BU14+CG14 -> 12 | CT14: =BJ14+BV14+CH14 -> 0 | CU14: =SUM(CQ14:CT14) -> 13 | CV14: =BL14+BX14+CJ14 -> 0
D15: SECURITY | I15: =SUM(E15:H15) -> 0 | O15: =SUM(K15:N15) -> 0 | S15: 2 | U15: =SUM(Q15:T15) -> 2 | Y15: 2 | AA15: =SUM(W15:Z15) -> 2 | AE15: 2 | AG15: =SUM(AC15:AF15) -> 2 | AK15: 2 | AM15: =SUM(AI15:AL15) -> 2 | AS15: =SUM(AO15:AR15) -> 0 | AY15: =SUM(AU15:AX15) -> 0 | BC15: 7 | BE15: =SUM(BA15:BD15) -> 7 | BI15: 7 | BK15: =SUM(BG15:BJ15) -> 7 | BM15: =E15+Q15 -> 0 | BN15: =F15+R15 -> 0 | BO15: =G15+S15 -> 2 | BP15: =H15+T15 -> 0 | BQ15: =I15+U15 -> 2 | BR15: =J15+V15 -> 0 | BS15: =K15+W15 -> 0 | BT15: =L15+X15 -> 0 | ... BX15: =P15+AB15 -> 0 | BY15: =AC15+AO15 -> 0 | BZ15: =AD15+AP15 -> 0 | CA15: =AE15+AQ15 -> 2 | CB15: =AF15+AR15 -> 0 | CC15: =AG15+AS15 -> 2 | CD15: =AH15+AT15 -> 0 | CE15: =AI15+AU15 -> 0 | CF15: =AJ15+AV15 -> 0 | ... CJ15: =AN15+AZ15 -> 0 | CK15: =BA15+BM15+BY15 -> 0 | CL15: =BB15+BN15+BZ15 -> 0 | CM15: =BC15+BO15+CA15 -> 11 | CN15: =BD15+BP15+CB15 -> 0 | CO15: =SUM(CK15:CN15) -> 11 | CP15: =BF15+BR15+CD15 -> 0 | CQ15: =BG15+BS15+CE15 -> 0 | CR15: =BH15+BT15+CF15 -> 0 | CS15: =BI15+BU15+CG15 -> 11 | CT15: =BJ15+BV15+CH15 -> 0 | CU15: =SUM(CQ15:CT15) -> 11 | CV15: =BL15+BX15+CJ15 -> 0
C16: PEMASARAN | D16: KADIV MARKETING | E16: 1 | I16: =SUM(E16:H16) -> 1 | K16: 1 | O16: =SUM(K16:N16) -> 1 | R16: 1 | U16: =SUM(Q16:T16) -> 1 | X16: 1 | AA16: =SUM(W16:Z16) -> 1 | AG16: =SUM(AC16:AF16) -> 0 | AM16: =SUM(AI16:AL16) -> 0 | AS16: =SUM(AO16:AR16) -> 0 | AY16: =SUM(AU16:AX16) -> 0 | BA16: 1 | BE16: =SUM(BA16:BD16) -> 1 | BG16: 1 | BK16: =SUM(BG16:BJ16) -> 1 | BM16: =E16+Q16 -> 1 | BN16: =F16+R16 -> 1 | BO16: =G16+S16 -> 0 | BP16: =H16+T16 -> 0 | BQ16: =I16+U16 -> 2 | BR16: =J16+V16 -> 0 | BS16: =K16+W16 -> 1 | BT16: =L16+X16 -> 1 | ... BX16: =P16+AB16 -> 0 | BY16: =AC16+AO16 -> 0 | BZ16: =AD16+AP16 -> 0 | CA16: =AE16+AQ16 -> 0 | CB16: =AF16+AR16 -> 0 | CC16: =AG16+AS16 -> 0 | CD16: =AH16+AT16 -> 0 | CE16: =AI16+AU16 -> 0 | CF16: =AJ16+AV16 -> 0 | ... CJ16: =AN16+AZ16 -> 0 | CK16: =BA16+BM16+BY16 -> 2 | CL16: =BB16+BN16+BZ16 -> 1 | CM16: =BC16+BO16+CA16 -> 0 | CN16: =BD16+BP16+CB16 -> 0 | CO16: =SUM(CK16:CN16) -> 3 | CP16: =BF16+BR16+CD16 -> 0 | CQ16: =BG16+BS16+CE16 -> 2 | CR16: =BH16+BT16+CF16 -> 1 | CS16: =BI16+BU16+CG16 -> 0 | CT16: =BJ16+BV16+CH16 -> 0 | CU16: =SUM(CQ16:CT16) -> 3 | CV16: =BL16+BX16+CJ16 -> 0
D17: MARKETING | E17: 3 | I17: =SUM(E17:H17) -> 3 | K17: 2 | O17: =SUM(K17:N17) -> 2 | R17: 1 | U17: =SUM(Q17:T17) -> 1 | X17: 1 | AA17: =SUM(W17:Z17) -> 1 | AC17: 1 | AD17: =2+2 -> 4 | AG17: =SUM(AC17:AF17) -> 5 | AI17: 1 | AJ17: 2 | AM17: =SUM(AI17:AL17) -> 3 | AO17: 3 | AS17: =SUM(AO17:AR17) -> 3 | AU17: 2 | AV17: 1 | AY17: =SUM(AU17:AX17) -> 3 | BA17: 4 | BE17: =SUM(BA17:BD17) -> 4 | BG17: 4 | BK17: =SUM(BG17:BJ17) -> 4 | BM17: =E17+Q17 -> 3 | BN17: =F17+R17 -> 1 | BO17: =G17+S17 -> 0 | BP17: =H17+T17 -> 0 | BQ17: =I17+U17 -> 4 | BR17: =J17+V17 -> 0 | BS17: =K17+W17 -> 2 | BT17: =L17+X17 -> 1 | ... BX17: =P17+AB17 -> 0 | BY17: =AC17+AO17 -> 4 | BZ17: =AD17+AP17 -> 4 | CA17: =AE17+AQ17 -> 0 | CB17: =AF17+AR17 -> 0 | CC17: =AG17+AS17 -> 8 | CD17: =AH17+AT17 -> 0 | CE17: =AI17+AU17 -> 3 | CF17: =AJ17+AV17 -> 3 | ... CJ17: =AN17+AZ17 -> 0 | CK17: =BA17+BM17+BY17 -> 11 | CL17: =BB17+BN17+BZ17 -> 5 | CM17: =BC17+BO17+CA17 -> 0 | CN17: =BD17+BP17+CB17 -> 0 | CO17: =SUM(CK17:CN17) -> 16 | CP17: =BF17+BR17+CD17 -> 0 | CQ17: =BG17+BS17+CE17 -> 9 | CR17: =BH17+BT17+CF17 -> 4 | CS17: =BI17+BU17+CG17 -> 0 | CT17: =BJ17+BV17+CH17 -> 0 | CU17: =SUM(CQ17:CT17) -> 13 | CV17: =BL17+BX17+CJ17 -> 0
D18: ADMIN MKT | G18: 1 | I18: =SUM(E18:H18) -> 1 | M18: 1 | O18: =SUM(K18:N18) -> 1 | Q18: 1 | U18: =SUM(Q18:T18) -> 1 | W18: 1 | AA18: =SUM(W18:Z18) -> 1 | AC18: 1 | AE18: 1 | AG18: =SUM(AC18:AF18) -> 2 | AI18: 1 | AK18: 1 | AM18: =SUM(AI18:AL18) -> 2 | AS18: =SUM(AO18:AR18) -> 0 | AY18: =SUM(AU18:AX18) -> 0 | BC18: 1 | BE18: =SUM(BA18:BD18) -> 1 | BI18: 1 | BK18: =SUM(BG18:BJ18) -> 1 | BM18: =E18+Q18 -> 1 | BN18: =F18+R18 -> 0 | BO18: =G18+S18 -> 1 | BP18: =H18+T18 -> 0 | BQ18: =I18+U18 -> 2 | BR18: =J18+V18 -> 0 | BS18: =K18+W18 -> 1 | BT18: =L18+X18 -> 0 | ... BX18: =P18+AB18 -> 0 | BY18: =AC18+AO18 -> 1 | BZ18: =AD18+AP18 -> 0 | CA18: =AE18+AQ18 -> 1 | CB18: =AF18+AR18 -> 0 | CC18: =AG18+AS18 -> 2 | CD18: =AH18+AT18 -> 0 | CE18: =AI18+AU18 -> 1 | CF18: =AJ18+AV18 -> 0 | ... CJ18: =AN18+AZ18 -> 0 | CK18: =BA18+BM18+BY18 -> 2 | CL18: =BB18+BN18+BZ18 -> 0 | CM18: =BC18+BO18+CA18 -> 3 | CN18: =BD18+BP18+CB18 -> 0 | CO18: =SUM(CK18:CN18) -> 5 | CP18: =BF18+BR18+CD18 -> 0 | CQ18: =BG18+BS18+CE18 -> 2 | CR18: =BH18+BT18+CF18 -> 0 | CS18: =BI18+BU18+CG18 -> 3 | CT18: =BJ18+BV18+CH18 -> 0 | CU18: =SUM(CQ18:CT18) -> 5 | CV18: =BL18+BX18+CJ18 -> 0
D19: MARKETING SUPPORT | F19: 1 | I19: =SUM(E19:H19) -> 1 | L19: 1 | O19: =SUM(K19:N19) -> 1 | U19: =SUM(Q19:T19) -> 0 | AA19: =SUM(W19:Z19) -> 0 | AG19: =SUM(AC19:AF19) -> 0 | AM19: =SUM(AI19:AL19) -> 0 | AS19: =SUM(AO19:AR19) -> 0 | AY19: =SUM(AU19:AX19) -> 0 | BC19: 1 | BE19: =SUM(BA19:BD19) -> 1 | BI19: 1 | BK19: =SUM(BG19:BJ19) -> 1 | BM19: =E19+Q19 -> 0 | BN19: =F19+R19 -> 1 | BO19: =G19+S19 -> 0 | BP19: =H19+T19 -> 0 | BQ19: =I19+U19 -> 1 | BR19: =J19+V19 -> 0 | BS19: =K19+W19 -> 0 | BT19: =L19+X19 -> 1 | ... BX19: =P19+AB19 -> 0 | BY19: =AC19+AO19 -> 0 | BZ19: =AD19+AP19 -> 0 | CA19: =AE19+AQ19 -> 0 | CB19: =AF19+AR19 -> 0 | CC19: =AG19+AS19 -> 0 | CD19: =AH19+AT19 -> 0 | CE19: =AI19+AU19 -> 0 | CF19: =AJ19+AV19 -> 0 | ... CJ19: =AN19+AZ19 -> 0 | CK19: =BA19+BM19+BY19 -> 0 | CL19: =BB19+BN19+BZ19 -> 1 | CM19: =BC19+BO19+CA19 -> 1 | CN19: =BD19+BP19+CB19 -> 0 | CO19: =SUM(CK19:CN19) -> 2 | CP19: =BF19+BR19+CD19 -> 0 | CQ19: =BG19+BS19+CE19 -> 0 | CR19: =BH19+BT19+CF19 -> 1 | CS19: =BI19+BU19+CG19 -> 1 | CT19: =BJ19+BV19+CH19 -> 0 | CU19: =SUM(CQ19:CT19) -> 2 | CV19: =BL19+BX19+CJ19 -> 0
C20: IT | D20: STAFF IT | I20: =SUM(E20:H20) -> 0 | O20: =SUM(K20:N20) -> 0 | R20: 1 | U20: =SUM(Q20:T20) -> 1 | AA20: =SUM(W20:Z20) -> 0 | AG20: =SUM(AC20:AF20) -> 0 | AM20: =SUM(AI20:AL20) -> 0 | AS20: =SUM(AO20:AR20) -> 0 | AY20: =SUM(AU20:AX20) -> 0 | BB20: 1 | BE20: =SUM(BA20:BD20) -> 1 | BH20: 1 | BK20: =SUM(BG20:BJ20) -> 1 | BM20: =E20+Q20 -> 0 | BN20: =F20+R20 -> 1 | BO20: =G20+S20 -> 0 | BP20: =H20+T20 -> 0 | BQ20: =I20+U20 -> 1 | BR20: =J20+V20 -> 0 | BS20: =K20+W20 -> 0 | BT20: =L20+X20 -> 0 | ... BX20: =P20+AB20 -> 0 | BY20: =AC20+AO20 -> 0 | BZ20: =AD20+AP20 -> 0 | CA20: =AE20+AQ20 -> 0 | CB20: =AF20+AR20 -> 0 | CC20: =AG20+AS20 -> 0 | CD20: =AH20+AT20 -> 0 | CE20: =AI20+AU20 -> 0 | CF20: =AJ20+AV20 -> 0 | ... CJ20: =AN20+AZ20 -> 0 | CK20: =BA20+BM20+BY20 -> 0 | CL20: =BB20+BN20+BZ20 -> 2 | CM20: =BC20+BO20+CA20 -> 0 | CN20: =BD20+BP20+CB20 -> 0 | CO20: =SUM(CK20:CN20) -> 2 | CP20: =BF20+BR20+CD20 -> 0 | CQ20: =BG20+BS20+CE20 -> 0 | CR20: =BH20+BT20+CF20 -> 1 | CS20: =BI20+BU20+CG20 -> 0 | CT20: =BJ20+BV20+CH20 -> 0 | CU20: =SUM(CQ20:CT20) -> 1 | CV20: =BL20+BX20+CJ20 -> 0
C21: PPIC | D21: KADIV PPIC | E21: 1 | I21: =SUM(E21:H21) -> 1 | K21: 1 | O21: =SUM(K21:N21) -> 1 | U21: =SUM(Q21:T21) -> 0 | AA21: =SUM(W21:Z21) -> 0 | AG21: =SUM(AC21:AF21) -> 0 | AM21: =SUM(AI21:AL21) -> 0 | AS21: =SUM(AO21:AR21) -> 0 | AY21: =SUM(AU21:AX21) -> 0 | BE21: =SUM(BA21:BD21) -> 0 | BK21: =SUM(BG21:BJ21) -> 0 | BM21: =E21+Q21 -> 1 | BN21: =F21+R21 -> 0 | BO21: =G21+S21 -> 0 | BP21: =H21+T21 -> 0 | BQ21: =I21+U21 -> 1 | BR21: =J21+V21 -> 0 | BS21: =K21+W21 -> 1 | BT21: =L21+X21 -> 0 | ... BX21: =P21+AB21 -> 0 | BY21: =AC21+AO21 -> 0 | BZ21: =AD21+AP21 -> 0 | CA21: =AE21+AQ21 -> 0 | CB21: =AF21+AR21 -> 0 | CC21: =AG21+AS21 -> 0 | CD21: =AH21+AT21 -> 0 | CE21: =AI21+AU21 -> 0 | CF21: =AJ21+AV21 -> 0 | ... CJ21: =AN21+AZ21 -> 0 | CK21: =BA21+BM21+BY21 -> 1 | CL21: =BB21+BN21+BZ21 -> 0 | CM21: =BC21+BO21+CA21 -> 0 | CN21: =BD21+BP21+CB21 -> 0 | CO21: =SUM(CK21:CN21) -> 1 | CP21: =BF21+BR21+CD21 -> 0 | CQ21: =BG21+BS21+CE21 -> 1 | CR21: =BH21+BT21+CF21 -> 0 | CS21: =BI21+BU21+CG21 -> 0 | CT21: =BJ21+BV21+CH21 -> 0 | CU21: =SUM(CQ21:CT21) -> 1 | CV21: =BL21+BX21+CJ21 -> 0
D22: KARU PPIC | I22: =SUM(E22:H22) -> 0 | O22: =SUM(K22:N22) -> 0 | U22: =SUM(Q22:T22) -> 0 | AA22: =SUM(W22:Z22) -> 0 | AG22: =SUM(AC22:AF22) -> 0 | AM22: =SUM(AI22:AL22) -> 0 | AS22: =SUM(AO22:AR22) -> 0 | AY22: =SUM(AU22:AX22) -> 0 | BA22: 1 | BE22: =SUM(BA22:BD22) -> 1 | BG22: 1 | BK22: =SUM(BG22:BJ22) -> 1 | BM22: =E22+Q22 -> 0 | BN22: =F22+R22 -> 0 | BO22: =G22+S22 -> 0 | BP22: =H22+T22 -> 0 | BQ22: =I22+U22 -> 0 | BR22: =J22+V22 -> 0 | BS22: =K22+W22 -> 0 | BT22: =L22+X22 -> 0 | ... BX22: =P22+AB22 -> 0 | BY22: =AC22+AO22 -> 0 | BZ22: =AD22+AP22 -> 0 | CA22: =AE22+AQ22 -> 0 | CB22: =AF22+AR22 -> 0 | CC22: =AG22+AS22 -> 0 | CD22: =AH22+AT22 -> 0 | CE22: =AI22+AU22 -> 0 | CF22: =AJ22+AV22 -> 0 | ... CJ22: =AN22+AZ22 -> 0 | CK22: =BA22+BM22+BY22 -> 1 | CL22: =BB22+BN22+BZ22 -> 0 | CM22: =BC22+BO22+CA22 -> 0 | CN22: =BD22+BP22+CB22 -> 0 | CO22: =SUM(CK22:CN22) -> 1 | CP22: =BF22+BR22+CD22 -> 0 | CQ22: =BG22+BS22+CE22 -> 1 | CR22: =BH22+BT22+CF22 -> 0 | CS22: =BI22+BU22+CG22 -> 0 | CT22: =BJ22+BV22+CH22 -> 0 | CU22: =SUM(CQ22:CT22) -> 1 | CV22: =BL22+BX22+CJ22 -> 0
D23: STAFF PPIC | E23: 1 | I23: =SUM(E23:H23) -> 1 | K23: 1 | O23: =SUM(K23:N23) -> 1 | R23: 1 | U23: =SUM(Q23:T23) -> 1 | X23: 1 | AA23: =SUM(W23:Z23) -> 1 | AC23: 1 | AG23: =SUM(AC23:AF23) -> 1 | AI23: 1 | AM23: =SUM(AI23:AL23) -> 1 | AS23: =SUM(AO23:AR23) -> 0 | AY23: =SUM(AU23:AX23) -> 0 | BE23: =SUM(BA23:BD23) -> 0 | BK23: =SUM(BG23:BJ23) -> 0 | BM23: =E23+Q23 -> 1 | BN23: =F23+R23 -> 1 | BO23: =G23+S23 -> 0 | BP23: =H23+T23 -> 0 | BQ23: =I23+U23 -> 2 | BR23: =J23+V23 -> 0 | BS23: =K23+W23 -> 1 | BT23: =L23+X23 -> 1 | ... BX23: =P23+AB23 -> 0 | BY23: =AC23+AO23 -> 1 | BZ23: =AD23+AP23 -> 0 | CA23: =AE23+AQ23 -> 0 | CB23: =AF23+AR23 -> 0 | CC23: =AG23+AS23 -> 1 | CD23: =AH23+AT23 -> 0 | CE23: =AI23+AU23 -> 1 | CF23: =AJ23+AV23 -> 0 | ... CJ23: =AN23+AZ23 -> 0 | CK23: =BA23+BM23+BY23 -> 2 | CL23: =BB23+BN23+BZ23 -> 1 | CM23: =BC23+BO23+CA23 -> 0 | CN23: =BD23+BP23+CB23 -> 0 | CO23: =SUM(CK23:CN23) -> 3 | CP23: =BF23+BR23+CD23 -> 0 | CQ23: =BG23+BS23+CE23 -> 2 | CR23: =BH23+BT23+CF23 -> 1 | CS23: =BI23+BU23+CG23 -> 0 | CT23: =BJ23+BV23+CH23 -> 0 | CU23: =SUM(CQ23:CT23) -> 3 | CV23: =BL23+BX23+CJ23 -> 0
D24: ADM PPIC | G24: 2 | I24: =SUM(E24:H24) -> 2 | M24: 2 | O24: =SUM(K24:N24) -> 2 | U24: =SUM(Q24:T24) -> 0 | AA24: =SUM(W24:Z24) -> 0 | AE24: 1 | AG24: =SUM(AC24:AF24) -> 1 | AK24: 1 | AM24: =SUM(AI24:AL24) -> 1 | AS24: =SUM(AO24:AR24) -> 0 | AY24: =SUM(AU24:AX24) -> 0 | BE24: =SUM(BA24:BD24) -> 0 | BK24: =SUM(BG24:BJ24) -> 0 | BM24: =E24+Q24 -> 0 | BN24: =F24+R24 -> 0 | BO24: =G24+S24 -> 2 | BP24: =H24+T24 -> 0 | BQ24: =I24+U24 -> 2 | BR24: =J24+V24 -> 0 | BS24: =K24+W24 -> 0 | BT24: =L24+X24 -> 0 | ... BX24: =P24+AB24 -> 0 | BY24: =AC24+AO24 -> 0 | BZ24: =AD24+AP24 -> 0 | CA24: =AE24+AQ24 -> 1 | CB24: =AF24+AR24 -> 0 | CC24: =AG24+AS24 -> 1 | CD24: =AH24+AT24 -> 0 | CE24: =AI24+AU24 -> 0 | CF24: =AJ24+AV24 -> 0 | ... CJ24: =AN24+AZ24 -> 0 | CK24: =BA24+BM24+BY24 -> 0 | CL24: =BB24+BN24+BZ24 -> 0 | CM24: =BC24+BO24+CA24 -> 3 | CN24: =BD24+BP24+CB24 -> 0 | CO24: =SUM(CK24:CN24) -> 3 | CP24: =BF24+BR24+CD24 -> 0 | CQ24: =BG24+BS24+CE24 -> 0 | CR24: =BH24+BT24+CF24 -> 0 | CS24: =BI24+BU24+CG24 -> 3 | CT24: =BJ24+BV24+CH24 -> 0 | CU24: =SUM(CQ24:CT24) -> 3 | CV24: =BL24+BX24+CJ24 -> 0
D25: KARU GUDANG | I25: =SUM(E25:H25) -> 0 | O25: =SUM(K25:N25) -> 0 | U25: =SUM(Q25:T25) -> 0 | AA25: =SUM(W25:Z25) -> 0 | AG25: =SUM(AC25:AF25) -> 0 | AM25: =SUM(AI25:AL25) -> 0 | AS25: =SUM(AO25:AR25) -> 0 | AY25: =SUM(AU25:AX25) -> 0 | BA25: 1 | BE25: =SUM(BA25:BD25) -> 1 | BG25: 1 | BK25: =SUM(BG25:BJ25) -> 1 | BM25: =E25+Q25 -> 0 | BN25: =F25+R25 -> 0 | BO25: =G25+S25 -> 0 | BP25: =H25+T25 -> 0 | BQ25: =I25+U25 -> 0 | BR25: =J25+V25 -> 0 | BS25: =K25+W25 -> 0 | BT25: =L25+X25 -> 0 | ... BX25: =P25+AB25 -> 0 | BY25: =AC25+AO25 -> 0 | BZ25: =AD25+AP25 -> 0 | CA25: =AE25+AQ25 -> 0 | CB25: =AF25+AR25 -> 0 | CC25: =AG25+AS25 -> 0 | CD25: =AH25+AT25 -> 0 | CE25: =AI25+AU25 -> 0 | CF25: =AJ25+AV25 -> 0 | ... CJ25: =AN25+AZ25 -> 0 | CK25: =BA25+BM25+BY25 -> 1 | CL25: =BB25+BN25+BZ25 -> 0 | CM25: =BC25+BO25+CA25 -> 0 | CN25: =BD25+BP25+CB25 -> 0 | CO25: =SUM(CK25:CN25) -> 1 | CP25: =BF25+BR25+CD25 -> 0 | CQ25: =BG25+BS25+CE25 -> 1 | CR25: =BH25+BT25+CF25 -> 0 | CS25: =BI25+BU25+CG25 -> 0 | CT25: =BJ25+BV25+CH25 -> 0 | CU25: =SUM(CQ25:CT25) -> 1 | CV25: =BL25+BX25+CJ25 -> 0
D26: STAFF GBB | F26: 1 | I26: =SUM(E26:H26) -> 1 | L26: 1 | O26: =SUM(K26:N26) -> 1 | R26: 1 | U26: =SUM(Q26:T26) -> 1 | X26: 1 | AA26: =SUM(W26:Z26) -> 1 | AG26: =SUM(AC26:AF26) -> 0 | AM26: =SUM(AI26:AL26) -> 0 | AS26: =SUM(AO26:AR26) -> 0 | AY26: =SUM(AU26:AX26) -> 0 | BA26: 1 | BE26: =SUM(BA26:BD26) -> 1 | BG26: 1 | BK26: =SUM(BG26:BJ26) -> 1 | BM26: =E26+Q26 -> 0 | BN26: =F26+R26 -> 2 | BO26: =G26+S26 -> 0 | BP26: =H26+T26 -> 0 | BQ26: =I26+U26 -> 2 | BR26: =J26+V26 -> 0 | BS26: =K26+W26 -> 0 | BT26: =L26+X26 -> 2 | ... BX26: =P26+AB26 -> 0 | BY26: =AC26+AO26 -> 0 | BZ26: =AD26+AP26 -> 0 | CA26: =AE26+AQ26 -> 0 | CB26: =AF26+AR26 -> 0 | CC26: =AG26+AS26 -> 0 | CD26: =AH26+AT26 -> 0 | CE26: =AI26+AU26 -> 0 | CF26: =AJ26+AV26 -> 0 | ... CJ26: =AN26+AZ26 -> 0 | CK26: =BA26+BM26+BY26 -> 1 | CL26: =BB26+BN26+BZ26 -> 2 | CM26: =BC26+BO26+CA26 -> 0 | CN26: =BD26+BP26+CB26 -> 0 | CO26: =SUM(CK26:CN26) -> 3 | CP26: =BF26+BR26+CD26 -> 0 | CQ26: =BG26+BS26+CE26 -> 1 | CR26: =BH26+BT26+CF26 -> 2 | CS26: =BI26+BU26+CG26 -> 0 | CT26: =BJ26+BV26+CH26 -> 0 | CU26: =SUM(CQ26:CT26) -> 3 | CV26: =BL26+BX26+CJ26 -> 0
D27: STAFF GUDANG SPAREPART | I27: =SUM(E27:H27) -> 0 | O27: =SUM(K27:N27) -> 0 | R27: 1 | U27: =SUM(Q27:T27) -> 1 | X27: 1 | AA27: =SUM(W27:Z27) -> 1 | AG27: =SUM(AC27:AF27) -> 0 | AM27: =SUM(AI27:AL27) -> 0 | AS27: =SUM(AO27:AR27) -> 0 | AY27: =SUM(AU27:AX27) -> 0 | BE27: =SUM(BA27:BD27) -> 0 | BK27: =SUM(BG27:BJ27) -> 0 | BM27: =E27+Q27 -> 0 | BN27: =F27+R27 -> 1 | BO27: =G27+S27 -> 0 | BP27: =H27+T27 -> 0 | BQ27: =I27+U27 -> 1 | BR27: =J27+V27 -> 0 | BS27: =K27+W27 -> 0 | BT27: =L27+X27 -> 1 | ... BX27: =P27+AB27 -> 0 | BY27: =AC27+AO27 -> 0 | BZ27: =AD27+AP27 -> 0 | CA27: =AE27+AQ27 -> 0 | CB27: =AF27+AR27 -> 0 | CC27: =AG27+AS27 -> 0 | CD27: =AH27+AT27 -> 0 | CE27: =AI27+AU27 -> 0 | CF27: =AJ27+AV27 -> 0 | ... CJ27: =AN27+AZ27 -> 0 | CK27: =BA27+BM27+BY27 -> 0 | CL27: =BB27+BN27+BZ27 -> 1 | CM27: =BC27+BO27+CA27 -> 0 | CN27: =BD27+BP27+CB27 -> 0 | CO27: =SUM(CK27:CN27) -> 1 | CP27: =BF27+BR27+CD27 -> 0 | CQ27: =BG27+BS27+CE27 -> 0 | CR27: =BH27+BT27+CF27 -> 1 | CS27: =BI27+BU27+CG27 -> 0 | CT27: =BJ27+BV27+CH27 -> 0 | CU27: =SUM(CQ27:CT27) -> 1 | CV27: =BL27+BX27+CJ27 -> 0
